Workbook

Sheet 空间资源
A1: 空间资源经营简报
A2: 公司 | B2: 25年完成 | C2: 26年预算 | D2: 孰高指标 | E2: 已入账 | F2: 入账同比 | G2: 待入账 | H2: 待续签 | I2: 全年预估收入 | J2: 业绩缺口 | K2: 4月缺口 | L2: 较上月新增 | M2: 备注
A3: 阜阳 | B3: 20.963642 | C3: 20.412388 | D3: 20.963642 | E3: 8.7150515 | F3: 2.1763707 | G3: 5.38 | H3: 7 | I3: =E3+G3+H3 -> 21.095051 | J3: =E3+G3+H3-D3 -> 0.1314098 | K3: 0.21275665 | L3: =-K3+J3 -> -0.08134685 | N3: =VLOOKUP(A3,[4]Sheet1!$B$4:$O$16,13,FALSE) -> 5.38 | O3: =N3-G3 -> 0
A4: 北城 | B4: 520.41069 | C4: 396.09429 | D4: 520.41069 | E4: 202.32602 | F4: 10.988084 | G4: 170.45 | H4: 99 | I4: =E4+G4+H4 -> 471.77602 | J4: =E4+G4+H4-D4 -> -48.63467 | K4: -50.49825 | L4: =-K4+J4 -> 1.8635805 | N4: =VLOOKUP(A4,[4]Sheet1!$B$4:$O$16,13,FALSE) -> 178.84 | O4: =N4-G4 -> 8.39
A5: 宁波 | B5: 412.92583 | C5: 392.40341 | D5: 412.92583 | E5: 195.13466 | F5: 29.475473 | G5: 149.9 | H5: 50 | I5: =E5+G5+H5 -> 395.03466 | J5: =E5+G5+H5-D5 -> -17.891171 | K5: -55.292366 | L5: =-K5+J5 -> 37.401195 | N5: =VLOOKUP(A5,[4]Sheet1!$B$4:$O$16,13,FALSE) -> 150 | O5: =N5-G5 -> 0.1
A6: 滨湖 | B6: 505.97782 | C6: 501.99821 | D6: =693.97782195-188 -> 505.97782 | E6: 220.90803 | F6: 17.238108 | G6: 144.01 | H6: 15 | I6: =E6+G6+H6 -> 379.91803 | J6: =E6+G6+H6-D6 -> -126.05979 | K6: -123.25837 | L6: =-K6+J6 -> -2.8014205 | M6: 1个广告合同提前退租，替换商家协商中 | N6: =VLOOKUP(A6,[4]Sheet1!$B$4:$O$16,13,FALSE) -> 140.2 | O6: =N6-G6 -> -3.81
A7: 长沙 | B7: 614.49592 | C7: 661.0042 | D7: 661.0042 | E7: 222.49288 | F7: -22.594008 | G7: 274.78502 | H7: 31.78 | I7: =E7+G7+H7 -> 529.0579 | J7: =E7+G7+H7-D7 -> -131.94629 | K7: -137.49695 | L7: =-K7+J7 -> 5.5506528 | N7: =VLOOKUP(A7,[4]Sheet1!$B$4:$O$16,13,FALSE) -> 286.63 | O7: =N7-G7 -> 11.844979
A8: 贵阳 | B8: 922.0172 | C8: 810.02518 | D8: 922.0172 | E8: 394.50547 | F8: -25.412295 | G8: 301.77 | H8: 76.94 | I8: =E8+G8+H8 -> 773.21547 | J8: =E8+G8+H8-D8 -> -148.80174 | K8: -203.74319 | L8: =-K8+J8 -> 54.941453 | N8: =VLOOKUP(A8,[4]Sheet1!$B$4:$O$16,13,FALSE) -> 301.77 | O8: =N8-G8 -> 0
A9: 北京 | B9: 1642.4747 | C9: 1562.0577 | D9: 1642.4747 | E9: 595.02894 | F9: -56.285752 | G9: 602.54487 | H9: 236.96338 | I9: =E9+G9+H9 -> 1434.5372 | J9: =E9+G9+H9-D9 -> -207.93751 | K9: -207.32784 | L9: =-K9+J9 -> -0.60967052 | M9: 电梯广告退租 | N9: =VLOOKUP(A9,[4]Sheet1!$B$4:$O$16,13,FALSE) -> 602.54 | O9: =N9-G9 -> -0.004868
A10: 小计 | B10: =SUM(B3:B9) -> 4639.2658 | C10: =SUM(C3:C9) -> 4343.9954 | D10: =SUM(D3:D9) -> 4685.7741 | E10: =SUM(E3:E9) -> 1839.1111 | F10: =SUM(F3:F9) -> -44.414019 | G10: =SUM(G3:G9) -> 1648.8399 | H10: =SUM(H3:H9) -> 516.68338 | I10: =SUM(I3:I9) -> 4004.6343 | ... K10: =SUM(K3:K9) -> -777.40421 | L10: =-K10+J10 -> 96.264444 | N10: =VLOOKUP(A10,[4]Sheet1!$B$4:$O$16,13,FALSE) -> #N/A | O10: =N10-G10 -> #N/A
A11: 闽江 | B11: 188.92003 | C11: 152 | D11: 188.92003 | E11: 84.004721 | F11: 1.8707083 | G11: 93.37 | H11: 6.94 | I11: =E11+G11+H11 -> 184.31472 | J11: =E11+G11+H11-D11 -> -4.6053102 | K11: -3.8464132 | L11: =-K11+J11 -> -0.75889695 | N11: 100.57 | O11: =N11-G11 -> 7.2
A12: 腾冲 | B12: 121.09677 | C12: 100.25263 | D12: 121.09677 | E12: 74.556415 | F12: 29.055305 | G12: 15.585824 | H12: 5 | I12: =E12+G12+H12 -> 95.14224 | J12: =E12+G12+H12-D12 -> -25.954527 | K12: -34.072877 | L12: =-K12+J12 -> 8.1183496 | N12: =VLOOKUP(A12,[4]Sheet1!$B$4:$O$16,13,FALSE) -> 15.58 | O12: =N12-G12 -> -0.005824
A13: 罗源 | B13: 159.07708 | C13: 115.44343 | D13: 159.07708 | E13: 60.550383 | F13: -3.9209268 | G13: 42.325593 | H13: 9.42 | I13: =E13+G13+H13 -> 112.29598 | J13: =E13+G13+H13-D13 -> -46.781104 | K13: -56.63476 | L13: =-K13+J13 -> 9.8536556 | N13: =VLOOKUP(A13,[4]Sheet1!$B$4:$O$16,13,FALSE) -> 35.54 | O13: =N13-G13 -> -6.7855932
A14: 连江 | B14: 289.75328 | C14: 193 | D14: 289.75328 | E14: 136.09906 | F14: 23.427445 | G14: 93.13 | H14: 7.08 | I14: =E14+G14+H14 -> 236.30906 | J14: =E14+G14+H14-D14 -> -53.444223 | K14: -53.44345 | L14: =-K14+J14 -> -0.00077255 | M14: 5月签约合同已计入4月 | N14: =VLOOKUP(A14,[4]Sheet1!$B$4:$O$16,13,FALSE) -> 93 | O14: =N14-G14 -> -0.13
A15: 版纳 | B15: 280.67058 | C15: 239.48988 | D15: 280.67058 | E15: 127.88337 | F15: 33.48674 | G15: 94.1 | H15: 3.14 | I15: =E15+G15+H15 -> 225.12337 | J15: =E15+G15+H15-D15 -> -55.547208 | K15: -57.410315 | L15: =-K15+J15 -> 1.8631064 | N15: =VLOOKUP(A15,[4]Sheet1!$B$4:$O$16,13,FALSE) -> 94 | O15: =N15-G15 -> -0.1
A16: 昆明 | B16: 2093.8022 | C16: 2112.0398 | D16: 2112.0398 | E16: 795.00726 | F16: -3.5485747 | G16: 720 | H16: 375 | I16: =E16+G16+H16 -> 1890.0073 | J16: =E16+G16+H16-D16 -> -222.0325 | K16: -218.24542 | L16: =-K16+J16 -> -3.787078 | M16: 2个合同退租，26年金额6.5万 | N16: =VLOOKUP(A16,[4]Sheet1!$B$4:$O$16,13,FALSE) -> 775.07 | O16: =N16-G16 -> 55.07
A17: 小计 | B17: =SUM(B11:B16) -> 3133.32 | C17: =SUM(C11:C16) -> 2912.2257 | D17: =SUM(D11:D16) -> 3151.5575 | E17: =SUM(E11:E16) -> 1278.1012 | F17: =SUM(F11:F16) -> 80.370696 | G17: =SUM(G11:G16) -> 1058.5114 | H17: =SUM(H11:H16) -> 406.58 | I17: =SUM(I11:I16) -> 2743.1926 | ... K17: =SUM(K11:K16) -> -423.65324 | L17: =-K17+J17 -> 15.288364 | N17: =VLOOKUP(A17,[4]Sheet1!$B$4:$O$16,13,FALSE) -> #N/A | O17: =N17-G17 -> #N/A
A18: 合计 | B18: =B10+B17 -> 7772.5858 | C18: =C10+C17 -> 7256.2211 | D18: =D10+D17 -> 7837.3316 | E18: =E10+E17 -> 3117.2123 | F18: =F10+F17 -> 35.956677 | G18: =G10+G17 -> 2707.3513 | H18: =H10+H17 -> 923.26338 | I18: =I10+I17 -> 6747.8269 | ... K18: =K10+K17 -> -1201.0575 | L18: =-K18+J18 -> 111.55281 | N18: =VLOOKUP(A18,[4]Sheet1!$B$4:$O$16,13,FALSE) -> #N/A | O18: =N18-G18 -> #N/A
B19: =I18-B18 -> -1024.7588 | C19: =I18-C18 -> -508.39415
A20: · 全年预估收入=已入账+待入账+待续签 · 与财务差异原因： 1. 宁波：换电柜业务（以生活名义对外签约）收入为每月指标划拨，未在本体空间资源应收账款未体现，公司统计时未计入待入账；经营用房、电梯广告协商退租部分、代租车位预估收入未计入待入账 2. 除宁波外，其他12家公司差额为数据导出时间不一致（本体统计时间为6月5日，财务统计时间为6月22日）

Sheet 新增及涨价
A1: 2026年2月新增及涨价
A2: 公司 | B2: 新增合同数量 | C2: 26年对应金额/万元 | D2: 涨价合同数量 | E2: 26年对应金额/万元 | F2: 合计/万元
A3: 版纳 | B3: 1 | C3: 28.644 | D3: 0 | E3: 0 | F3: =C3+E3 -> 28.644
A4: 北城 | B4: 4 | C4: 8.6 | D4: 0 | E4: 0 | F4: =C4+E4 -> 8.6
A5: 北京 | B5: 4 | C5: 5.7714215 | D5: 7 | E5: 3.972059 | F5: =C5+E5 -> 9.7434805
A6: 滨湖 | B6: 8 | C6: 10 | D6: 0 | E6: 0 | F6: =C6+E6 -> 10
A7: 阜阳 | B7: 0 | C7: 0 | D7: 0 | E7: 0 | F7: =C7+E7 -> 0
A8: 贵阳 | B8: 19 | C8: 4.3805107 | D8: 0 | E8: 0 | F8: =C8+E8 -> 4.3805107
A9: 昆明 | B9: 1 | C9: 1.03 | D9: 0 | E9: 0 | F9: =C9+E9 -> 1.03
A10: 连江 | B10: 15 | C10: 4.785266 | D10: 0 | E10: 0 | F10: =C10+E10 -> 4.785266
A11: 罗源 | B11: 1 | C11: 0.2 | D11: 0 | E11: 0 | F11: =C11+E11 -> 0.2
A12: 闽江 | B12: 3 | C12: 5.37 | D12: 0 | E12: 0 | F12: =C12+E12 -> 5.37
A13: 宁波 | B13: 4 | C13: 2 | D13: 0 | E13: 0 | F13: =C13+E13 -> 2
A14: 腾冲 | B14: 0 | C14: 0 | D14: 0 | E14: 0 | F14: =C14+E14 -> 0
A15: 长沙 | B15: 4 | C15: 3.38 | D15: 0 | E15: 0 | F15: =C15+E15 -> 3.38
A16: 合计 | B16: =SUM(B3:B15) -> 64 | C16: =SUM(C3:C15) -> 74.161198 | D16: =SUM(D3:D15) -> 7 | E16: =SUM(E3:E15) -> 3.972059 | F16: =C16+E16 -> 78.133257

Sheet 整体
A1: 经营简报（全口径）
A2: · 收费率=实收/（应收-减免），当期、历欠各项数据均为全口径
A3: 公司 | B3: 当期收费率 | J3: 历欠收费率
B4: 2026年 | E4: 2025年 | H4: 同比 | J4: 2026年 | M4: 2025年 | P4: 同比
B5: 应收 | C5: 实收 | D5: 收费率 | E5: 应收 | F5: 实收 | G5: 收费率 | H5: 实收 | I5: 收费率 | J5: 应收 | K5: 实收 | L5: 收费率 | M5: 应收 | N5: 实收 | O5: 收费率 | P5: 实收 | Q5: 收费率
A6: 北京 | B6: =VLOOKUP($A6,'[1]直收代收-26应收减免 (原)'!$AC$4:$AP$17,12,0) -> 14912.063 | C6: =VLOOKUP($A6,'[1]直收代收-26应收减免 (原)'!$AC$2:$AP$17,13,0) -> 11234.02 | D6: =C6/B6 -> 0.75335116 | E6: =VLOOKUP($A6,'[1]直收代收-25应收减免（原）'!$AC$4:$AP$17,12,0) -> 14449.351 | F6: =VLOOKUP($A6,'[1]直收代收-25应收减免（原）'!$AC$2:$AP$17,13,0) -> 11304.693 | G6: =F6/E6 -> 0.7823668 | H6: =C6-F6 -> -70.67255 | I6: =D6-G6 -> -0.029015643 | J6: =VLOOKUP($A6,'[1]直收代收-26应收减免 (原)'!$AC$26:$AP$41,12,0) -> 5998.025 | K6: =VLOOKUP($A6,'[1]直收代收-26应收减免 (原)'!$AC$26:$AP$41,13,0) -> 1279.9915 | L6: =K6/J6 -> 0.21340216 | M6: =VLOOKUP($A6,'[1]直收代收-25应收减免（原）'!$AC$26:$AP$41,12,0) -> 5330.5938 | N6: =VLOOKUP($A6,'[1]直收代收-25应收减免（原）'!$AC$26:$AP$41,13,0) -> 1501.1819 | O6: =N6/M6 -> 0.28161626 | P6: =K6-N6 -> -221.19046 | Q6: =L6-O6 -> -0.068214109
A7: 阜阳 | B7: =VLOOKUP($A7,'[1]直收代收-26应收减免 (原)'!AC$4:AP$17,12,0) -> 2276.8438 | C7: =VLOOKUP($A7,'[1]直收代收-26应收减免 (原)'!$AC$2:$AP$17,13,0) -> 1616.8871 | D7: =C7/B7 -> 0.71014406 | E7: =VLOOKUP($A7,'[1]直收代收-25应收减免（原）'!AC$4:AP$17,12,0) -> 1565.9531 | F7: =VLOOKUP($A7,'[1]直收代收-25应收减免（原）'!$AC$2:$AP$17,13,0) -> 1122.5895 | G7: =F7/E7 -> 0.71687304 | H7: =C7-F7 -> 494.29752 | I7: =D7-G7 -> -0.0067289844 | J7: =VLOOKUP($A7,'[1]直收代收-26应收减免 (原)'!$AC$26:$AP$41,12,0) -> 1210.8432 | K7: =VLOOKUP($A7,'[1]直收代收-26应收减免 (原)'!$AC$26:$AP$41,13,0) -> 819.97545 | L7: =K7/J7 -> 0.67719376 | M7: =VLOOKUP($A7,'[1]直收代收-25应收减免（原）'!$AC$26:$AP$41,12,0) -> 773.6718 | N7: =VLOOKUP($A7,'[1]直收代收-25应收减免（原）'!$AC$26:$AP$41,13,0) -> 299.38737 | O7: =N7/M7 -> 0.38696947 | P7: =K7-N7 -> 520.58808 | Q7: =L7-O7 -> 0.29022428
A8: 北城 | B8: =VLOOKUP($A8,'[1]直收代收-26应收减免 (原)'!AC$4:AP$17,12,0) -> 9214.6679 | C8: =VLOOKUP($A8,'[1]直收代收-26应收减免 (原)'!$AC$2:$AP$17,13,0) -> 6788.178 | D8: =C8/B8 -> 0.73667093 | E8: =VLOOKUP($A8,'[1]直收代收-25应收减免（原）'!AC$4:AP$17,12,0) -> 9294.7157 | F8: =VLOOKUP($A8,'[1]直收代收-25应收减免（原）'!$AC$2:$AP$17,13,0) -> 6902.0286 | G8: =F8/E8 -> 0.74257555 | H8: =C8-F8 -> -113.85063 | I8: =D8-G8 -> -0.0059046224 | J8: =VLOOKUP($A8,'[1]直收代收-26应收减免 (原)'!$AC$26:$AP$41,12,0) -> 4489.2686 | K8: =VLOOKUP($A8,'[1]直收代收-26应收减免 (原)'!$AC$26:$AP$41,13,0) -> 1255.3731 | L8: =K8/J8 -> 0.27963868 | M8: =VLOOKUP($A8,'[1]直收代收-25应收减免（原）'!$AC$26:$AP$41,12,0) -> 3753.0779 | N8: =VLOOKUP($A8,'[1]直收代收-25应收减免（原）'!$AC$26:$AP$41,13,0) -> 1119.6496 | O8: =N8/M8 -> 0.29832836 | P8: =K8-N8 -> 135.72355 | Q8: =L8-O8 -> -0.018689685
A9: 滨湖 | B9: =VLOOKUP($A9,'[1]直收代收-26应收减免 (原)'!AC$4:AP$17,12,0) -> 6445.5908 | C9: =VLOOKUP($A9,'[1]直收代收-26应收减免 (原)'!$AC$2:$AP$17,13,0) -> 4735.5027 | D9: =C9/B9 -> 0.7346887 | E9: =VLOOKUP($A9,'[1]直收代收-25应收减免（原）'!AC$4:AP$17,12,0) -> 6003.8192 | F9: =VLOOKUP($A9,'[1]直收代收-25应收减免（原）'!$AC$2:$AP$17,13,0) -> 4629.3517 | G9: =F9/E9 -> 0.77106781 | H9: =C9-F9 -> 106.151 | I9: =D9-G9 -> -0.036379112 | J9: =VLOOKUP($A9,'[1]直收代收-26应收减免 (原)'!$AC$26:$AP$41,12,0) -> 1931.0728 | K9: =VLOOKUP($A9,'[1]直收代收-26应收减免 (原)'!$AC$26:$AP$41,13,0) -> 1060.1885 | L9: =K9/J9 -> 0.54901528 | M9: =VLOOKUP($A9,'[1]直收代收-25应收减免（原）'!$AC$26:$AP$41,12,0) -> 1442.0597 | N9: =VLOOKUP($A9,'[1]直收代收-25应收减免（原）'!$AC$26:$AP$41,13,0) -> 670.54209 | O9: =N9/M9 -> 0.46498913 | P9: =K9-N9 -> 389.64639 | Q9: =L9-O9 -> 0.084026151
A10: 宁波 | B10: =VLOOKUP($A10,'[1]直收代收-26应收减免 (原)'!AC$4:AP$17,12,0) -> 7198.3088 | C10: =VLOOKUP($A10,'[1]直收代收-26应收减免 (原)'!$AC$2:$AP$17,13,0) -> 4814.5679 | D10: =C10/B10 -> 0.66884709 | E10: =VLOOKUP($A10,'[1]直收代收-25应收减免（原）'!AC$4:AP$17,12,0) -> 7472.2829 | F10: =VLOOKUP($A10,'[1]直收代收-25应收减免（原）'!$AC$2:$AP$17,13,0) -> 5328.4627 | G10: =F10/E10 -> 0.71309702 | H10: =C10-F10 -> -513.8948 | I10: =D10-G10 -> -0.044249933 | J10: =VLOOKUP($A10,'[1]直收代收-26应收减免 (原)'!$AC$26:$AP$41,12,0) -> 3598.746 | K10: =VLOOKUP($A10,'[1]直收代收-26应收减免 (原)'!$AC$26:$AP$41,13,0) -> 842.95383 | L10: =K10/J10 -> 0.23423543 | M10: =VLOOKUP($A10,'[1]直收代收-25应收减免（原）'!$AC$26:$AP$41,12,0) -> 2818.7766 | N10: =VLOOKUP($A10,'[1]直收代收-25应收减免（原）'!$AC$26:$AP$41,13,0) -> 876.45556 | O10: =N10/M10 -> 0.31093474 | P10: =K10-N10 -> -33.501733 | Q10: =L10-O10 -> -0.076699305
A11: 长沙 | B11: =VLOOKUP($A11,'[1]直收代收-26应收减免 (原)'!AC$4:AP$17,12,0) -> 4463.3638 | C11: =VLOOKUP($A11,'[1]直收代收-26应收减免 (原)'!$AC$2:$AP$17,13,0) -> 3096.0355 | D11: =C11/B11 -> 0.6936552 | E11: =VLOOKUP($A11,'[1]直收代收-25应收减免（原）'!AC$4:AP$17,12,0) -> 4329.3031 | F11: =VLOOKUP($A11,'[1]直收代收-25应收减免（原）'!$AC$2:$AP$17,13,0) -> 2783.2547 | G11: =F11/E11 -> 0.64288745 | H11: =C11-F11 -> 312.78084 | I11: =D11-G11 -> 0.050767753 | J11: =VLOOKUP($A11,'[1]直收代收-26应收减免 (原)'!$AC$26:$AP$41,12,0) -> 4177.2719 | K11: =VLOOKUP($A11,'[1]直收代收-26应收减免 (原)'!$AC$26:$AP$41,13,0) -> 387.78258 | L11: =K11/J11 -> 0.092831539 | M11: =VLOOKUP($A11,'[1]直收代收-25应收减免（原）'!$AC$26:$AP$41,12,0) -> 3797.9963 | N11: =VLOOKUP($A11,'[1]直收代收-25应收减免（原）'!$AC$26:$AP$41,13,0) -> 514.09545 | O11: =N11/M11 -> 0.13535965 | P11: =K11-N11 -> -126.31287 | Q11: =L11-O11 -> -0.042528112
A12: 贵阳 | B12: =VLOOKUP($A12,'[1]直收代收-26应收减免 (原)'!AC$4:AP$17,12,0) -> 9651.5783 | C12: =VLOOKUP($A12,'[1]直收代收-26应收减免 (原)'!$AC$2:$AP$17,13,0) -> 6908.2047 | D12: =C12/B12 -> 0.71575907 | E12: =VLOOKUP($A12,'[1]直收代收-25应收减免（原）'!AC$4:AP$17,12,0) -> 11050.52 | F12: =VLOOKUP($A12,'[1]直收代收-25应收减免（原）'!$AC$2:$AP$17,13,0) -> 7937.7606 | G12: =F12/E12 -> 0.71831559 | H12: =C12-F12 -> -1029.5559 | I12: =D12-G12 -> -0.0025565278 | J12: =VLOOKUP($A12,'[1]直收代收-26应收减免 (原)'!$AC$26:$AP$41,12,0) -> 5313.6921 | K12: =VLOOKUP($A12,'[1]直收代收-26应收减免 (原)'!$AC$26:$AP$41,13,0) -> 1464.7371 | L12: =K12/J12 -> 0.27565336 | M12: =VLOOKUP($A12,'[1]直收代收-25应收减免（原）'!$AC$26:$AP$41,12,0) -> 4460.7399 | N12: =VLOOKUP($A12,'[1]直收代收-25应收减免（原）'!$AC$26:$AP$41,13,0) -> 1301.866 | O12: =N12/M12 -> 0.2918498 | P12: =K12-N12 -> 162.87107 | Q12: =L12-O12 -> -0.016196432
A13: 广州 | B13: =VLOOKUP($A13,'[1]直收代收-26应收减免 (原)'!AC$4:AP$17,12,0) -> 649.04408 | C13: =VLOOKUP($A13,'[1]直收代收-26应收减免 (原)'!$AC$2:$AP$17,13,0) -> 385.09311 | D13: =C13/B13 -> 0.59332351 | E13: =VLOOKUP($A13,'[1]直收代收-25应收减免（原）'!AC$4:AP$17,12,0) -> 597.93157 | F13: =VLOOKUP($A13,'[1]直收代收-25应收减免（原）'!$AC$2:$AP$17,13,0) -> 87.897284 | G13: =F13/E13 -> 0.14700225 | H13: =C13-F13 -> 297.19583 | I13: =D13-G13 -> 0.44632126 | J13: =VLOOKUP($A13,'[1]直收代收-26应收减免 (原)'!$AC$26:$AP$41,12,0) -> 600.51861 | K13: =VLOOKUP($A13,'[1]直收代收-26应收减免 (原)'!$AC$26:$AP$41,13,0) -> 87.58576 | L13: =K13/J13 -> 0.1458502 | M13: =VLOOKUP($A13,'[1]直收代收-25应收减免（原）'!$AC$26:$AP$41,12,0) -> 130.68745 | N13: =VLOOKUP($A13,'[1]直收代收-25应收减免（原）'!$AC$26:$AP$41,13,0) -> 130.68745 | O13: =N13/M13 -> 0.99999999 | P13: =K13-N13 -> -43.101693 | Q13: =L13-O13 -> -0.85414979
A14: 小计 | B14: =SUM(B6:B13) -> 54811.461 | C14: =SUM(C6:C13) -> 39578.489 | D14: =C14/B14 -> 0.72208419 | E14: =SUM(E6:E13) -> 54763.876 | F14: =SUM(F6:F13) -> 40096.038 | G14: =F14/E14 -> 0.73216216 | H14: =C14-F14 -> -517.54869 | I14: =D14-G14 -> -0.010077967 | J14: =SUM(J6:J13) -> 27319.438 | K14: =SUM(K6:K13) -> 7198.5878 | L14: =K14/J14 -> 0.26349692 | M14: =SUM(M6:M13) -> 22507.603 | N14: =SUM(N6:N13) -> 6413.8655 | O14: =N14/M14 -> 0.28496439 | P14: =K14-N14 -> 784.72235 | Q14: =L14-O14 -> -0.02146747
A15: 昆明 | B15: =VLOOKUP($A15,'[1]直收代收-26应收减免 (原)'!AC$4:AP$17,12,0) -> 5853.1317 | C15: =VLOOKUP($A15,'[1]直收代收-26应收减免 (原)'!$AC$2:$AP$17,13,0) -> 4775.0479 | D15: =C15/B15 -> 0.81581077 | E15: =VLOOKUP($A15,'[1]直收代收-25应收减免（原）'!AC$4:AP$17,12,0) -> 6238.5545 | F15: =VLOOKUP($A15,'[1]直收代收-25应收减免（原）'!$AC$2:$AP$17,13,0) -> 4975.4186 | G15: =F15/E15 -> 0.79752747 | H15: =C15-F15 -> -200.3707 | I15: =D15-G15 -> 0.018283305 | J15: =VLOOKUP($A15,'[1]直收代收-26应收减免 (原)'!$AC$26:$AP$41,12,0) -> 3212.3007 | K15: =VLOOKUP($A15,'[1]直收代收-26应收减免 (原)'!$AC$26:$AP$41,13,0) -> 452.93953 | L15: =K15/J15 -> 0.1410016 | M15: =VLOOKUP($A15,'[1]直收代收-25应收减免（原）'!$AC$26:$AP$41,12,0) -> 2944.6509 | N15: =VLOOKUP($A15,'[1]直收代收-25应收减免（原）'!$AC$26:$AP$41,13,0) -> 468.57213 | O15: =N15/M15 -> 0.15912655 | P15: =K15-N15 -> -15.632608 | Q15: =L15-O15 -> -0.018124953
A16: 罗源 | B16: =VLOOKUP($A16,'[1]直收代收-26应收减免 (原)'!AC$4:AP$17,12,0) -> 5421.7286 | C16: =VLOOKUP($A16,'[1]直收代收-26应收减免 (原)'!$AC$2:$AP$17,13,0) -> 4012.0905 | D16: =C16/B16 -> 0.74000209 | E16: =VLOOKUP($A16,'[1]直收代收-25应收减免（原）'!AC$4:AP$17,12,0) -> 5439.3206 | F16: =VLOOKUP($A16,'[1]直收代收-25应收减免（原）'!$AC$2:$AP$17,13,0) -> 3822.0052 | G16: =F16/E16 -> 0.70266225 | H16: =C16-F16 -> 190.08526 | I16: =D16-G16 -> 0.037339845 | J16: =VLOOKUP($A16,'[1]直收代收-26应收减免 (原)'!$AC$26:$AP$41,12,0) -> 3149.5945 | K16: =VLOOKUP($A16,'[1]直收代收-26应收减免 (原)'!$AC$26:$AP$41,13,0) -> 1353.3005 | L16: =K16/J16 -> 0.42967454 | M16: =VLOOKUP($A16,'[1]直收代收-25应收减免（原）'!$AC$26:$AP$41,12,0) -> 2991.0053 | N16: =VLOOKUP($A16,'[1]直收代收-25应收减免（原）'!$AC$26:$AP$41,13,0) -> 1371.381 | O16: =N16/M16 -> 0.45850168 | P16: =K16-N16 -> -18.080408 | Q16: =L16-O16 -> -0.028827145
A17: 闽江 | B17: =VLOOKUP($A17,'[1]直收代收-26应收减免 (原)'!AC$4:AP$17,12,0) -> 3823.9109 | C17: =VLOOKUP($A17,'[1]直收代收-26应收减免 (原)'!$AC$2:$AP$17,13,0) -> 2726.4989 | D17: =C17/B17 -> 0.71301318 | E17: =VLOOKUP($A17,'[1]直收代收-25应收减免（原）'!AC$4:AP$17,12,0) -> 3711.761 | F17: =VLOOKUP($A17,'[1]直收代收-25应收减免（原）'!$AC$2:$AP$17,13,0) -> 2709.7939 | G17: =F17/E17 -> 0.73005613 | H17: =C17-F17 -> 16.705025 | I17: =D17-G17 -> -0.017042948 | J17: =VLOOKUP($A17,'[1]直收代收-26应收减免 (原)'!$AC$26:$AP$41,12,0) -> 889.39873 | K17: =VLOOKUP($A17,'[1]直收代收-26应收减免 (原)'!$AC$26:$AP$41,13,0) -> 453.54584 | L17: =K17/J17 -> 0.50994657 | M17: =VLOOKUP($A17,'[1]直收代收-25应收减免（原）'!$AC$26:$AP$41,12,0) -> 681.21751 | N17: =VLOOKUP($A17,'[1]直收代收-25应收减免（原）'!$AC$26:$AP$41,13,0) -> 313.57395 | O17: =N17/M17 -> 0.46031398 | P17: =K17-N17 -> 139.97189 | Q17: =L17-O17 -> 0.04963259
A18: 腾冲 | B18: =VLOOKUP($A18,'[1]直收代收-26应收减免 (原)'!AC$4:AP$17,12,0) -> 2202.1943 | C18: =VLOOKUP($A18,'[1]直收代收-26应收减免 (原)'!$AC$2:$AP$17,13,0) -> 1575.6506 | D18: =C18/B18 -> 0.7154912 | E18: =VLOOKUP($A18,'[1]直收代收-25应收减免（原）'!AC$4:AP$17,12,0) -> 2108.8585 | F18: =VLOOKUP($A18,'[1]直收代收-25应收减免（原）'!$AC$2:$AP$17,13,0) -> 1600.6164 | G18: =F18/E18 -> 0.75899656 | H18: =C18-F18 -> -24.965758 | I18: =D18-G18 -> -0.043505362 | J18: =VLOOKUP($A18,'[1]直收代收-26应收减免 (原)'!$AC$26:$AP$41,12,0) -> 1368.2813 | K18: =VLOOKUP($A18,'[1]直收代收-26应收减免 (原)'!$AC$26:$AP$41,13,0) -> 243.65507 | L18: =K18/J18 -> 0.17807381 | M18: =VLOOKUP($A18,'[1]直收代收-25应收减免（原）'!$AC$26:$AP$41,12,0) -> 1265.3366 | N18: =VLOOKUP($A18,'[1]直收代收-25应收减免（原）'!$AC$26:$AP$41,13,0) -> 153.16636 | O18: =N18/M18 -> 0.12104791 | P18: =K18-N18 -> 90.488718 | Q18: =L18-O18 -> 0.057025901
A19: 连江 | B19: =VLOOKUP($A19,'[1]直收代收-26应收减免 (原)'!AC$4:AP$17,12,0) -> 5230.6058 | C19: =VLOOKUP($A19,'[1]直收代收-26应收减免 (原)'!$AC$2:$AP$17,13,0) -> 3376.9428 | D19: =C19/B19 -> 0.64561217 | E19: =VLOOKUP($A19,'[1]直收代收-25应收减免（原）'!AC$4:AP$17,12,0) -> 5039.9099 | F19: =VLOOKUP($A19,'[1]直收代收-25应收减免（原）'!$AC$2:$AP$17,13,0) -> 3227.1614 | G19: =F19/E19 -> 0.64032125 | H19: =C19-F19 -> 149.78137 | I19: =D19-G19 -> 0.0052909277 | J19: =VLOOKUP($A19,'[1]直收代收-26应收减免 (原)'!$AC$26:$AP$41,12,0) -> 4631.8485 | K19: =VLOOKUP($A19,'[1]直收代收-26应收减免 (原)'!$AC$26:$AP$41,13,0) -> 1163.7737 | L19: =K19/J19 -> 0.2512547 | M19: =VLOOKUP($A19,'[1]直收代收-25应收减免（原）'!$AC$26:$AP$41,12,0) -> 4173.3728 | N19: =VLOOKUP($A19,'[1]直收代收-25应收减免（原）'!$AC$26:$AP$41,13,0) -> 1208.2881 | O19: =N19/M19 -> 0.28952317 | P19: =K19-N19 -> -44.514408 | Q19: =L19-O19 -> -0.038268466
A20: 版纳 | B20: =VLOOKUP($A20,'[1]直收代收-26应收减免 (原)'!AC$4:AP$17,12,0) -> 2624.3694 | C20: =VLOOKUP($A20,'[1]直收代收-26应收减免 (原)'!$AC$2:$AP$17,13,0) -> 1408.1766 | D20: =C20/B20 -> 0.53657712 | E20: =VLOOKUP($A20,'[1]直收代收-25应收减免（原）'!AC$4:AP$17,12,0) -> 2525.0557 | F20: =VLOOKUP($A20,'[1]直收代收-25应收减免（原）'!$AC$2:$AP$17,13,0) -> 1227.2877 | G20: =F20/E20 -> 0.48604382 | H20: =C20-F20 -> 180.88886 | I20: =D20-G20 -> 0.0505333 | J20: =VLOOKUP($A20,'[1]直收代收-26应收减免 (原)'!$AC$26:$AP$41,12,0) -> 2045.2657 | K20: =VLOOKUP($A20,'[1]直收代收-26应收减免 (原)'!$AC$26:$AP$41,13,0) -> 372.14333 | L20: =K20/J20 -> 0.18195354 | M20: =VLOOKUP($A20,'[1]直收代收-25应收减免（原）'!$AC$26:$AP$41,12,0) -> 1867.7669 | N20: =VLOOKUP($A20,'[1]直收代收-25应收减免（原）'!$AC$26:$AP$41,13,0) -> 340.78943 | O20: =N20/M20 -> 0.18245822 | P20: =K20-N20 -> 31.353906 | Q20: =L20-O20 -> -0.00050467674
A21: 小计 | B21: =SUM(B15:B20) -> 25155.941 | C21: =SUM(C15:C20) -> 17874.407 | D21: =C21/B21 -> 0.71054418 | E21: =SUM(E15:E20) -> 25063.46 | F21: =SUM(F15:F20) -> 17562.283 | G21: =F21/E21 -> 0.70071263 | H21: =C21-F21 -> 312.12407 | I21: =D21-G21 -> 0.0098315498 | J21: =SUM(J15:J20) -> 15296.689 | K21: =SUM(K15:K20) -> 4039.358 | L21: =K21/J21 -> 0.26406747 | M21: =SUM(M15:M20) -> 13923.35 | N21: =SUM(N15:N20) -> 3855.7709 | O21: =N21/M21 -> 0.27692839 | P21: =K21-N21 -> 183.58709 | Q21: =L21-O21 -> -0.012860924
A22: 合计 | B22: =B21+B14 -> 79967.401 | C22: =C21+C14 -> 57452.896 | D22: =C22/B22 -> 0.71845396 | E22: =E21+E14 -> 79827.337 | F22: =F21+F14 -> 57658.321 | G22: =F22/E22 -> 0.72228792 | H22: =C22-F22 -> -205.42462 | I22: =D22-G22 -> -0.0038339581 | J22: =J21+J14 -> 42616.128 | K22: =K21+K14 -> 11237.946 | L22: =K22/J22 -> 0.26370171 | M22: =M21+M14 -> 36430.954 | N22: =N21+N14 -> 10269.636 | O22: =N22/M22 -> 0.28189315 | P22: =K22-N22 -> 968.30944 | Q22: =L22-O22 -> -0.018191442

Sheet 当期-费项
A1: 当期收费简报-自建
A2: · 收费率=实收/（应收-减免），其他项不含筑科案场服务费
A3: 公司 | B3: 直收项（物、车） | J3: 代收项（代收水电、公摊水电） | R3: 其他项（不含筑科案场服务费） | Z3: 合计 | AH3: 备注
B4: 2026年 | E4: 2025年 | H4: 同比 | J4: 2026年 | M4: 2025年 | P4: 同比 | R4: 2026年 | U4: 2025年 | X4: 同比 | Z4: 2026年 | AC4: 2025年 | AF4: 同比
B5: 应收 | C5: 实收 | D5: 收费率 | E5: 应收 | F5: 实收 | G5: 收费率 | H5: 实收 | I5: 收费率 | J5: 应收 | K5: 实收 | L5: 收费率 | M5: 应收 | N5: 实收 | O5: 收费率 | P5: 实收 | Q5: 收费率 | R5: 应收 | S5: 实收 | T5: 收费率 | U5: 应收 | V5: 实收 | W5: 收费率 | X5: 实收 | Y5: 收费率 | Z5: 应收 | AA5: 实收 | AB5: 收费率 | AC5: 应收 | AD5: 实收 | AE5: 收费率 | AF5: 实收 | AG5: 收费率
A6: 滨湖 | B6: =VLOOKUP($A6,'[1]直收代收-26应收减免 (调整)'!$A$27:$K$42,3,0) -> 2514.7632 | C6: =VLOOKUP($A6,'[1]直收代收-26应收减免 (调整)'!$A$27:$K$42,4,0) -> 2051.1169 | D6: =IF(B6>0,C6/B6,"——") -> 0.81563023 | E6: =VLOOKUP($A6,'[1]直收代收-25应收减免（调整）'!$A$27:$K$42,3,0) -> 2521.9441 | F6: =VLOOKUP($A6,'[1]直收代收-25应收减免（调整）'!$A$27:$K$42,4,0) -> 2056.3547 | G6: =IF(E6>0,F6/E6,"——") -> 0.81538473 | H6: =C6-F6 -> -5.237806 | I6: =D6-G6 -> 0.00024550273 | J6: =VLOOKUP($A6,'[1]直收代收-26应收减免 (调整)'!$A$27:$K$42,6,0) -> 949.10693 | K6: =VLOOKUP($A6,'[1]直收代收-26应收减免 (调整)'!$A$27:$K$42,7,0) -> 920.72959 | L6: =IF(J6>0,K6/J6,"——") -> 0.97010101 | M6: =VLOOKUP($A6,'[1]直收代收-25应收减免（调整）'!$A$27:$K$42,6,0) -> 904.29329 | N6: =VLOOKUP($A6,'[1]直收代收-25应收减免（调整）'!$A$27:$K$42,7,0) -> 872.36029 | O6: =IF(M6>0,N6/M6,"——") -> 0.96468733 | P6: =K6-N6 -> 48.369303 | Q6: =(K6/J6)-(N6/M6) -> 0.0054136755 | R6: =VLOOKUP($A6,'[1]直收代收-26应收减免 (调整)'!$A$27:$K$42,9,0) -> 391.74631 | S6: =VLOOKUP($A6,'[1]直收代收-26应收减免 (调整)'!$A$27:$K$42,10,0) -> 344.78159 | T6: =IF(R6>0,S6/R6,"——") -> 0.88011446 | U6: =VLOOKUP($A6,'[1]直收代收-25应收减免（调整）'!$A$27:$K$42,9,0) -> 381.20346 | V6: =VLOOKUP($A6,'[1]直收代收-25应收减免（调整）'!$A$27:$K$42,10,0) -> 328.01389 | W6: =IF(U6>0,V6/U6,"——") -> 0.86046934 | X6: =S6-V6 -> 16.767705 | Y6: =(S6/R6)-(V6/U6) -> 0.019645122 | Z6: =B6+J6+R6 -> 3855.6164 | AA6: =C6+K6+S6 -> 3316.6281 | AB6: =IF(Z6>0,AA6/Z6,"——") -> 0.86020695 | AC6: =E6+M6+U6 -> 3807.4408 | AD6: =F6+N6+V6 -> 3256.7289 | AE6: =IF(AC6>0,AD6/AC6,"——") -> 0.85535902 | AF6: =AA6-AD6 -> 59.899202 | AG6: =(AA6/Z6)-(AD6/AC6) -> 0.0048479329
A7: 贵阳 | B7: =VLOOKUP($A7,'[1]直收代收-26应收减免 (调整)'!$A$27:$K$42,3,0) -> 4290.5413 | C7: =VLOOKUP($A7,'[1]直收代收-26应收减免 (调整)'!$A$27:$K$42,4,0) -> 3323.571 | D7: =IF(B7>0,C7/B7,"——") -> 0.77462743 | E7: =VLOOKUP($A7,'[1]直收代收-25应收减免（调整）'!$A$27:$K$42,3,0) -> 4605.0374 | F7: =VLOOKUP($A7,'[1]直收代收-25应收减免（调整）'!$A$27:$K$42,4,0) -> 3313.6713 | G7: =IF(E7>0,F7/E7,"——") -> 0.71957533 | H7: =C7-F7 -> 9.899679 | I7: =D7-G7 -> 0.055052104 | J7: =VLOOKUP($A7,'[1]直收代收-26应收减免 (调整)'!$A$27:$K$42,6,0) -> 1798.6104 | K7: =VLOOKUP($A7,'[1]直收代收-26应收减免 (调整)'!$A$27:$K$42,7,0) -> 1753.2597 | L7: =IF(J7>0,K7/J7,"——") -> 0.97478568 | M7: =VLOOKUP($A7,'[1]直收代收-25应收减免（调整）'!$A$27:$K$42,6,0) -> 1945.9926 | N7: =VLOOKUP($A7,'[1]直收代收-25应收减免（调整）'!$A$27:$K$42,7,0) -> 1870.9419 | O7: =IF(M7>0,N7/M7,"——") -> 0.96143321 | P7: =K7-N7 -> -117.68221 | Q7: =(K7/J7)-(N7/M7) -> 0.013352462 | R7: =VLOOKUP($A7,'[1]直收代收-26应收减免 (调整)'!$A$27:$K$42,9,0) -> 562.83894 | S7: =VLOOKUP($A7,'[1]直收代收-26应收减免 (调整)'!$A$27:$K$42,10,0) -> 501.56484 | T7: =IF(R7>0,S7/R7,"——") -> 0.89113386 | U7: =VLOOKUP($A7,'[1]直收代收-25应收减免（调整）'!$A$27:$K$42,9,0) -> 584.93554 | V7: =VLOOKUP($A7,'[1]直收代收-25应收减免（调整）'!$A$27:$K$42,10,0) -> 479.35776 | W7: =IF(U7>0,V7/U7,"——") -> 0.81950526 | X7: =S7-V7 -> 22.207079 | Y7: =(S7/R7)-(V7/U7) -> 0.071628593 | Z7: =B7+J7+R7 -> 6651.9906 | AA7: =C7+K7+S7 -> 5578.3955 | AB7: =IF(Z7>0,AA7/Z7,"——") -> 0.83860543 | AC7: =E7+M7+U7 -> 7135.9655 | AD7: =F7+N7+V7 -> 5663.9709 | AE7: =IF(AC7>0,AD7/AC7,"——") -> 0.79372174 | AF7: =AA7-AD7 -> -85.575457 | AG7: =(AA7/Z7)-(AD7/AC7) -> 0.044883694
A8: 北京 | B8: =VLOOKUP($A8,'[1]直收代收-26应收减免 (调整)'!$A$27:$K$42,3,0) -> 8869.0727 | C8: =VLOOKUP($A8,'[1]直收代收-26应收减免 (调整)'!$A$27:$K$42,4,0) -> 7165.5783 | D8: =IF(B8>0,C8/B8,"——") -> 0.8079287 | E8: =VLOOKUP($A8,'[1]直收代收-25应收减免（调整）'!$A$27:$K$42,3,0) -> 8899.6998 | F8: =VLOOKUP($A8,'[1]直收代收-25应收减免（调整）'!$A$27:$K$42,4,0) -> 7293.9654 | G8: =IF(E8>0,F8/E8,"——") -> 0.81957433 | H8: =C8-F8 -> -128.3871 | I8: =D8-G8 -> -0.011645626 | J8: =VLOOKUP($A8,'[1]直收代收-26应收减免 (调整)'!$A$27:$K$42,6,0) -> 1014.4345 | K8: =VLOOKUP($A8,'[1]直收代收-26应收减免 (调整)'!$A$27:$K$42,7,0) -> 991.5658 | L8: =IF(J8>0,K8/J8,"——") -> 0.9774567 | M8: =VLOOKUP($A8,'[1]直收代收-25应收减免（调整）'!$A$27:$K$42,6,0) -> 1132.328 | N8: =VLOOKUP($A8,'[1]直收代收-25应收减免（调整）'!$A$27:$K$42,7,0) -> 1103.3812 | O8: =IF(M8>0,N8/M8,"——") -> 0.97443606 | P8: =K8-N8 -> -111.81539 | Q8: =(K8/J8)-(N8/M8) -> 0.0030206346 | R8: =VLOOKUP($A8,'[1]直收代收-26应收减免 (调整)'!$A$27:$K$42,9,0) -> 657.40772 | S8: =VLOOKUP($A8,'[1]直收代收-26应收减免 (调整)'!$A$27:$K$42,10,0) -> 561.14153 | T8: =IF(R8>0,S8/R8,"——") -> 0.85356699 | U8: =VLOOKUP($A8,'[1]直收代收-25应收减免（调整）'!$A$27:$K$42,9,0) -> 740.3482 | V8: =VLOOKUP($A8,'[1]直收代收-25应收减免（调整）'!$A$27:$K$42,10,0) -> 701.26983 | W8: =IF(U8>0,V8/U8,"——") -> 0.94721623 | X8: =S8-V8 -> -140.1283 | Y8: =(S8/R8)-(V8/U8) -> -0.093649243 | Z8: =B8+J8+R8 -> 10540.915 | AA8: =C8+K8+S8 -> 8718.2857 | AB8: =IF(Z8>0,AA8/Z8,"——") -> 0.82709004 | AC8: =E8+M8+U8 -> 10772.376 | AD8: =F8+N8+V8 -> 9098.6165 | AE8: =IF(AC8>0,AD8/AC8,"——") -> 0.84462486 | AF8: =AA8-AD8 -> -380.33079 | AG8: =(AA8/Z8)-(AD8/AC8) -> -0.01753482 | AH8: 电梯广告收入减少
A9: 北城 | B9: =VLOOKUP($A9,'[1]直收代收-26应收减免 (调整)'!$A$27:$K$42,3,0) -> 4342.98 | C9: =VLOOKUP($A9,'[1]直收代收-26应收减免 (调整)'!$A$27:$K$42,4,0) -> 3218.6259 | D9: =IF(B9>0,C9/B9,"——") -> 0.74110999 | E9: =VLOOKUP($A9,'[1]直收代收-25应收减免（调整）'!$A$27:$K$42,3,0) -> 4326.9119 | F9: =VLOOKUP($A9,'[1]直收代收-25应收减免（调整）'!$A$27:$K$42,4,0) -> 3293.333 | G9: =IF(E9>0,F9/E9,"——") -> 0.7611278 | H9: =C9-F9 -> -74.707066 | I9: =D9-G9 -> -0.020017811 | J9: =VLOOKUP($A9,'[1]直收代收-26应收减免 (调整)'!$A$27:$K$42,6,0) -> 1455.4637 | K9: =VLOOKUP($A9,'[1]直收代收-26应收减免 (调整)'!$A$27:$K$42,7,0) -> 1392.9849 | L9: =IF(J9>0,K9/J9,"——") -> 0.95707296 | M9: =VLOOKUP($A9,'[1]直收代收-25应收减免（调整）'!$A$27:$K$42,6,0) -> 1529.8701 | N9: =VLOOKUP($A9,'[1]直收代收-25应收减免（调整）'!$A$27:$K$42,7,0) -> 1467.8836 | O9: =IF(M9>0,N9/M9,"——") -> 0.95948248 | P9: =K9-N9 -> -74.89867 | Q9: =(K9/J9)-(N9/M9) -> -0.002409523 | R9: =VLOOKUP($A9,'[1]直收代收-26应收减免 (调整)'!$A$27:$K$42,9,0) -> 564.31587 | S9: =VLOOKUP($A9,'[1]直收代收-26应收减免 (调整)'!$A$27:$K$42,10,0) -> 510.82318 | T9: =IF(R9>0,S9/R9,"——") -> 0.90520789 | U9: =VLOOKUP($A9,'[1]直收代收-25应收减免（调整）'!$A$27:$K$42,9,0) -> 558.91131 | V9: =VLOOKUP($A9,'[1]直收代收-25应收减免（调整）'!$A$27:$K$42,10,0) -> 515.36652 | W9: =IF(U9>0,V9/U9,"——") -> 0.92208997 | X9: =S9-V9 -> -4.543336 | Y9: =(S9/R9)-(V9/U9) -> -0.016882081 | Z9: =B9+J9+R9 -> 6362.7596 | AA9: =C9+K9+S9 -> 5122.434 | AB9: =IF(Z9>0,AA9/Z9,"——") -> 0.80506484 | AC9: =E9+M9+U9 -> 6415.6934 | AD9: =F9+N9+V9 -> 5276.5831 | AE9: =IF(AC9>0,AD9/AC9,"——") -> 0.82244939 | AF9: =AA9-AD9 -> -154.14907 | AG9: =(AA9/Z9)-(AD9/AC9) -> -0.01738455 | AH9: 空置商铺、公寓未缴费，现尝试分段收费
A10: 阜阳 | B10: =VLOOKUP($A10,'[1]直收代收-26应收减免 (调整)'!$A$27:$K$42,3,0) -> 851.2774 | C10: =VLOOKUP($A10,'[1]直收代收-26应收减免 (调整)'!$A$27:$K$42,4,0) -> 643.96349 | D10: =IF(B10>0,C10/B10,"——") -> 0.75646727 | E10: =VLOOKUP($A10,'[1]直收代收-25应收减免（调整）'!$A$27:$K$42,3,0) -> 806.94731 | F10: =VLOOKUP($A10,'[1]直收代收-25应收减免（调整）'!$A$27:$K$42,4,0) -> 621.76625 | G10: =IF(E10>0,F10/E10,"——") -> 0.77051655 | H10: =C10-F10 -> 22.197239 | I10: =D10-G10 -> -0.014049279 | J10: =VLOOKUP($A10,'[1]直收代收-26应收减免 (调整)'!$A$27:$K$42,6,0) -> 32.198583 | K10: =VLOOKUP($A10,'[1]直收代收-26应收减免 (调整)'!$A$27:$K$42,7,0) -> 25.287683 | L10: =IF(J10>0,K10/J10,"——") -> 0.78536633 | M10: =VLOOKUP($A10,'[1]直收代收-25应收减免（调整）'!$A$27:$K$42,6,0) -> 21.661296 | N10: =VLOOKUP($A10,'[1]直收代收-25应收减免（调整）'!$A$27:$K$42,7,0) -> 12.471187 | O10: =IF(M10>0,N10/M10,"——") -> 0.57573596 | P10: =K10-N10 -> 12.816496 | Q10: =(K10/J10)-(N10/M10) -> 0.20963037 | R10: =VLOOKUP($A10,'[1]直收代收-26应收减免 (调整)'!$A$27:$K$42,9,0) -> 134.77037 | S10: =VLOOKUP($A10,'[1]直收代收-26应收减免 (调整)'!$A$27:$K$42,10,0) -> 109.11894 | T10: =IF(R10>0,S10/R10,"——") -> 0.80966567 | U10: =VLOOKUP($A10,'[1]直收代收-25应收减免（调整）'!$A$27:$K$42,9,0) -> 123.624 | V10: =VLOOKUP($A10,'[1]直收代收-25应收减免（调整）'!$A$27:$K$42,10,0) -> 98.413895 | W10: =IF(U10>0,V10/U10,"——") -> 0.79607435 | X10: =S10-V10 -> 10.70505 | Y10: =(S10/R10)-(V10/U10) -> 0.013591328 | Z10: =B10+J10+R10 -> 1018.2464 | AA10: =C10+K10+S10 -> 778.37012 | AB10: =IF(Z10>0,AA10/Z10,"——") -> 0.7644222 | AC10: =E10+M10+U10 -> 952.2326 | AD10: =F10+N10+V10 -> 732.65133 | AE10: =IF(AC10>0,AD10/AC10,"——") -> 0.76940375 | AF10: =AA10-AD10 -> 45.718785 | AG10: =(AA10/Z10)-(AD10/AC10) -> -0.0049815512
A11: 长沙 | B11: =VLOOKUP($A11,'[1]直收代收-26应收减免 (调整)'!$A$27:$K$42,3,0) -> 2417.6103 | C11: =VLOOKUP($A11,'[1]直收代收-26应收减免 (调整)'!$A$27:$K$42,4,0) -> 1681.6839 | D11: =IF(B11>0,C11/B11,"——") -> 0.69559761 | E11: =VLOOKUP($A11,'[1]直收代收-25应收减免（调整）'!$A$27:$K$42,3,0) -> 2417.8255 | F11: =VLOOKUP($A11,'[1]直收代收-25应收减免（调整）'!$A$27:$K$42,4,0) -> 1718.8282 | G11: =IF(E11>0,F11/E11,"——") -> 0.71089839 | H11: =C11-F11 -> -37.144329 | I11: =D11-G11 -> -0.01530078 | J11: =VLOOKUP($A11,'[1]直收代收-26应收减免 (调整)'!$A$27:$K$42,6,0) -> 754.66352 | K11: =VLOOKUP($A11,'[1]直收代收-26应收减免 (调整)'!$A$27:$K$42,7,0) -> 718.62116 | L11: =IF(J11>0,K11/J11,"——") -> 0.95224049 | M11: =VLOOKUP($A11,'[1]直收代收-25应收减免（调整）'!$A$27:$K$42,6,0) -> 945.57957 | N11: =VLOOKUP($A11,'[1]直收代收-25应收减免（调整）'!$A$27:$K$42,7,0) -> 619.76893 | O11: =IF(M11>0,N11/M11,"——") -> 0.65543816 | P11: =K11-N11 -> 98.852224 | Q11: =(K11/J11)-(N11/M11) -> 0.29680233 | R11: =VLOOKUP($A11,'[1]直收代收-26应收减免 (调整)'!$A$27:$K$42,9,0) -> 256.11729 | S11: =VLOOKUP($A11,'[1]直收代收-26应收减免 (调整)'!$A$27:$K$42,10,0) -> 219.55859 | T11: =IF(R11>0,S11/R11,"——") -> 0.85725799 | U11: =VLOOKUP($A11,'[1]直收代收-25应收减免（调整）'!$A$27:$K$42,9,0) -> 262.49448 | V11: =VLOOKUP($A11,'[1]直收代收-25应收减免（调整）'!$A$27:$K$42,10,0) -> 193.9399 | W11: =IF(U11>0,V11/U11,"——") -> 0.73883423 | X11: =S11-V11 -> 25.618686 | Y11: =(S11/R11)-(V11/U11) -> 0.11842376 | Z11: =B11+J11+R11 -> 3428.3911 | AA11: =C11+K11+S11 -> 2619.8636 | AB11: =IF(Z11>0,AA11/Z11,"——") -> 0.7641671 | AC11: =E11+M11+U11 -> 3625.8995 | AD11: =F11+N11+V11 -> 2532.5371 | AE11: =IF(AC11>0,AD11/AC11,"——") -> 0.6984576 | AF11: =AA11-AD11 -> 87.326581 | AG11: =(AA11/Z11)-(AD11/AC11) -> 0.065709503 | AH11: A区收费进度较慢
A12: 宁波 | B12: =VLOOKUP($A12,'[1]直收代收-26应收减免 (调整)'!$A$27:$K$42,3,0) -> 5529.1448 | C12: =VLOOKUP($A12,'[1]直收代收-26应收减免 (调整)'!$A$27:$K$42,4,0) -> 3555.1314 | D12: =IF(B12>0,C12/B12,"——") -> 0.64298035 | E12: =VLOOKUP($A12,'[1]直收代收-25应收减免（调整）'!$A$27:$K$42,3,0) -> 5510.9037 | F12: =VLOOKUP($A12,'[1]直收代收-25应收减免（调整）'!$A$27:$K$42,4,0) -> 3813.9914 | G12: =IF(E12>0,F12/E12,"——") -> 0.69208094 | H12: =C12-F12 -> -258.86001 | I12: =D12-G12 -> -0.049100596 | J12: =VLOOKUP($A12,'[1]直收代收-26应收减免 (调整)'!$A$27:$K$42,6,0) -> 466.48441 | K12: =VLOOKUP($A12,'[1]直收代收-26应收减免 (调整)'!$A$27:$K$42,7,0) -> 446.78034 | L12: =IF(J12>0,K12/J12,"——") -> 0.95776049 | M12: =VLOOKUP($A12,'[1]直收代收-25应收减免（调整）'!$A$27:$K$42,6,0) -> 533.62792 | N12: =VLOOKUP($A12,'[1]直收代收-25应收减免（调整）'!$A$27:$K$42,7,0) -> 494.90902 | O12: =IF(M12>0,N12/M12,"——") -> 0.92744214 | P12: =K12-N12 -> -48.128678 | Q12: =(K12/J12)-(N12/M12) -> 0.030318345 | R12: =VLOOKUP($A12,'[1]直收代收-26应收减免 (调整)'!$A$27:$K$42,9,0) -> 832.77407 | S12: =VLOOKUP($A12,'[1]直收代收-26应收减免 (调整)'!$A$27:$K$42,10,0) -> 699.32551 | T12: =IF(R12>0,S12/R12,"——") -> 0.83975419 | U12: =VLOOKUP($A12,'[1]直收代收-25应收减免（调整）'!$A$27:$K$42,9,0) -> 777.97955 | V12: =VLOOKUP($A12,'[1]直收代收-25应收减免（调整）'!$A$27:$K$42,10,0) -> 807.18764 | W12: =IF(U12>0,V12/U12,"——") -> 1.0375435 | X12: =S12-V12 -> -107.86213 | Y12: =(S12/R12)-(V12/U12) -> -0.19778933 | Z12: =B12+J12+R12 -> 6828.4032 | AA12: =C12+K12+S12 -> 4701.2373 | AB12: =IF(Z12>0,AA12/Z12,"——") -> 0.68848267 | AC12: =E12+M12+U12 -> 6822.5112 | AD12: =F12+N12+V12 -> 5116.0881 | AE12: =IF(AC12>0,AD12/AC12,"——") -> 0.74988343 | AF12: =AA12-AD12 -> -414.85082 | AG12: =(AA12/Z12)-(AD12/AC12) -> -0.061400766 | AH12: 1. 直收：空置房、管委会未缴费 2. 其他：5间经营用房退租
A13: 小计 | B13: =SUM(B6:B12) -> 28815.39 | C13: =SUM(C6:C12) -> 21639.671 | D13: =C13/B13 -> 0.75097617 | E13: =SUM(E6:E12) -> 29089.27 | F13: =SUM(F6:F12) -> 22111.91 | G13: =F13/E13 -> 0.76013975 | H13: =SUM(H6:H12) -> -472.23939 | I13: =D13-G13 -> -0.0091635847 | J13: =SUM(J6:J12) -> 6470.9621 | K13: =SUM(K6:K12) -> 6249.2292 | L13: =K13/J13 -> 0.96573417 | M13: =SUM(M6:M12) -> 7013.3527 | N13: =SUM(N6:N12) -> 6441.7161 | O13: =N13/M13 -> 0.9184931 | P13: =SUM(P6:P12) -> -192.48693 | Q13: =L13-O13 -> 0.047241071 | R13: =SUM(R6:R12) -> 3399.9706 | S13: =SUM(S6:S12) -> 2946.3142 | T13: =S13/R13 -> 0.8665705 | U13: =SUM(U6:U12) -> 3429.4965 | V13: =SUM(V6:V12) -> 3123.5494 | W13: =V13/U13 -> 0.9107895 | X13: =SUM(X6:X12) -> -177.23525 | Y13: =T13-W13 -> -0.044219003 | Z13: =SUM(Z6:Z12) -> 38686.322 | AA13: =SUM(AA6:AA12) -> 30835.214 | AB13: =AA13/Z13 -> 0.79705727 | AC13: =SUM(AC6:AC12) -> 39532.119 | AD13: =SUM(AD6:AD12) -> 31677.176 | AE13: =AD13/AC13 -> 0.80130225 | AF13: =SUM(AF6:AF12) -> -841.96157 | AG13: =AB13-AE13 -> -0.0042449823
A14: 昆明 | B14: =VLOOKUP($A14,'[1]直收代收-26应收减免 (调整)'!$A$27:$K$42,3,0) -> 2277.0127 | C14: =VLOOKUP($A14,'[1]直收代收-26应收减免 (调整)'!$A$27:$K$42,4,0) -> 2048.9924 | D14: =IF(B14>0,C14/B14,"——") -> 0.89985988 | E14: =VLOOKUP($A14,'[1]直收代收-25应收减免（调整）'!$A$27:$K$42,3,0) -> 2202.1173 | F14: =VLOOKUP($A14,'[1]直收代收-25应收减免（调整）'!$A$27:$K$42,4,0) -> 1990.2533 | G14: =IF(E14>0,F14/E14,"——") -> 0.90379074 | H14: =C14-F14 -> 58.739099 | I14: =D14-G14 -> -0.003930865 | J14: =VLOOKUP($A14,'[1]直收代收-26应收减免 (调整)'!$A$27:$K$42,6,0) -> 662.30594 | K14: =VLOOKUP($A14,'[1]直收代收-26应收减免 (调整)'!$A$27:$K$42,7,0) -> 632.49948 | L14: =IF(J14>0,K14/J14,"——") -> 0.95499593 | M14: =VLOOKUP($A14,'[1]直收代收-25应收减免（调整）'!$A$27:$K$42,6,0) -> 654.62048 | N14: =VLOOKUP($A14,'[1]直收代收-25应收减免（调整）'!$A$27:$K$42,7,0) -> 644.47947 | O14: =IF(M14>0,N14/M14,"——") -> 0.98450856 | P14: =K14-N14 -> -11.979989 | Q14: =(K14/J14)-(N14/M14) -> -0.029512637 | R14: =VLOOKUP($A14,'[1]直收代收-26应收减免 (调整)'!$A$27:$K$42,9,0) -> 1211.158 | S14: =VLOOKUP($A14,'[1]直收代收-26应收减免 (调整)'!$A$27:$K$42,10,0) -> 1095.2975 | T14: =IF(R14>0,S14/R14,"——") -> 0.90433911 | U14: =VLOOKUP($A14,'[1]直收代收-25应收减免（调整）'!$A$27:$K$42,9,0) -> 1207.0436 | V14: =VLOOKUP($A14,'[1]直收代收-25应收减免（调整）'!$A$27:$K$42,10,0) -> 1090.4601 | W14: =IF(U14>0,V14/U14,"——") -> 0.90341402 | X14: =S14-V14 -> 4.837409 | Y14: =(S14/R14)-(V14/U14) -> 0.00092509319 | Z14: =B14+J14+R14 -> 4150.4766 | AA14: =C14+K14+S14 -> 3776.7894 | AB14: =IF(Z14>0,AA14/Z14,"——") -> 0.90996522 | AC14: =E14+M14+U14 -> 4063.7814 | AD14: =F14+N14+V14 -> 3725.1928 | AE14: =IF(AC14>0,AD14/AC14,"——") -> 0.9166814 | AF14: =AA14-AD14 -> 51.596519 | AG14: =(AA14/Z14)-(AD14/AC14) -> -0.0067161792 | AH14: 铁塔、联通电费未支付
A15: 闽江 | B15: =VLOOKUP($A15,'[1]直收代收-26应收减免 (调整)'!$A$27:$K$42,3,0) -> 2005.3989 | C15: =VLOOKUP($A15,'[1]直收代收-26应收减免 (调整)'!$A$27:$K$42,4,0) -> 1489.7352 | D15: =IF(B15>0,C15/B15,"——") -> 0.74286229 | E15: =VLOOKUP($A15,'[1]直收代收-25应收减免（调整）'!$A$27:$K$42,3,0) -> 2007.8047 | F15: =VLOOKUP($A15,'[1]直收代收-25应收减免（调整）'!$A$27:$K$42,4,0) -> 1512.6196 | G15: =IF(E15>0,F15/E15,"——") -> 0.75336986 | H15: =C15-F15 -> -22.884387 | I15: =D15-G15 -> -0.010507578 | J15: =VLOOKUP($A15,'[1]直收代收-26应收减免 (调整)'!$A$27:$K$42,6,0) -> 615.43268 | K15: =VLOOKUP($A15,'[1]直收代收-26应收减免 (调整)'!$A$27:$K$42,7,0) -> 463.46042 | L15: =IF(J15>0,K15/J15,"——") -> 0.75306437 | M15: =VLOOKUP($A15,'[1]直收代收-25应收减免（调整）'!$A$27:$K$42,6,0) -> 598.10168 | N15: =VLOOKUP($A15,'[1]直收代收-25应收减免（调整）'!$A$27:$K$42,7,0) -> 462.58245 | O15: =IF(M15>0,N15/M15,"——") -> 0.77341774 | P15: =K15-N15 -> 0.877977 | Q15: =(K15/J15)-(N15/M15) -> -0.020353366 | R15: =VLOOKUP($A15,'[1]直收代收-26应收减免 (调整)'!$A$27:$K$42,9,0) -> 188.2212 | S15: =VLOOKUP($A15,'[1]直收代收-26应收减免 (调整)'!$A$27:$K$42,10,0) -> 169.49157 | T15: =IF(R15>0,S15/R15,"——") -> 0.90049142 | U15: =VLOOKUP($A15,'[1]直收代收-25应收减免（调整）'!$A$27:$K$42,9,0) -> 190.40211 | V15: =VLOOKUP($A15,'[1]直收代收-25应收减免（调整）'!$A$27:$K$42,10,0) -> 181.23433 | W15: =IF(U15>0,V15/U15,"——") -> 0.95185042 | X15: =S15-V15 -> -11.742754 | Y15: =(S15/R15)-(V15/U15) -> -0.051358998 | Z15: =B15+J15+R15 -> 2809.0528 | AA15: =C15+K15+S15 -> 2122.6872 | AB15: =IF(Z15>0,AA15/Z15,"——") -> 0.75565943 | AC15: =E15+M15+U15 -> 2796.3085 | AD15: =F15+N15+V15 -> 2156.4364 | AE15: =IF(AC15>0,AD15/AC15,"——") -> 0.77117254 | AF15: =AA15-AD15 -> -33.749164 | AG15: =(AA15/Z15)-(AD15/AC15) -> -0.015513117 | AH15: 1. 代收：宜宅充电桩电费未付 2. 其他：电梯广告费未付
A16: 罗源 | B16: =VLOOKUP($A16,'[1]直收代收-26应收减免 (调整)'!$A$27:$K$42,3,0) -> 3377.5034 | C16: =VLOOKUP($A16,'[1]直收代收-26应收减免 (调整)'!$A$27:$K$42,4,0) -> 2494.5969 | D16: =IF(B16>0,C16/B16,"——") -> 0.73859198 | E16: =VLOOKUP($A16,'[1]直收代收-25应收减免（调整）'!$A$27:$K$42,3,0) -> 3338.2086 | F16: =VLOOKUP($A16,'[1]直收代收-25应收减免（调整）'!$A$27:$K$42,4,0) -> 2464.5187 | G16: =IF(E16>0,F16/E16,"——") -> 0.73827581 | H16: =C16-F16 -> 30.078263 | I16: =D16-G16 -> 0.00031617385 | J16: =VLOOKUP($A16,'[1]直收代收-26应收减免 (调整)'!$A$27:$K$42,6,0) -> 1048.3324 | K16: =VLOOKUP($A16,'[1]直收代收-26应收减免 (调整)'!$A$27:$K$42,7,0) -> 708.31443 | L16: =IF(J16>0,K16/J16,"——") -> 0.67565827 | M16: =VLOOKUP($A16,'[1]直收代收-25应收减免（调整）'!$A$27:$K$42,6,0) -> 978.79424 | N16: =VLOOKUP($A16,'[1]直收代收-25应收减免（调整）'!$A$27:$K$42,7,0) -> 596.68213 | O16: =IF(M16>0,N16/M16,"——") -> 0.60960936 | P16: =K16-N16 -> 111.6323 | Q16: =(K16/J16)-(N16/M16) -> 0.066048906 | R16: =VLOOKUP($A16,'[1]直收代收-26应收减免 (调整)'!$A$27:$K$42,9,0) -> 501.83068 | S16: =VLOOKUP($A16,'[1]直收代收-26应收减免 (调整)'!$A$27:$K$42,10,0) -> 488.46727 | T16: =IF(R16>0,S16/R16,"——") -> 0.97337068 | U16: =VLOOKUP($A16,'[1]直收代收-25应收减免（调整）'!$A$27:$K$42,9,0) -> 462.78532 | V16: =VLOOKUP($A16,'[1]直收代收-25应收减免（调整）'!$A$27:$K$42,10,0) -> 460.02168 | W16: =IF(U16>0,V16/U16,"——") -> 0.99402824 | X16: =S16-V16 -> 28.445591 | Y16: =(S16/R16)-(V16/U16) -> -0.020657562 | Z16: =B16+J16+R16 -> 4927.6664 | AA16: =C16+K16+S16 -> 3691.3786 | AB16: =IF(Z16>0,AA16/Z16,"——") -> 0.74911293 | AC16: =E16+M16+U16 -> 4779.7882 | AD16: =F16+N16+V16 -> 3521.2225 | AE16: =IF(AC16>0,AD16/AC16,"——") -> 0.73669007 | AF16: =AA16-AD16 -> 170.15616 | AG16: =(AA16/Z16)-(AD16/AC16) -> 0.012422859
A17: 腾冲 | B17: =VLOOKUP($A17,'[1]直收代收-26应收减免 (调整)'!$A$27:$K$42,3,0) -> 906.18361 | C17: =VLOOKUP($A17,'[1]直收代收-26应收减免 (调整)'!$A$27:$K$42,4,0) -> 546.73595 | D17: =IF(B17>0,C17/B17,"——") -> 0.60333904 | E17: =VLOOKUP($A17,'[1]直收代收-25应收减免（调整）'!$A$27:$K$42,3,0) -> 912.73567 | F17: =VLOOKUP($A17,'[1]直收代收-25应收减免（调整）'!$A$27:$K$42,4,0) -> 548.71593 | G17: =IF(E17>0,F17/E17,"——") -> 0.60117726 | H17: =C17-F17 -> -1.979978 | I17: =D17-G17 -> 0.002161784 | J17: =VLOOKUP($A17,'[1]直收代收-26应收减免 (调整)'!$A$27:$K$42,6,0) -> 457.54328 | K17: =VLOOKUP($A17,'[1]直收代收-26应收减免 (调整)'!$A$27:$K$42,7,0) -> 414.43851 | L17: =IF(J17>0,K17/J17,"——") -> 0.90579084 | M17: =VLOOKUP($A17,'[1]直收代收-25应收减免（调整）'!$A$27:$K$42,6,0) -> 468.84962 | N17: =VLOOKUP($A17,'[1]直收代收-25应收减免（调整）'!$A$27:$K$42,7,0) -> 407.03753 | O17: =IF(M17>0,N17/M17,"——") -> 0.86816222 | P17: =K17-N17 -> 7.400981 | Q17: =(K17/J17)-(N17/M17) -> 0.037628619 | R17: =VLOOKUP($A17,'[1]直收代收-26应收减免 (调整)'!$A$27:$K$42,9,0) -> 240.37102 | S17: =VLOOKUP($A17,'[1]直收代收-26应收减免 (调整)'!$A$27:$K$42,10,0) -> 239.45212 | T17: =IF(R17>0,S17/R17,"——") -> 0.99617716 | U17: =VLOOKUP($A17,'[1]直收代收-25应收减免（调整）'!$A$27:$K$42,9,0) -> 294.13393 | V17: =VLOOKUP($A17,'[1]直收代收-25应收减免（调整）'!$A$27:$K$42,10,0) -> 286.65137 | W17: =IF(U17>0,V17/U17,"——") -> 0.9745607 | X17: =S17-V17 -> -47.199244 | Y17: =(S17/R17)-(V17/U17) -> 0.021616459 | Z17: =B17+J17+R17 -> 1604.0979 | AA17: =C17+K17+S17 -> 1200.6266 | AB17: =IF(Z17>0,AA17/Z17,"——") -> 0.74847463 | AC17: =E17+M17+U17 -> 1675.7192 | AD17: =F17+N17+V17 -> 1242.4048 | AE17: =IF(AC17>0,AD17/AC17,"——") -> 0.74141587 | AF17: =AA17-AD17 -> -41.778241 | AG17: =(AA17/Z17)-(AD17/AC17) -> 0.0070587564
A18: 连江 | B18: =VLOOKUP($A18,'[1]直收代收-26应收减免 (调整)'!$A$27:$K$42,3,0) -> 3371.7184 | C18: =VLOOKUP($A18,'[1]直收代收-26应收减免 (调整)'!$A$27:$K$42,4,0) -> 2046.9129 | D18: =IF(B18>0,C18/B18,"——") -> 0.607083 | E18: =VLOOKUP($A18,'[1]直收代收-25应收减免（调整）'!$A$27:$K$42,3,0) -> 3361.7546 | F18: =VLOOKUP($A18,'[1]直收代收-25应收减免（调整）'!$A$27:$K$42,4,0) -> 2073.3159 | G18: =IF(E18>0,F18/E18,"——") -> 0.61673624 | H18: =C18-F18 -> -26.402966 | I18: =D18-G18 -> -0.009653242 | J18: =VLOOKUP($A18,'[1]直收代收-26应收减免 (调整)'!$A$27:$K$42,6,0) -> 894.11486 | K18: =VLOOKUP($A18,'[1]直收代收-26应收减免 (调整)'!$A$27:$K$42,7,0) -> 599.97527 | L18: =IF(J18>0,K18/J18,"——") -> 0.67102706 | M18: =VLOOKUP($A18,'[1]直收代收-25应收减免（调整）'!$A$27:$K$42,6,0) -> 887.16249 | N18: =VLOOKUP($A18,'[1]直收代收-25应收减免（调整）'!$A$27:$K$42,7,0) -> 548.78193 | O18: =IF(M18>0,N18/M18,"——") -> 0.61858107 | P18: =K18-N18 -> 51.193339 | Q18: =(K18/J18)-(N18/M18) -> 0.052445983 | R18: =VLOOKUP($A18,'[1]直收代收-26应收减免 (调整)'!$A$27:$K$42,9,0) -> 341.09031 | S18: =VLOOKUP($A18,'[1]直收代收-26应收减免 (调整)'!$A$27:$K$42,10,0) -> 326.63433 | T18: =IF(R18>0,S18/R18,"——") -> 0.95761834 | U18: =VLOOKUP($A18,'[1]直收代收-25应收减免（调整）'!$A$27:$K$42,9,0) -> 324.80467 | V18: =VLOOKUP($A18,'[1]直收代收-25应收减免（调整）'!$A$27:$K$42,10,0) -> 310.04824 | W18: =IF(U18>0,V18/U18,"——") -> 0.95456827 | X18: =S18-V18 -> 16.586097 | Y18: =(S18/R18)-(V18/U18) -> 0.0030500646 | Z18: =B18+J18+R18 -> 4606.9236 | AA18: =C18+K18+S18 -> 2973.5225 | AB18: =IF(Z18>0,AA18/Z18,"——") -> 0.64544646 | AC18: =E18+M18+U18 -> 4573.7217 | AD18: =F18+N18+V18 -> 2932.1461 | AE18: =IF(AC18>0,AD18/AC18,"——") -> 0.64108536 | AF18: =AA18-AD18 -> 41.37647 | AG18: =(AA18/Z18)-(AD18/AC18) -> 0.0043611027
A19: 版纳 | B19: =VLOOKUP($A19,'[1]直收代收-26应收减免 (调整)'!$A$27:$K$42,3,0) -> 1083.0994 | C19: =VLOOKUP($A19,'[1]直收代收-26应收减免 (调整)'!$A$27:$K$42,4,0) -> 620.74613 | D19: =IF(B19>0,C19/B19,"——") -> 0.57312021 | E19: =VLOOKUP($A19,'[1]直收代收-25应收减免（调整）'!$A$27:$K$42,3,0) -> 1064.9533 | F19: =VLOOKUP($A19,'[1]直收代收-25应收减免（调整）'!$A$27:$K$42,4,0) -> 590.84776 | G19: =IF(E19>0,F19/E19,"——") -> 0.55481095 | H19: =C19-F19 -> 29.898369 | I19: =D19-G19 -> 0.018309261 | J19: =VLOOKUP($A19,'[1]直收代收-26应收减免 (调整)'!$A$27:$K$42,6,0) -> 247.83558 | K19: =VLOOKUP($A19,'[1]直收代收-26应收减免 (调整)'!$A$27:$K$42,7,0) -> 191.32694 | L19: =IF(J19>0,K19/J19,"——") -> 0.77199142 | M19: =VLOOKUP($A19,'[1]直收代收-25应收减免（调整）'!$A$27:$K$42,6,0) -> 255.4009 | N19: =VLOOKUP($A19,'[1]直收代收-25应收减免（调整）'!$A$27:$K$42,7,0) -> 181.35517 | O19: =IF(M19>0,N19/M19,"——") -> 0.71008037 | P19: =K19-N19 -> 9.971775 | Q19: =(K19/J19)-(N19/M19) -> 0.061911055 | R19: =VLOOKUP($A19,'[1]直收代收-26应收减免 (调整)'!$A$27:$K$42,9,0) -> 372.63516 | S19: =VLOOKUP($A19,'[1]直收代收-26应收减免 (调整)'!$A$27:$K$42,10,0) -> 201.46406 | T19: =IF(R19>0,S19/R19,"——") -> 0.54064694 | U19: =VLOOKUP($A19,'[1]直收代收-25应收减免（调整）'!$A$27:$K$42,9,0) -> 369.57058 | V19: =VLOOKUP($A19,'[1]直收代收-25应收减免（调整）'!$A$27:$K$42,10,0) -> 168.96889 | W19: =IF(U19>0,V19/U19,"——") -> 0.45720331 | X19: =S19-V19 -> 32.495165 | Y19: =(S19/R19)-(V19/U19) -> 0.083443628 | Z19: =B19+J19+R19 -> 1703.5701 | AA19: =C19+K19+S19 -> 1013.5371 | AB19: =IF(Z19>0,AA19/Z19,"——") -> 0.59494889 | AC19: =E19+M19+U19 -> 1689.9248 | AD19: =F19+N19+V19 -> 941.17182 | AE19: =IF(AC19>0,AD19/AC19,"——") -> 0.55693119 | AF19: =AA19-AD19 -> 72.365309 | AG19: =(AA19/Z19)-(AD19/AC19) -> 0.038017702
A20: 小计 | B20: =SUM(B14:B19) -> 13020.916 | C20: =SUM(C14:C19) -> 9247.7195 | D20: =C20/B20 -> 0.71022033 | E20: =SUM(E14:E19) -> 12887.574 | F20: =SUM(F14:F19) -> 9180.2711 | G20: =F20/E20 -> 0.71233507 | H20: =SUM(H14:H19) -> 67.4484 | I20: =D20-G20 -> -0.0021147384 | J20: =SUM(J14:J19) -> 3925.5647 | K20: =SUM(K14:K19) -> 3010.0151 | L20: =K20/J20 -> 0.7667725 | M20: =SUM(M14:M19) -> 3842.9294 | N20: =SUM(N14:N19) -> 2840.9187 | O20: =N20/M20 -> 0.73925861 | P20: =SUM(P14:P19) -> 169.09639 | Q20: =L20-O20 -> 0.027513882 | R20: =SUM(R14:R19) -> 2855.3063 | S20: =SUM(S14:S19) -> 2520.8069 | T20: =S20/R20 -> 0.88284989 | U20: =SUM(U14:U19) -> 2848.7402 | V20: =SUM(V14:V19) -> 2497.3846 | W20: =V20/U20 -> 0.87666282 | X20: =SUM(X14:X19) -> 23.422264 | Y20: =T20-W20 -> 0.0061870737 | Z20: =SUM(Z14:Z19) -> 19801.787 | AA20: =SUM(AA14:AA19) -> 14778.541 | AB20: =AA20/Z20 -> 0.74632361 | AC20: =SUM(AC14:AC19) -> 19579.244 | AD20: =SUM(AD14:AD19) -> 14518.574 | AE20: =AD20/AC20 -> 0.74152886 | AF20: =SUM(AF14:AF19) -> 259.96705 | AG20: =AB20-AE20 -> 0.0047947504
A21: 合计 | B21: =B20+B13 -> 41836.306 | C21: =C20+C13 -> 30887.39 | D21: =C21/B21 -> 0.73829153 | E21: =E20+E13 -> 41976.844 | F21: =F20+F13 -> 31292.181 | G21: =F21/E21 -> 0.74546294 | H21: =H20+H13 -> -404.79099 | I21: =D21-G21 -> -0.0071714056 | J21: =J20+J13 -> 10396.527 | K21: =K20+K13 -> 9259.2442 | L21: =K21/J21 -> 0.89060938 | M21: =M20+M13 -> 10856.282 | N21: =N20+N13 -> 9282.6348 | O21: =N21/M21 -> 0.8550473 | P21: =P20+P13 -> -23.390548 | Q21: =L21-O21 -> 0.035562074 | R21: =R20+R13 -> 6255.2769 | S21: =S20+S13 -> 5467.1211 | T21: =S21/R21 -> 0.87400145 | U21: =U20+U13 -> 6278.2367 | V21: =V20+V13 -> 5620.934 | W21: =V21/U21 -> 0.89530457 | X21: =X20+X13 -> -153.81298 | Y21: =T21-W21 -> -0.021303122 | Z21: =Z20+Z13 -> 58488.11 | AA21: =AA20+AA13 -> 45613.756 | AB21: =AA21/Z21 -> 0.77988083 | AC21: =AC20+AC13 -> 59111.363 | AD21: =AD20+AD13 -> 46195.75 | AE21: =AD21/AC21 -> 0.78150372 | AF21: =AF20+AF13 -> -581.99452 | AG21: =AB21-AE21 -> -0.0016228905
A23: 当期收费简报-外拓
A24: · 收费率=实收/（应收-减免），各项数据为全口径
A25: 公司 | B25: 直收项（物、车） | J25: 代收项（代收水电、公摊水电） | R25: 其他项 | Z25: 合计 | AH25: 备注
B26: 2026年 | E26: 2025年 | H26: 同比 | J26: 2026年 | M26: 2025年 | P26: 同比 | R26: 2026年 | U26: 2025年 | X26: 同比 | Z26: 2026年 | AC26: 2025年 | AF26: 同比
B27: 应收 | C27: 实收 | D27: 收费率 | E27: 应收 | F27: 实收 | G27: 收费率 | H27: 实收 | I27: 收费率 | J27: 应收 | K27: 实收 | L27: 收费率 | M27: 应收 | N27: 实收 | O27: 收费率 | P27: 实收 | Q27: 收费率 | R27: 应收 | S27: 实收 | T27: 收费率 | U27: 应收 | V27: 实收 | W27: 收费率 | X27: 实收 | Y27: 收费率 | Z27: 应收 | AA27: 实收 | AB27: 收费率 | AC27: 应收 | AD27: 实收 | AE27: 收费率 | AF27: 实收 | AG27: 收费率
A28: 阜阳 | B28: =VLOOKUP($A28,'[1]直收代收-26应收减免 (调整)'!$O$27:$Y$42,3,0) -> 1166.3284 | C28: =VLOOKUP($A28,'[1]直收代收-26应收减免 (调整)'!$O$27:$Y$42,4,0) -> 748.71854 | D28: =IF(B28>0,C28/B28,"——") -> 0.64194487 | E28: =VLOOKUP($A28,'[1]直收代收-25应收减免（调整）'!$O$27:$Y$42,3,0) -> 452.38797 | F28: =VLOOKUP($A28,'[1]直收代收-25应收减免（调整）'!$O$27:$Y$42,4,0) -> 236.21872 | G28: =IF(E28>0,F28/E28,"——") -> 0.5221596 | H28: =C28-F28 -> 512.49982 | I28: =D28-G28 -> 0.11978527 | J28: =VLOOKUP($A28,'[1]直收代收-26应收减免 (调整)'!$O$27:$Y$42,6,0) -> 24.571322 | K28: =VLOOKUP($A28,'[1]直收代收-26应收减免 (调整)'!$O$27:$Y$42,7,0) -> 24.571322 | L28: =IF(J28>0,K28/J28,"——") -> 1 | M28: =VLOOKUP($A28,'[1]直收代收-25应收减免（调整）'!$O$27:$Y$42,6,0) -> 112.10125 | N28: =VLOOKUP($A28,'[1]直收代收-25应收减免（调整）'!$O$27:$Y$42,7,0) -> 112.10125 | O28: =IF(M28>0,N28/M28,"——") -> 1 | P28: =K28-N28 -> -87.529924 | Q28: =(K28/J28)-(N28/M28) -> 0 | R28: =VLOOKUP($A28,'[1]直收代收-26应收减免 (调整)'!$O$27:$Y$42,9,0) -> 67.697682 | S28: =VLOOKUP($A28,'[1]直收代收-26应收减免 (调整)'!$O$27:$Y$42,10,0) -> 65.227095 | T28: =IF(R28>0,S28/R28,"——") -> 0.96350559 | U28: =VLOOKUP($A28,'[1]直收代收-25应收减免（调整）'!$O$27:$Y$42,9,0) -> 49.231262 | V28: =VLOOKUP($A28,'[1]直收代收-25应收减免（调整）'!$O$27:$Y$42,10,0) -> 41.618247 | W28: =IF(U28>0,V28/U28,"——") -> 0.84536218 | X28: =S28-V28 -> 23.608848 | Y28: =(S28/R28)-(V28/U28) -> 0.11814341 | Z28: =B28+J28+R28 -> 1258.5974 | AA28: =C28+K28+S28 -> 838.51696 | AB28: =IF(Z28>0,AA28/Z28,"——") -> 0.66623127 | AC28: =E28+M28+U28 -> 613.72048 | AD28: =F28+N28+V28 -> 389.93822 | AE28: =IF(AC28>0,AD28/AC28,"——") -> 0.63536778 | AF28: =AA28-AD28 -> 448.57874 | AG28: =(AA28/Z28)-(AD28/AC28) -> 0.030863497
A29: 北京 | B29: =VLOOKUP($A29,'[1]直收代收-26应收减免 (调整)'!$O$27:$Y$42,3,0) -> 3759.518 | C29: =VLOOKUP($A29,'[1]直收代收-26应收减免 (调整)'!$O$27:$Y$42,4,0) -> 2216.7359 | D29: =IF(B29>0,C29/B29,"——") -> 0.589633 | E29: =VLOOKUP($A29,'[1]直收代收-25应收减免（调整）'!$O$27:$Y$42,3,0) -> 3360.0445 | F29: =VLOOKUP($A29,'[1]直收代收-25应收减免（调整）'!$O$27:$Y$42,4,0) -> 1912.3776 | G29: =IF(E29>0,F29/E29,"——") -> 0.56915248 | H29: =C29-F29 -> 304.35827 | I29: =D29-G29 -> 0.020480528 | J29: =VLOOKUP($A29,'[1]直收代收-26应收减免 (调整)'!$O$27:$Y$42,6,0) -> 233.38613 | K29: =VLOOKUP($A29,'[1]直收代收-26应收减免 (调整)'!$O$27:$Y$42,7,0) -> 166.35772 | L29: =IF(J29>0,K29/J29,"——") -> 0.71280035 | M29: =VLOOKUP($A29,'[1]直收代收-25应收减免（调整）'!$O$27:$Y$42,6,0) -> 165.45434 | N29: =VLOOKUP($A29,'[1]直收代收-25应收减免（调整）'!$O$27:$Y$42,7,0) -> 145.66614 | O29: =IF(M29>0,N29/M29,"——") -> 0.88040083 | P29: =K29-N29 -> 20.691577 | Q29: =(K29/J29)-(N29/M29) -> -0.16760049 | R29: =VLOOKUP($A29,'[1]直收代收-26应收减免 (调整)'!$O$27:$Y$42,9,0) -> 137.32197 | S29: =VLOOKUP($A29,'[1]直收代收-26应收减免 (调整)'!$O$27:$Y$42,10,0) -> 131.76753 | T29: =IF(R29>0,S29/R29,"——") -> 0.95955167 | U29: =VLOOKUP($A29,'[1]直收代收-25应收减免（调整）'!$O$27:$Y$42,9,0) -> 151.47638 | V29: =VLOOKUP($A29,'[1]直收代收-25应收减免（调整）'!$O$27:$Y$42,10,0) -> 148.03244 | W29: =IF(U29>0,V29/U29,"——") -> 0.97726416 | X29: =S29-V29 -> -16.264911 | Y29: =(S29/R29)-(V29/U29) -> -0.017712493 | Z29: =B29+J29+R29 -> 4130.2261 | AA29: =C29+K29+S29 -> 2514.8612 | AB29: =IF(Z29>0,AA29/Z29,"——") -> 0.60889188 | AC29: =E29+M29+U29 -> 3676.9752 | AD29: =F29+N29+V29 -> 2206.0762 | AE29: =IF(AC29>0,AD29/AC29,"——") -> 0.59997038 | AF29: =AA29-AD29 -> 308.78494 | AG29: =(AA29/Z29)-(AD29/AC29) -> 0.0089214987
A30: 北城 | B30: =VLOOKUP($A30,'[1]直收代收-26应收减免 (调整)'!$O$27:$Y$42,3,0) -> 1999.2584 | C30: =VLOOKUP($A30,'[1]直收代收-26应收减免 (调整)'!$O$27:$Y$42,4,0) -> 920.05044 | D30: =IF(B30>0,C30/B30,"——") -> 0.46019587 | E30: =VLOOKUP($A30,'[1]直收代收-25应收减免（调整）'!$O$27:$Y$42,3,0) -> 1972.7428 | F30: =VLOOKUP($A30,'[1]直收代收-25应收减免（调整）'!$O$27:$Y$42,4,0) -> 853.77089 | G30: =IF(E30>0,F30/E30,"——") -> 0.43278368 | H30: =C30-F30 -> 66.27955 | I30: =D30-G30 -> 0.027412182 | J30: =VLOOKUP($A30,'[1]直收代收-26应收减免 (调整)'!$O$27:$Y$42,6,0) -> 604.1003 | K30: =VLOOKUP($A30,'[1]直收代收-26应收减免 (调整)'!$O$27:$Y$42,7,0) -> 584.99262 | L30: =IF(J30>0,K30/J30,"——") -> 0.96837002 | M30: =VLOOKUP($A30,'[1]直收代收-25应收减免（调整）'!$O$27:$Y$42,6,0) -> 608.04232 | N30: =VLOOKUP($A30,'[1]直收代收-25应收减免（调整）'!$O$27:$Y$42,7,0) -> 587.65073 | O30: =IF(M30>0,N30/M30,"——") -> 0.96646354 | P30: =K30-N30 -> -2.658112 | Q30: =(K30/J30)-(N30/M30) -> 0.0019064776 | R30: =VLOOKUP($A30,'[1]直收代收-26应收减免 (调整)'!$O$27:$Y$42,9,0) -> 193.1276 | S30: =VLOOKUP($A30,'[1]直收代收-26应收减免 (调整)'!$O$27:$Y$42,10,0) -> 160.70092 | T30: =IF(R30>0,S30/R30,"——") -> 0.83209714 | U30: =VLOOKUP($A30,'[1]直收代收-25应收减免（调整）'!$O$27:$Y$42,9,0) -> 203.43888 | V30: =VLOOKUP($A30,'[1]直收代收-25应收减免（调整）'!$O$27:$Y$42,10,0) -> 174.02392 | W30: =IF(U30>0,V30/U30,"——") -> 0.8554113 | X30: =S30-V30 -> -13.322998 | Y30: =(S30/R30)-(V30/U30) -> -0.023314159 | Z30: =B30+J30+R30 -> 2796.4863 | AA30: =C30+K30+S30 -> 1665.744 | AB30: =IF(Z30>0,AA30/Z30,"——") -> 0.59565606 | AC30: =E30+M30+U30 -> 2784.224 | AD30: =F30+N30+V30 -> 1615.4455 | AE30: =IF(AC30>0,AD30/AC30,"——") -> 0.58021393 | AF30: =AA30-AD30 -> 50.29844 | AG30: =(AA30/Z30)-(AD30/AC30) -> 0.015442124
A31: 宁波 | B31: =VLOOKUP($A31,'[1]直收代收-26应收减免 (调整)'!$O$27:$Y$42,3,0) -> 95.023644 | C31: =VLOOKUP($A31,'[1]直收代收-26应收减免 (调整)'!$O$27:$Y$42,4,0) -> 53.575039 | D31: =IF(B31>0,C31/B31,"——") -> 0.56380746 | E31: =VLOOKUP($A31,'[1]直收代收-25应收减免（调整）'!$O$27:$Y$42,3,0) -> 387.75247 | F31: =VLOOKUP($A31,'[1]直收代收-25应收减免（调整）'!$O$27:$Y$42,4,0) -> 210.70455 | G31: =IF(E31>0,F31/E31,"——") -> 0.54339962 | H31: =C31-F31 -> -157.12951 | I31: =D31-G31 -> 0.020407835 | J31: =VLOOKUP($A31,'[1]直收代收-26应收减免 (调整)'!$O$27:$Y$42,6,0) -> 0.05448 | K31: =VLOOKUP($A31,'[1]直收代收-26应收减免 (调整)'!$O$27:$Y$42,7,0) -> 0.05448 | L31: =IF(J31>0,K31/J31,"——") -> 1 | M31: =VLOOKUP($A31,'[1]直收代收-25应收减免（调整）'!$O$27:$Y$42,6,0) -> 1.78356 | N31: =VLOOKUP($A31,'[1]直收代收-25应收减免（调整）'!$O$27:$Y$42,7,0) -> 1.532574 | O31: =IF(M31>0,N31/M31,"——") -> 0.85927807 | P31: =K31-N31 -> -1.478094 | Q31: =(K31/J31)-(N31/M31) -> 0.14072193 | R31: =VLOOKUP($A31,'[1]直收代收-26应收减免 (调整)'!$O$27:$Y$42,9,0) -> 0 | S31: =VLOOKUP($A31,'[1]直收代收-26应收减免 (调整)'!$O$27:$Y$42,10,0) -> 0 | T31: =IF(R31>0,S31/R31,"——") -> —— | U31: =VLOOKUP($A31,'[1]直收代收-25应收减免（调整）'!$O$27:$Y$42,9,0) -> 0.7875 | V31: =VLOOKUP($A31,'[1]直收代收-25应收减免（调整）'!$O$27:$Y$42,10,0) -> 0.1375 | W31: =IF(U31>0,V31/U31,"——") -> 0.17460317 | X31: =S31-V31 -> -0.1375 | Y31: —— | Z31: =B31+J31+R31 -> 95.078124 | AA31: =C31+K31+S31 -> 53.629519 | AB31: =IF(Z31>0,AA31/Z31,"——") -> 0.5640574 | AC31: =E31+M31+U31 -> 390.32353 | AD31: =F31+N31+V31 -> 212.37462 | AE31: =IF(AC31>0,AD31/AC31,"——") -> 0.54409894 | AF31: =AA31-AD31 -> -158.7451 | AG31: =(AA31/Z31)-(AD31/AC31) -> 0.019958454
A32: 滨湖 | B32: =VLOOKUP($A32,'[1]直收代收-26应收减免 (调整)'!$O$27:$Y$42,3,0) -> 1996.1443 | C32: =VLOOKUP($A32,'[1]直收代收-26应收减免 (调整)'!$O$27:$Y$42,4,0) -> 871.6537 | D32: =IF(B32>0,C32/B32,"——") -> 0.43666869 | E32: =VLOOKUP($A32,'[1]直收代收-25应收减免（调整）'!$O$27:$Y$42,3,0) -> 1566.7503 | F32: =VLOOKUP($A32,'[1]直收代收-25应收减免（调整）'!$O$27:$Y$42,4,0) -> 779.27128 | G32: =IF(E32>0,F32/E32,"——") -> 0.49738064 | H32: =C32-F32 -> 92.382421 | I32: =D32-G32 -> -0.060711951 | J32: =VLOOKUP($A32,'[1]直收代收-26应收减免 (调整)'!$O$27:$Y$42,6,0) -> 429.89566 | K32: =VLOOKUP($A32,'[1]直收代收-26应收减免 (调整)'!$O$27:$Y$42,7,0) -> 386.67495 | L32: =IF(J32>0,K32/J32,"——") -> 0.89946233 | M32: =VLOOKUP($A32,'[1]直收代收-25应收减免（调整）'!$O$27:$Y$42,6,0) -> 402.98143 | N32: =VLOOKUP($A32,'[1]直收代收-25应收减免（调整）'!$O$27:$Y$42,7,0) -> 367.8823 | O32: =IF(M32>0,N32/M32,"——") -> 0.91290137 | P32: =K32-N32 -> 18.792655 | Q32: =(K32/J32)-(N32/M32) -> -0.013439039 | R32: =VLOOKUP($A32,'[1]直收代收-26应收减免 (调整)'!$O$27:$Y$42,9,0) -> 163.93447 | S32: =VLOOKUP($A32,'[1]直收代收-26应收减免 (调整)'!$O$27:$Y$42,10,0) -> 160.54603 | T32: =IF(R32>0,S32/R32,"——") -> 0.9793305 | U32: =VLOOKUP($A32,'[1]直收代收-25应收减免（调整）'!$O$27:$Y$42,9,0) -> 226.64664 | V32: =VLOOKUP($A32,'[1]直收代收-25应收减免（调整）'!$O$27:$Y$42,10,0) -> 225.46931 | W32: =IF(U32>0,V32/U32,"——") -> 0.99480546 | X32: =S32-V32 -> -64.92328 | Y32: =(S32/R32)-(V32/U32) -> -0.015474952 | Z32: =B32+J32+R32 -> 2589.9744 | AA32: =C32+K32+S32 -> 1418.8747 | AB32: =IF(Z32>0,AA32/Z32,"——") -> 0.54783348 | AC32: =E32+M32+U32 -> 2196.3784 | AD32: =F32+N32+V32 -> 1372.6229 | AE32: =IF(AC32>0,AD32/AC32,"——") -> 0.62494828 | AF32: =AA32-AD32 -> 46.251796 | AG32: =(AA32/Z32)-(AD32/AC32) -> -0.077114798 | AH32: 5个单业权项目回款滞后
A33: 长沙 | B33: =VLOOKUP($A33,'[1]直收代收-26应收减免 (调整)'!$O$27:$Y$42,3,0) -> 945.11284 | C33: =VLOOKUP($A33,'[1]直收代收-26应收减免 (调整)'!$O$27:$Y$42,4,0) -> 427.05786 | D33: =IF(B33>0,C33/B33,"——") -> 0.45185913 | E33: =VLOOKUP($A33,'[1]直收代收-25应收减免（调整）'!$O$27:$Y$42,3,0) -> 587.93258 | F33: =VLOOKUP($A33,'[1]直收代收-25应收减免（调整）'!$O$27:$Y$42,4,0) -> 169.4299 | G33: =IF(E33>0,F33/E33,"——") -> 0.28817913 | H33: =C33-F33 -> 257.62796 | I33: =D33-G33 -> 0.16367999 | J33: =VLOOKUP($A33,'[1]直收代收-26应收减免 (调整)'!$O$27:$Y$42,6,0) -> 75.891009 | K33: =VLOOKUP($A33,'[1]直收代收-26应收减免 (调整)'!$O$27:$Y$42,7,0) -> 38.654907 | L33: =IF(J33>0,K33/J33,"——") -> 0.50934765 | M33: =VLOOKUP($A33,'[1]直收代收-25应收减免（调整）'!$O$27:$Y$42,6,0) -> 80.055814 | N33: =VLOOKUP($A33,'[1]直收代收-25应收减免（调整）'!$O$27:$Y$42,7,0) -> 70.415457 | O33: =IF(M33>0,N33/M33,"——") -> 0.87957955 | P33: =K33-N33 -> -31.76055 | Q33: =(K33/J33)-(N33/M33) -> -0.3702319 | R33: =VLOOKUP($A33,'[1]直收代收-26应收减免 (调整)'!$O$27:$Y$42,9,0) -> 13.968861 | S33: =VLOOKUP($A33,'[1]直收代收-26应收减免 (调整)'!$O$27:$Y$42,10,0) -> 10.459077 | T33: =IF(R33>0,S33/R33,"——") -> 0.74874229 | U33: =VLOOKUP($A33,'[1]直收代收-25应收减免（调整）'!$O$27:$Y$42,9,0) -> 35.415225 | V33: =VLOOKUP($A33,'[1]直收代收-25应收减免（调整）'!$O$27:$Y$42,10,0) -> 10.87223 | W33: =IF(U33>0,V33/U33,"——") -> 0.30699311 | X33: =S33-V33 -> -0.413153 | Y33: =(S33/R33)-(V33/U33) -> 0.44174918 | Z33: =B33+J33+R33 -> 1034.9727 | AA33: =C33+K33+S33 -> 476.17185 | AB33: =IF(Z33>0,AA33/Z33,"——") -> 0.46008155 | AC33: =E33+M33+U33 -> 703.40361 | AD33: =F33+N33+V33 -> 250.71759 | AE33: =IF(AC33>0,AD33/AC33,"——") -> 0.35643489 | AF33: =AA33-AD33 -> 225.45426 | AG33: =(AA33/Z33)-(AD33/AC33) -> 0.10364666 | AH33: 玺宇悦城开发商遗留问题影响收费
A34: 贵阳 | B34: =VLOOKUP($A34,'[1]直收代收-26应收减免 (调整)'!$O$27:$Y$42,3,0) -> 2771.7326 | C34: =VLOOKUP($A34,'[1]直收代收-26应收减免 (调整)'!$O$27:$Y$42,4,0) -> 1127.1737 | D34: =IF(B34>0,C34/B34,"——") -> 0.40666755 | E34: =VLOOKUP($A34,'[1]直收代收-25应收减免（调整）'!$O$27:$Y$42,3,0) -> 3560.4303 | F34: =VLOOKUP($A34,'[1]直收代收-25应收减免（调整）'!$O$27:$Y$42,4,0) -> 1979.0621 | G34: =IF(E34>0,F34/E34,"——") -> 0.55584913 | H34: =C34-F34 -> -851.88837 | I34: =D34-G34 -> -0.14918158 | J34: =VLOOKUP($A34,'[1]直收代收-26应收减免 (调整)'!$O$27:$Y$42,6,0) -> 81.625947 | K34: =VLOOKUP($A34,'[1]直收代收-26应收减免 (调整)'!$O$27:$Y$42,7,0) -> 73.864971 | L34: =IF(J34>0,K34/J34,"——") -> 0.90492023 | M34: =VLOOKUP($A34,'[1]直收代收-25应收减免（调整）'!$O$27:$Y$42,6,0) -> 83.949653 | N34: =VLOOKUP($A34,'[1]直收代收-25应收减免（调整）'!$O$27:$Y$42,7,0) -> 75.856228 | O34: =IF(M34>0,N34/M34,"——") -> 0.90359192 | P34: =K34-N34 -> -1.991257 | Q34: =(K34/J34)-(N34/M34) -> 0.0013283149 | R34: =VLOOKUP($A34,'[1]直收代收-26应收减免 (调整)'!$O$27:$Y$42,9,0) -> 146.22912 | S34: =VLOOKUP($A34,'[1]直收代收-26应收减免 (调整)'!$O$27:$Y$42,10,0) -> 128.77049 | T34: =IF(R34>0,S34/R34,"——") -> 0.88060771 | U34: =VLOOKUP($A34,'[1]直收代收-25应收减免（调整）'!$O$27:$Y$42,9,0) -> 270.17419 | V34: =VLOOKUP($A34,'[1]直收代收-25应收减免（调整）'!$O$27:$Y$42,10,0) -> 218.8713 | W34: =IF(U34>0,V34/U34,"——") -> 0.81011181 | X34: =S34-V34 -> -90.100815 | Y34: =(S34/R34)-(V34/U34) -> 0.070495892 | Z34: =B34+J34+R34 -> 2999.5876 | AA34: =C34+K34+S34 -> 1329.8092 | AB34: =IF(Z34>0,AA34/Z34,"——") -> 0.44333066 | AC34: =E34+M34+U34 -> 3914.5541 | AD34: =F34+N34+V34 -> 2273.7896 | AE34: =IF(AC34>0,AD34/AC34,"——") -> 0.58085533 | AF34: =AA34-AD34 -> -943.98045 | AG34: =(AA34/Z34)-(AD34/AC34) -> -0.13752467
A35: 小计 | B35: =SUM(B28:B34) -> 12733.118 | C35: =SUM(C28:C34) -> 6364.9652 | D35: =C35/B35 -> 0.49987483 | E35: =SUM(E28:E34) -> 11888.041 | F35: =SUM(F28:F34) -> 6140.8351 | G35: =F35/E35 -> 0.51655568 | H35: =SUM(H28:H34) -> 224.13014 | I35: =D35-G35 -> -0.016680857 | J35: =SUM(J28:J34) -> 1449.5249 | K35: =SUM(K28:K34) -> 1275.171 | L35: =K35/J35 -> 0.87971653 | M35: =SUM(M28:M34) -> 1454.3684 | N35: =SUM(N28:N34) -> 1361.1047 | O35: =N35/M35 -> 0.93587341 | P35: =SUM(P28:P34) -> -85.933705 | Q35: =L35-O35 -> -0.056156881 | R35: =SUM(R28:R34) -> 722.2797 | S35: =SUM(S28:S34) -> 657.47114 | T35: =S35/R35 -> 0.91027221 | U35: =SUM(U28:U34) -> 937.17007 | V35: =SUM(V28:V34) -> 819.02494 | W35: =V35/U35 -> 0.87393416 | X35: =SUM(X28:X34) -> -161.55381 | Y35: =T35-W35 -> 0.036338042 | Z35: =SUM(Z28:Z34) -> 14904.923 | AA35: =SUM(AA28:AA34) -> 8297.6073 | AB35: =AA35/Z35 -> 0.55670247 | AC35: =SUM(AC28:AC34) -> 14279.579 | AD35: =SUM(AD28:AD34) -> 8320.9647 | AE35: =AD35/AC35 -> 0.58271778 | AF35: =SUM(AF28:AF34) -> -23.357374 | AG35: =AB35-AE35 -> -0.026015303
