Workbook

Sheet 汇总
A3: KPI | C3: 权重 | D3: 北京 | E3: 贵阳 | F3: 昆明 | G3: 滨湖 | H3: 长沙 | I3: 闽江 | J3: 北城 | K3: 罗源 | L3: 连江 | M3: 宁波 | N3: 腾冲 | O3: 版纳 | P3: 阜阳
A4: 经营收益（35%） | B4: 当期收费率（15%） | C4: 0.15 | D4: =ROUND(INDEX(收费率!$F$4:$F$16,MATCH(汇总!D3,收费率!$E$4:$E$16,0)),1) -> 67.2 | E4: =ROUND(INDEX(收费率!$F$4:$F$16,MATCH(汇总!E3,收费率!$E$4:$E$16,0)),1) -> 64.5 | F4: =ROUND(INDEX(收费率!$F$4:$F$16,MATCH(汇总!F3,收费率!$E$4:$E$16,0)),1) -> 74.9 | G4: =ROUND(INDEX(收费率!$F$4:$F$16,MATCH(汇总!G3,收费率!$E$4:$E$16,0)),1) -> 63.9 | H4: =ROUND(INDEX(收费率!$F$4:$F$16,MATCH(汇总!H3,收费率!$E$4:$E$16,0)),1) -> 60 | I4: =ROUND(INDEX(收费率!$F$4:$F$16,MATCH(汇总!I3,收费率!$E$4:$E$16,0)),1) -> 57.4 | J4: =ROUND(INDEX(收费率!$F$4:$F$16,MATCH(汇总!J3,收费率!$E$4:$E$16,0)),1) -> 74.8 | K4: =ROUND(INDEX(收费率!$F$4:$F$16,MATCH(汇总!K3,收费率!$E$4:$E$16,0)),1) -> 78.1 | ... P4: =ROUND(INDEX(收费率!$F$4:$F$16,MATCH(汇总!P3,收费率!$E$4:$E$16,0)),1) -> 75.8
B5: 历欠收费率（10%） | C5: 0.1 | D5: =ROUND(INDEX(收费率!$F$23:$F$35,MATCH(汇总!D3,收费率!$E$23:$E$35,0)),1) -> 53.8 | E5: =ROUND(INDEX(收费率!$F$23:$F$35,MATCH(汇总!E3,收费率!$E$23:$E$35,0)),1) -> 50.5 | F5: =ROUND(INDEX(收费率!$F$23:$F$35,MATCH(汇总!F3,收费率!$E$23:$E$35,0)),1) -> 62.9 | G5: =ROUND(INDEX(收费率!$F$23:$F$35,MATCH(汇总!G3,收费率!$E$23:$E$35,0)),1) -> 34.9 | H5: =ROUND(INDEX(收费率!$F$23:$F$35,MATCH(汇总!H3,收费率!$E$23:$E$35,0)),1) -> 63.9 | I5: =ROUND(INDEX(收费率!$F$23:$F$35,MATCH(汇总!I3,收费率!$E$23:$E$35,0)),1) -> 52.2 | J5: =ROUND(INDEX(收费率!$F$23:$F$35,MATCH(汇总!J3,收费率!$E$23:$E$35,0)),1) -> 47.9 | K5: =ROUND(INDEX(收费率!$F$23:$F$35,MATCH(汇总!K3,收费率!$E$23:$E$35,0)),1) -> 63.3 | ... P5: =ROUND(INDEX(收费率!$F$23:$F$35,MATCH(汇总!P3,收费率!$E$23:$E$35,0)),1) -> 68.4
B6: 空间资源指标完成（10%） | C6: 0.1 | D6: {=MAX(0,ROUND(INDEX(空间资源!$G$3:$G$15,MATCH(D3,空间资源!$F$3:$F$15,0)),1))} -> 0 | E6: {=MAX(0,ROUND(INDEX(空间资源!$G$3:$G$15,MATCH(E3,空间资源!$F$3:$F$15,0)),1))} -> 0 | F6: {=MAX(0,ROUND(INDEX(空间资源!$G$3:$G$15,MATCH(F3,空间资源!$F$3:$F$15,0)),1))} -> 0 | G6: {=MAX(0,ROUND(INDEX(空间资源!$G$3:$G$15,MATCH(G3,空间资源!$F$3:$F$15,0)),1))} -> 0 | H6: {=MAX(0,ROUND(INDEX(空间资源!$G$3:$G$15,MATCH(H3,空间资源!$F$3:$F$15,0)),1))} -> 0 | I6: {=MAX(0,ROUND(INDEX(空间资源!$G$3:$G$15,MATCH(I3,空间资源!$F$3:$F$15,0)),1))} -> 0 | J6: {=MAX(0,ROUND(INDEX(空间资源!$G$3:$G$15,MATCH(J3,空间资源!$F$3:$F$15,0)),1))} -> 0 | K6: {=MAX(0,ROUND(INDEX(空间资源!$G$3:$G$15,MATCH(K3,空间资源!$F$3:$F$15,0)),1))} -> 0 | ... P6: {=MAX(0,ROUND(INDEX(空间资源!$G$3:$G$15,MATCH(P3,空间资源!$F$3:$F$15,0)),1))} -> 0
A7: 客户服务（35%） | B7: 业主满意度（25%） | C7: 0.25 | D7: =ROUND(INDEX(业主满意度!$J$4:$J$16,MATCH(D3,业主满意度!$H$4:$H$16,0)),1) -> 70 | E7: =ROUND(INDEX(业主满意度!$J$4:$J$16,MATCH(E3,业主满意度!$H$4:$H$16,0)),1) -> 70 | F7: =ROUND(INDEX(业主满意度!$J$4:$J$16,MATCH(F3,业主满意度!$H$4:$H$16,0)),1) -> 70 | G7: =ROUND(INDEX(业主满意度!$J$4:$J$16,MATCH(G3,业主满意度!$H$4:$H$16,0)),1) -> 70 | H7: =ROUND(INDEX(业主满意度!$J$4:$J$16,MATCH(H3,业主满意度!$H$4:$H$16,0)),1) -> 70 | I7: =ROUND(INDEX(业主满意度!$J$4:$J$16,MATCH(I3,业主满意度!$H$4:$H$16,0)),1) -> 70 | J7: =ROUND(INDEX(业主满意度!$J$4:$J$16,MATCH(J3,业主满意度!$H$4:$H$16,0)),1) -> 70 | K7: =ROUND(INDEX(业主满意度!$J$4:$J$16,MATCH(K3,业主满意度!$H$4:$H$16,0)),1) -> 70 | ... P7: =ROUND(INDEX(业主满意度!$J$4:$J$16,MATCH(P3,业主满意度!$H$4:$H$16,0)),1) -> 70
B8: 投诉完成率（10%） | C8: 0.1 | D8: =ROUND(INDEX(投诉完成率!$P$5:$P$17,MATCH(D3,投诉完成率!$O$5:$O$17,0)),1) -> 80 | E8: =ROUND(INDEX(投诉完成率!$P$5:$P$17,MATCH(E3,投诉完成率!$O$5:$O$17,0)),1) -> 100 | F8: =ROUND(INDEX(投诉完成率!$P$5:$P$17,MATCH(F3,投诉完成率!$O$5:$O$17,0)),1) -> 95 | G8: =ROUND(INDEX(投诉完成率!$P$5:$P$17,MATCH(G3,投诉完成率!$O$5:$O$17,0)),1) -> 85 | H8: =ROUND(INDEX(投诉完成率!$P$5:$P$17,MATCH(H3,投诉完成率!$O$5:$O$17,0)),1) -> 90 | I8: =ROUND(INDEX(投诉完成率!$P$5:$P$17,MATCH(I3,投诉完成率!$O$5:$O$17,0)),1) -> 100 | J8: =ROUND(INDEX(投诉完成率!$P$5:$P$17,MATCH(J3,投诉完成率!$O$5:$O$17,0)),1) -> 90 | K8: =ROUND(INDEX(投诉完成率!$P$5:$P$17,MATCH(K3,投诉完成率!$O$5:$O$17,0)),1) -> 67.5 | ... P8: =ROUND(INDEX(投诉完成率!$P$5:$P$17,MATCH(P3,投诉完成率!$O$5:$O$17,0)),1) -> 80.8
A9: 工程管控（20%） | B9: 设备设施管理（10%） | C9: 0.1 | D9: =ROUND(INDEX(设备设施管理!$H$3:$H$15,MATCH(D3,设备设施管理!$G$3:$G$15,0)),1) -> 0 | E9: =ROUND(INDEX(设备设施管理!$H$3:$H$15,MATCH(E3,设备设施管理!$G$3:$G$15,0)),1) -> 0 | F9: =ROUND(INDEX(设备设施管理!$H$3:$H$15,MATCH(F3,设备设施管理!$G$3:$G$15,0)),1) -> 0 | G9: =ROUND(INDEX(设备设施管理!$H$3:$H$15,MATCH(G3,设备设施管理!$G$3:$G$15,0)),1) -> 0 | H9: =ROUND(INDEX(设备设施管理!$H$3:$H$15,MATCH(H3,设备设施管理!$G$3:$G$15,0)),1) -> 0 | I9: =ROUND(INDEX(设备设施管理!$H$3:$H$15,MATCH(I3,设备设施管理!$G$3:$G$15,0)),1) -> 0 | J9: =ROUND(INDEX(设备设施管理!$H$3:$H$15,MATCH(J3,设备设施管理!$G$3:$G$15,0)),1) -> 0 | K9: =ROUND(INDEX(设备设施管理!$H$3:$H$15,MATCH(K3,设备设施管理!$G$3:$G$15,0)),1) -> 0 | ... P9: =ROUND(INDEX(设备设施管理!$H$3:$H$15,MATCH(P3,设备设施管理!$G$3:$G$15,0)),1) -> 0
B10: 自用能耗成本管控（10%） | C10: 0.1 | D10: =ROUND(INDEX(自用能耗成本!$K$3:$K$15,MATCH(D3,自用能耗成本!$J$3:$J$15,0)),1) -> 119 | E10: =ROUND(INDEX(自用能耗成本!$K$3:$K$15,MATCH(E3,自用能耗成本!$J$3:$J$15,0)),1) -> 111.4 | F10: =ROUND(INDEX(自用能耗成本!$K$3:$K$15,MATCH(F3,自用能耗成本!$J$3:$J$15,0)),1) -> 79.4 | G10: =ROUND(INDEX(自用能耗成本!$K$3:$K$15,MATCH(G3,自用能耗成本!$J$3:$J$15,0)),1) -> 120 | H10: =ROUND(INDEX(自用能耗成本!$K$3:$K$15,MATCH(H3,自用能耗成本!$J$3:$J$15,0)),1) -> 70.6 | I10: =ROUND(INDEX(自用能耗成本!$K$3:$K$15,MATCH(I3,自用能耗成本!$J$3:$J$15,0)),1) -> 120 | J10: =ROUND(INDEX(自用能耗成本!$K$3:$K$15,MATCH(J3,自用能耗成本!$J$3:$J$15,0)),1) -> 113.5 | K10: =ROUND(INDEX(自用能耗成本!$K$3:$K$15,MATCH(K3,自用能耗成本!$J$3:$J$15,0)),1) -> 99.6 | ... P10: =ROUND(INDEX(自用能耗成本!$K$3:$K$15,MATCH(P3,自用能耗成本!$J$3:$J$15,0)),1) -> 120
A11: 效率管理（10%） | B11: 基础信息维护合格率（5%） | C11: 0.05 | D11: =ROUND(INDEX(基础信息抽查!$Q$3:$Q$15,MATCH(D3,基础信息抽查!$O$3:$O$15,0)),1) -> 95.3 | E11: =ROUND(INDEX(基础信息抽查!$Q$3:$Q$15,MATCH(E3,基础信息抽查!$O$3:$O$15,0)),1) -> 100 | F11: =ROUND(INDEX(基础信息抽查!$Q$3:$Q$15,MATCH(F3,基础信息抽查!$O$3:$O$15,0)),1) -> 100 | G11: =ROUND(INDEX(基础信息抽查!$Q$3:$Q$15,MATCH(G3,基础信息抽查!$O$3:$O$15,0)),1) -> 69.5 | H11: =ROUND(INDEX(基础信息抽查!$Q$3:$Q$15,MATCH(H3,基础信息抽查!$O$3:$O$15,0)),1) -> 89.5 | I11: =ROUND(INDEX(基础信息抽查!$Q$3:$Q$15,MATCH(I3,基础信息抽查!$O$3:$O$15,0)),1) -> 93.8 | J11: =ROUND(INDEX(基础信息抽查!$Q$3:$Q$15,MATCH(J3,基础信息抽查!$O$3:$O$15,0)),1) -> 95.3 | K11: =ROUND(INDEX(基础信息抽查!$Q$3:$Q$15,MATCH(K3,基础信息抽查!$O$3:$O$15,0)),1) -> 100 | ... P11: =ROUND(INDEX(基础信息抽查!$Q$3:$Q$15,MATCH(P3,基础信息抽查!$O$3:$O$15,0)),1) -> 96
B12: 400电话知晓率（5%） | C12: 0.05 | D12: =ROUND(INDEX('400知晓率'!$R$3:$R$15,MATCH(D3,'400知晓率'!$P$3:$P$15,0)),1) -> 141.7 | E12: =ROUND(INDEX('400知晓率'!$R$3:$R$15,MATCH(E3,'400知晓率'!$P$3:$P$15,0)),1) -> 104.6 | F12: =ROUND(INDEX('400知晓率'!$R$3:$R$15,MATCH(F3,'400知晓率'!$P$3:$P$15,0)),1) -> 113.7 | G12: =ROUND(INDEX('400知晓率'!$R$3:$R$15,MATCH(G3,'400知晓率'!$P$3:$P$15,0)),1) -> 92.8 | H12: =ROUND(INDEX('400知晓率'!$R$3:$R$15,MATCH(H3,'400知晓率'!$P$3:$P$15,0)),1) -> 100.2 | I12: =ROUND(INDEX('400知晓率'!$R$3:$R$15,MATCH(I3,'400知晓率'!$P$3:$P$15,0)),1) -> 108.6 | J12: =ROUND(INDEX('400知晓率'!$R$3:$R$15,MATCH(J3,'400知晓率'!$P$3:$P$15,0)),1) -> 101.1 | K12: =ROUND(INDEX('400知晓率'!$R$3:$R$15,MATCH(K3,'400知晓率'!$P$3:$P$15,0)),1) -> 111.5 | ... P12: =ROUND(INDEX('400知晓率'!$R$3:$R$15,MATCH(P3,'400知晓率'!$P$3:$P$15,0)),1) -> 112.3
A13: 重大事项扣罚 | C13: —— | D13: 0 | E13: 0 | F13: 0 | G13: 0 | H13: 0 | I13: 0 | J13: 0 | K13: 0 | L13: 0 | M13: 0 | N13: 0 | O13: 0 | P13: 0
A14: 总分 | C14: —— | D14: =D4*$C$4+D5*$C$5+D6*$C$6+D7*$C$7+D8*$C$8+D9*$C$9+D10*$C$10+D11*$C$11+D12*$C$12 -> 64.71 | E14: =E4*$C$4+E5*$C$5+E6*$C$6+E7*$C$7+E8*$C$8+E9*$C$9+E10*$C$10+E11*$C$11+E12*$C$12 -> 63.595 | F14: =F4*$C$4+F5*$C$5+F6*$C$6+F7*$C$7+F8*$C$8+F9*$C$9+F10*$C$10+F11*$C$11+F12*$C$12 -> 63.15 | G14: =G4*$C$4+G5*$C$5+G6*$C$6+G7*$C$7+G8*$C$8+G9*$C$9+G10*$C$10+G11*$C$11+G12*$C$12 -> 59.19 | H14: =H4*$C$4+H5*$C$5+H6*$C$6+H7*$C$7+H8*$C$8+H9*$C$9+H10*$C$10+H11*$C$11+H12*$C$12 -> 58.435 | I14: =I4*$C$4+I5*$C$5+I6*$C$6+I7*$C$7+I8*$C$8+I9*$C$9+I10*$C$10+I11*$C$11+I12*$C$12 -> 63.45 | J14: =J4*$C$4+J5*$C$5+J6*$C$6+J7*$C$7+J8*$C$8+J9*$C$9+J10*$C$10+J11*$C$11+J12*$C$12 -> 63.68 | K14: =K4*$C$4+K5*$C$5+K6*$C$6+K7*$C$7+K8*$C$8+K9*$C$9+K10*$C$10+K11*$C$11+K12*$C$12 -> 62.83 | ... P14: =P4*$C$4+P5*$C$5+P6*$C$6+P7*$C$7+P8*$C$8+P9*$C$9+P10*$C$10+P11*$C$11+P12*$C$12 -> 66.205
A15: 排名 | C15: —— | D15: =RANK(D14,$D$14:$P$14) -> 3 | E15: =RANK(E14,$D$14:$P$14) -> 5 | F15: =RANK(F14,$D$14:$P$14) -> 7 | G15: =RANK(G14,$D$14:$P$14) -> 11 | H15: =RANK(H14,$D$14:$P$14) -> 12 | I15: =RANK(I14,$D$14:$P$14) -> 6 | J15: =RANK(J14,$D$14:$P$14) -> 4 | K15: =RANK(K14,$D$14:$P$14) -> 8 | ... P15: =RANK(P14,$D$14:$P$14) -> 1
A19: 仅保留1位小数
A20: KPI | D20: 北京 | E20: 贵阳 | F20: 昆明 | G20: 滨湖 | H20: 长沙 | I20: 闽江 | J20: 北城 | K20: 罗源 | L20: 连江 | M20: 宁波 | N20: 腾冲 | O20: 版纳 | P20: 阜阳
A21: 经营收益（35%） | B21: 当期收费率（15%） | C21: 0.15 | D21: =ROUND(D4*0.15,1) -> 10.1 | E21: =ROUND(E4*0.15,1) -> 9.7 | F21: =ROUND(F4*0.15,1) -> 11.2 | G21: =ROUND(G4*0.15,1) -> 9.6 | H21: =ROUND(H4*0.15,1) -> 9 | I21: =ROUND(I4*0.15,1) -> 8.6 | J21: =ROUND(J4*0.15,1) -> 11.2 | K21: =ROUND(K4*0.15,1) -> 11.7 | ... P21: =ROUND(P4*0.15,1) -> 11.4
B22: 历欠收费率（10%） | C22: 0.1 | D22: =ROUND(D5*0.1,1) -> 5.4 | E22: =ROUND(E5*0.1,1) -> 5.1 | F22: =ROUND(F5*0.1,1) -> 6.3 | G22: =ROUND(G5*0.1,1) -> 3.5 | H22: =ROUND(H5*0.1,1) -> 6.4 | I22: =ROUND(I5*0.1,1) -> 5.2 | J22: =ROUND(J5*0.1,1) -> 4.8 | K22: =ROUND(K5*0.1,1) -> 6.3 | ... P22: =ROUND(P5*0.1,1) -> 6.8
B23: 空间资源指标完成（10%） | C23: 0.1 | D23: =ROUND(D6*0.1,1) -> 0 | E23: =ROUND(E6*0.1,1) -> 0 | F23: =ROUND(F6*0.1,1) -> 0 | G23: =ROUND(G6*0.1,1) -> 0 | H23: =ROUND(H6*0.1,1) -> 0 | I23: =ROUND(I6*0.1,1) -> 0 | J23: =ROUND(J6*0.1,1) -> 0 | K23: =ROUND(K6*0.1,1) -> 0 | ... P23: =ROUND(P6*0.1,1) -> 0
A24: 客户服务（35%） | B24: 业主满意度（25%） | C24: 0.25 | D24: =ROUND(D7*0.25,1) -> 17.5 | E24: =ROUND(E7*0.25,1) -> 17.5 | F24: =ROUND(F7*0.25,1) -> 17.5 | G24: =ROUND(G7*0.25,1) -> 17.5 | H24: =ROUND(H7*0.25,1) -> 17.5 | I24: =ROUND(I7*0.25,1) -> 17.5 | J24: =ROUND(J7*0.25,1) -> 17.5 | K24: =ROUND(K7*0.25,1) -> 17.5 | ... P24: =ROUND(P7*0.25,1) -> 17.5
B25: 投诉完成率（10%） | C25: 0.1 | D25: =ROUND(D8*0.1,1) -> 8 | E25: =ROUND(E8*0.1,1) -> 10 | F25: =ROUND(F8*0.1,1) -> 9.5 | G25: =ROUND(G8*0.1,1) -> 8.5 | H25: =ROUND(H8*0.1,1) -> 9 | I25: =ROUND(I8*0.1,1) -> 10 | J25: =ROUND(J8*0.1,1) -> 9 | K25: =ROUND(K8*0.1,1) -> 6.8 | ... P25: =ROUND(P8*0.1,1) -> 8.1
A26: 工程管控（15%） | B26: 设备设施管理（10%） | C26: 0.1 | D26: =ROUND(D9*0.1,1) -> 0 | E26: =ROUND(E9*0.1,1) -> 0 | F26: =ROUND(F9*0.1,1) -> 0 | G26: =ROUND(G9*0.1,1) -> 0 | H26: =ROUND(H9*0.1,1) -> 0 | I26: =ROUND(I9*0.1,1) -> 0 | J26: =ROUND(J9*0.1,1) -> 0 | K26: =ROUND(K9*0.1,1) -> 0 | ... P26: =ROUND(P9*0.1,1) -> 0
B27: 自用能耗成本管控（10%） | C27: 0.1 | D27: =ROUND(D10*0.05,1) -> 6 | E27: =ROUND(E10*0.05,1) -> 5.6 | F27: =ROUND(F10*0.05,1) -> 4 | G27: =ROUND(G10*0.05,1) -> 6 | H27: =ROUND(H10*0.05,1) -> 3.5 | I27: =ROUND(I10*0.05,1) -> 6 | J27: =ROUND(J10*0.05,1) -> 5.7 | K27: =ROUND(K10*0.05,1) -> 5 | ... P27: =ROUND(P10*0.05,1) -> 6
A28: 效率管理（10%） | B28: 客户信息维护（10%） | C28: 0.1 | D28: =ROUND(D11*0.05,1)+ROUND(D12*0.05,1) -> 11.9 | E28: =ROUND(E11*0.05,1)+ROUND(E12*0.05,1) -> 10.2 | F28: =ROUND(F11*0.05,1)+ROUND(F12*0.05,1) -> 10.7 | G28: =ROUND(G11*0.05,1)+ROUND(G12*0.05,1) -> 8.1 | H28: =ROUND(H11*0.05,1)+ROUND(H12*0.05,1) -> 9.5 | I28: =ROUND(I11*0.05,1)+ROUND(I12*0.05,1) -> 10.1 | J28: =ROUND(J11*0.05,1)+ROUND(J12*0.05,1) -> 9.9 | K28: =ROUND(K11*0.05,1)+ROUND(K12*0.05,1) -> 10.6 | ... P28: =ROUND(P11*0.05,1)+ROUND(P12*0.05,1) -> 10.4
A29: 重大事项扣罚 | D29: =D13 -> 0 | E29: =E13 -> 0 | F29: 0 | G29: =G13 -> 0 | H29: =H13 -> 0 | I29: =I13 -> 0 | J29: =J13 -> 0 | K29: =K13 -> 0 | L29: =L13 -> 0 | M29: =M13 -> 0 | N29: =N13 -> 0 | ... P29: =P13 -> 0
A30: 总分 | D30: =SUM(D21:D29) -> 58.9 | E30: =SUM(E21:E29) -> 58.1 | F30: =SUM(F21:F29) -> 59.2 | G30: =SUM(G21:G29) -> 53.2 | H30: =SUM(H21:H29) -> 54.9 | I30: =SUM(I21:I29) -> 57.4 | J30: =SUM(J21:J29) -> 58.1 | K30: =SUM(K21:K29) -> 57.9 | ... P30: =SUM(P21:P29) -> 60.2
A31: 排名 | D31: =RANK(D30,$D$30:$P$30) -> 4 | E31: =RANK(E30,$D$30:$P$30) -> 5 | F31: =RANK(F30,$D$30:$P$30) -> 2 | G31: =RANK(G30,$D$30:$P$30) -> 12 | H31: =RANK(H30,$D$30:$P$30) -> 10 | I31: =RANK(I30,$D$30:$P$30) -> 8 | J31: =RANK(J30,$D$30:$P$30) -> 5 | K31: =RANK(K30,$D$30:$P$30) -> 7 | ... P31: =RANK(P30,$D$30:$P$30) -> 1
A33: 2025年城市公司KPI考核指标得分

Sheet 26年考核标准
A1: 附件一
A2: 品质服务精细化管理KPI
A3: 序号 | B3: 类型 | C3: KPI指标 | D3: 权重 | E3: 指标说明 | F3: 评分标准 | G3: 备注
A4: 1 | B4: 经营收益(35%) | C4: 当期收费率 | D4: 0.15 | E4: 当期收费率R=实收金额/应收金额*100% | F4: 当期收费率R以综合费项全年收费率指标为基准线 ①当R=基准线时，得100分 ②当R＞基准线时，较基准线每上升1%加3分（封顶120分），得分=100+(R-基准线)/1%*3 ③当R＜基准线时，较基准线每下降1%减2分，得分=100-(基准线-R)/1%*2 | G4: 含公司自建、外拓项目综合收费项（全口径），详见附件四
A5: 2 | C5: 历欠收费率 | D5: 0.1 | E5: 历欠收费率R=实收金额/应收金额*100% | F5: 历欠收费率R以全年欠费回款指标为基准线 ①当R=基准线时，得100分 ②当R＞基准线时，较基准线每上升1%加3分（封顶120分），得分=100+(R-基准线)/1%*3 ③当R＜基准线时，较基准线每下降1%减2分，得分=100-(基准线-R)/1%*2 | G5: 含公司自建、外拓多业权项目（在管+撤场1年内），详见附件四
A6: 3 | C6: 空间资源指标完成率 | D6: 0.1 | E6: 空间资源指标完成率R=实收金额/指标金额*100% | F6: 空间资源指标完成率R以全年空间资源经营指标为基准线 ①当R=基准线时，得100分 ②当R＞基准线时，较基准线每上升1%加3分（封顶120分），得分=100+(R-基准线)/1%*3 ③当R＜基准线时，较基准线每下降1%减2分，得分=100-(基准线-R)/1%*2 | G6: 自建项目，详见附件四
A7: 4 | B7: 客户服务(35%) | C7: 业主满意度 | D7: 0.25 | E7: 400调查年度客户满意度评分 | F7: 业主满意度R以各公司上年度得分为基准线： ①目标值≥75分，基础分100分；目标值＜75分，基础分90分 ②目标值≥80分：实际值较目标值每上升1%加2分（封顶120分），每下降1%减1分 ③75分≤目标值＜80分：实际值较目标值每上升1%加1分，每下降1%减2分 ④目标值＜75分：实际值未达75分，较目标值每上升1%分差加分[（实际值-目标值）/（75-目标值）*10分]，每下降1%减3分；实际值达75分以上按②、③规则核算 | G7: 1、自建项目 2、客户满意度评分以400电话调查结果为准
A8: 5 | C8: 投诉处理 完成率 | D8: 0.1 | E8: 投诉处理完成率R | F8: 投诉处理完成率R以75%为基准线，得分=基础分*满意度系数 ①基础分：投诉处理完成率按月度核算，每月R均75%(含）以上，得100分，单月不达标，-5分/次 ②满意度系数：以年度投诉处理满意度确定系数，满意度≥50分时，系数1.0；40分≤满意度＜50分时，系数0.95；满意度＜40分时，系数0.9 | G8: 自建、外拓项目
A9: 6 | B9: 工程管控（20%） | C9: 设备设施管理 | D9: 0.1 | E9: 设施设备健康度R | F9: 设备设施健康度R为公区设备运行稳定性及预防性维护执行情况的综合得分，按各二级指标实际值折算后加权计算 | G9: 1、自建项目 2、设备设施健康度二级指标细则详见《品质服务检核计划》（附件三）
A10: 7 | C10: 自用能耗成本管控 | D10: 0.1 | E10: 自用水、电能耗实支成本管控 | F10: 自用能耗成本R以各公司上年度实际能耗成本支出为基准线： ①R≤25年实际成本，实际值较目标值每下降1%加1分（封顶120分），得分=100+(25年实际成本-R)/1%*1 ①R＞25年实际成本，实际值较目标值每上升1%减1分，得分=100+(R-25年实际成本)/1%*1 | G10: 自建项目
A11: 8 | B11: 效率管理(10%) | C11: 客户信息维护 | D11: 0.1 | E11: 客户基础信息准确率与400知晓率 | F11: 基础信息准确率基准线95%，400知晓率基准线50%，两项指标权重1:1 ①当R=基准线时，得100分 ②当R＞基准线时，较基准线每上升1%加2分(封顶120分)，得分=100+(R-基准线)/1%*2 ③当R＜基准线时，较基准线每下降1%减2分，得分=100-(基准线-R)/1%*2 | G11: 自建项目

Sheet 收费率
A2: 各城市公司当期收费率对比分析（综合）
A3: 公司 | B3: 45778 | C3: 46143 | E3: 公司 | F3: 得分 | G3: 权重得分 | I3: 公司 | J3: 考核指标 | L3: 验算
A4: 版纳 | B4: 0.48604382 | C4: 0.53657712 | D4: =C4-B4 -> 0.0505333 | E4: =A4 -> 版纳 | F4: =ROUND(IF(C4=J4,100,IF(AND(C4>J4),100+(C4-J4)/1%*3,IF(C4<J4,100+(C4-J4)/1%*2,100-(J4-C4)/1%*2))),1) -> 37.2 | G4: =F4*0.15 -> 5.58 | I4: 版纳 | J4: 0.85053911 | K4: =C4-J4 -> -0.31396199 | L4: =ROUND(100-(J4-C4)/1%*2,1) -> 37.2 | M4: =F4-L4 -> 0 | N4: 100-(基准线-R)/1%*2。
A5: 北城 | B5: 0.74257555 | C5: 0.73667093 | D5: =C5-B5 -> -0.0059046224 | E5: =A5 -> 北城 | F5: =ROUND(IF(C5=J5,100,IF(AND(C5>J5),100+(C5-J5)/1%*3,IF(C5<J5,100+(C5-J5)/1%*2,100-(J5-C5)/1%*2))),1) -> 74.8 | G5: =F5*0.15 -> 11.22 | I5: 北城 | J5: 0.86274859 | K5: =C5-J5 -> -0.12607766 | L5: =ROUND(100-(J5-C5)/1%*2,1) -> 74.8 | M5: =F5-L5 -> 0
A6: 北京 | B6: 0.7823668 | C6: 0.75335116 | D6: =C6-B6 -> -0.029015643 | E6: =A6 -> 北京 | F6: =ROUND(IF(C6=J6,100,IF(AND(C6>J6),100+(C6-J6)/1%*3,IF(C6<J6,100+(C6-J6)/1%*2,100-(J6-C6)/1%*2))),1) -> 67.2 | G6: =F6*0.15 -> 10.08 | I6: 北京 | J6: 0.91748947 | K6: =C6-J6 -> -0.16413831 | L6: =ROUND(100-(J6-C6)/1%*2,1) -> 67.2 | M6: =F6-L6 -> 0
A7: 滨湖 | B7: 0.77106781 | C7: 0.7346887 | D7: =C7-B7 -> -0.036379112 | E7: =A7 -> 滨湖 | F7: =ROUND(IF(C7=J7,100,IF(AND(C7>J7),100+(C7-J7)/1%*3,IF(C7<J7,100+(C7-J7)/1%*2,100-(J7-C7)/1%*2))),1) -> 63.9 | G7: =F7*0.15 -> 9.585 | I7: 滨湖 | J7: 0.91502025 | K7: =C7-J7 -> -0.18033155 | L7: =ROUND(100-(J7-C7)/1%*2,1) -> 63.9 | M7: =F7-L7 -> 0
A8: 阜阳 | B8: 0.71687304 | C8: 0.71014406 | D8: =C8-B8 -> -0.0067289844 | E8: 阜阳 | F8: =ROUND(IF(C8=J8,100,IF(AND(C8>J8),100+(C8-J8)/1%*3,IF(C8<J8,100+(C8-J8)/1%*2,100-(J8-C8)/1%*2))),1) -> 75.8 | G8: =F8*0.15 -> 11.37 | I8: 阜阳 | J8: 0.83110199 | K8: =C8-J8 -> -0.12095794 | L8: =ROUND(100-(J8-C8)/1%*2,1) -> 75.8 | M8: =F8-L8 -> 0
A9: 贵阳 | B9: 0.71831559 | C9: 0.71575907 | D9: =C9-B9 -> -0.0025565278 | E9: =A9 -> 贵阳 | F9: =ROUND(IF(C9=J9,100,IF(AND(C9>J9),100+(C9-J9)/1%*3,IF(C9<J9,100+(C9-J9)/1%*2,100-(J9-C9)/1%*2))),1) -> 64.5 | G9: =F9*0.15 -> 9.675 | I9: 贵阳 | J9: 0.89323852 | K9: =C9-J9 -> -0.17747946 | L9: =ROUND(100-(J9-C9)/1%*2,1) -> 64.5 | M9: =F9-L9 -> 0
A10: 昆明 | B10: 0.79752747 | C10: 0.81581077 | D10: =C10-B10 -> 0.018283305 | E10: =A10 -> 昆明 | F10: =ROUND(IF(C10=J10,100,IF(AND(C10>J10),100+(C10-J10)/1%*3,IF(C10<J10,100+(C10-J10)/1%*2,100-(J10-C10)/1%*2))),1) -> 74.9 | G10: =F10*0.15 -> 11.235 | I10: 昆明 | J10: 0.94130664 | K10: =C10-J10 -> -0.12549587 | L10: =ROUND(100-(J10-C10)/1%*2,1) -> 74.9 | M10: =F10-L10 -> 0
A11: 连江 | B11: 0.64032125 | C11: 0.64561217 | D11: =C11-B11 -> 0.0052909277 | E11: =A11 -> 连江 | F11: =ROUND(IF(C11=J11,100,IF(AND(C11>J11),100+(C11-J11)/1%*3,IF(C11<J11,100+(C11-J11)/1%*2,100-(J11-C11)/1%*2))),1) -> 65.1 | G11: =F11*0.15 -> 9.765 | I11: 连江 | J11: 0.82024414 | K11: =C11-J11 -> -0.17463196 | L11: =ROUND(100-(J11-C11)/1%*2,1) -> 65.1 | M11: =F11-L11 -> 0
A12: 罗源 | B12: 0.70266225 | C12: 0.74000209 | D12: =C12-B12 -> 0.037339845 | E12: =A12 -> 罗源 | F12: =ROUND(IF(C12=J12,100,IF(AND(C12>J12),100+(C12-J12)/1%*3,IF(C12<J12,100+(C12-J12)/1%*2,100-(J12-C12)/1%*2))),1) -> 78.1 | G12: =F12*0.15 -> 11.715 | I12: 罗源 | J12: 0.84925425 | K12: =C12-J12 -> -0.10925216 | L12: =ROUND(100-(J12-C12)/1%*2,1) -> 78.1 | M12: =F12-L12 -> 0
A13: 闽江 | B13: 0.73005613 | C13: 0.71301318 | D13: =C13-B13 -> -0.017042948 | E13: =A13 -> 闽江 | F13: =ROUND(IF(C13=J13,100,IF(AND(C13>J13),100+(C13-J13)/1%*3,IF(C13<J13,100+(C13-J13)/1%*2,100-(J13-C13)/1%*2))),1) -> 57.4 | G13: =F13*0.15 -> 8.61 | I13: 闽江 | J13: 0.92607614 | K13: =C13-J13 -> -0.21306296 | L13: =ROUND(100-(J13-C13)/1%*2,1) -> 57.4 | M13: =F13-L13 -> 0
A14: 宁波 | B14: 0.71309702 | C14: 0.66884709 | D14: =C14-B14 -> -0.044249933 | E14: =A14 -> 宁波 | F14: =ROUND(IF(C14=J14,100,IF(AND(C14>J14),100+(C14-J14)/1%*3,IF(C14<J14,100+(C14-J14)/1%*2,100-(J14-C14)/1%*2))),1) -> 55.8 | G14: =F14*0.15 -> 8.37 | I14: 宁波 | J14: 0.8899695 | K14: =C14-J14 -> -0.22112241 | L14: =ROUND(100-(J14-C14)/1%*2,1) -> 55.8 | M14: =F14-L14 -> 0
A15: 腾冲 | B15: 0.75899656 | C15: 0.7154912 | D15: =C15-B15 -> -0.043505362 | E15: =A15 -> 腾冲 | F15: =ROUND(IF(C15=J15,100,IF(AND(C15>J15),100+(C15-J15)/1%*3,IF(C15<J15,100+(C15-J15)/1%*2,100-(J15-C15)/1%*2))),1) -> 53 | G15: =F15*0.15 -> 7.95 | I15: 腾冲 | J15: 0.95070579 | K15: =C15-J15 -> -0.23521459 | L15: =ROUND(100-(J15-C15)/1%*2,1) -> 53 | M15: =F15-L15 -> 0
A16: 长沙 | B16: 0.64288745 | C16: 0.6936552 | D16: =C16-B16 -> 0.050767753 | E16: =A16 -> 长沙 | F16: =ROUND(IF(C16=J16,100,IF(AND(C16>J16),100+(C16-J16)/1%*3,IF(C16<J16,100+(C16-J16)/1%*2,100-(J16-C16)/1%*2))),1) -> 60 | G16: =F16*0.15 -> 9 | I16: 长沙 | J16: 0.89348274 | K16: =C16-J16 -> -0.19982754 | L16: =ROUND(100-(J16-C16)/1%*2,1) -> 60 | M16: =F16-L16 -> 0
A17: 合计 | B17: 0.72228792 | C17: 0.71845396 | D17: -0.0088836544 | I17: 集团 | J17: 0.89041041
A21: 各城市公司历欠收费率对比分析（综合)
A22: 公司 | B22: 45778 | C22: 46143 | E22: 公司 | F22: 得分 | G22: 权重得分 | I22: 公司 | J22: 考核指标 | L22: 验算
A23: 版纳 | B23: 0.16340834 | C23: 0.15092283 | D23: =C23-B23 -> -0.012485509 | E23: =A23 -> 版纳 | F23: =ROUND(IF(C23=J23,100,IF(AND(C23>J23),100+(C23-J23)/1%*3,IF(C23<J23,100+(C23-J23)/1%*2,100-(J23-C23)/1%*2))),1) -> 54.2 | G23: =F23*0.1 -> 5.42 | I23: 版纳 | J23: 0.37983292 | K23: =C23-J23 -> -0.22891009 | L23: =ROUND(100-(J23-C23)/1%*2,1) -> 54.2 | M23: =F23-L23 -> 0
A24: 北城 | B24: 0.20565772 | C24: 0.21689077 | D24: =C24-B24 -> 0.01123305 | E24: =A24 -> 北城 | F24: =ROUND(IF(C24=J24,100,IF(AND(C24>J24),100+(C24-J24)/1%*3,IF(C24<J24,100+(C24-J24)/1%*2,100-(J24-C24)/1%*2))),1) -> 47.9 | G24: =F24*0.1 -> 4.79 | I24: 北城 | J24: 0.47757673 | K24: =C24-J24 -> -0.26068597 | L24: =ROUND(100-(J24-C24)/1%*2,1) -> 47.9 | M24: =F24-L24 -> 0
A25: 北京 | B25: 0.14281271 | C25: 0.11719348 | D25: =C25-B25 -> -0.025619233 | E25: =A25 -> 北京 | F25: =ROUND(IF(C25=J25,100,IF(AND(C25>J25),100+(C25-J25)/1%*3,IF(C25<J25,100+(C25-J25)/1%*2,100-(J25-C25)/1%*2))),1) -> 53.8 | G25: =F25*0.1 -> 5.38 | I25: 北京 | J25: 0.34816798 | K25: =C25-J25 -> -0.23097451 | L25: =ROUND(100-(J25-C25)/1%*2,1) -> 53.8 | M25: =F25-L25 -> 0
A26: 滨湖 | B26: 0.28932089 | C26: 0.27902228 | D26: =C26-B26 -> -0.010298616 | E26: =A26 -> 滨湖 | F26: =ROUND(IF(C26=J26,100,IF(AND(C26>J26),100+(C26-J26)/1%*3,IF(C26<J26,100+(C26-J26)/1%*2,100-(J26-C26)/1%*2))),1) -> 34.9 | G26: =F26*0.1 -> 3.49 | I26: 滨湖 | J26: 0.60469842 | K26: =C26-J26 -> -0.32567615 | L26: =ROUND(100-(J26-C26)/1%*2,1) -> 34.9 | M26: =F26-L26 -> 0
A27: 阜阳 | B27: 0.37999294 | C27: 0.44431144 | D27: =C27-B27 -> 0.064318501 | E27: 阜阳 | F27: =ROUND(IF(C27=J27,100,IF(AND(C27>J27),100+(C27-J27)/1%*3,IF(C27<J27,100+(C27-J27)/1%*2,100-(J27-C27)/1%*2))),1) -> 68.4 | G27: =F27*0.1 -> 6.84 | I27: 阜阳 | J27: 0.60249489 | K27: =C27-J27 -> -0.15818345 | L27: =ROUND(100-(J27-C27)/1%*2,1) -> 68.4 | M27: =F27-L27 -> 0 | N27: 100-(基准线-R)/1%*3
A28: 贵阳 | B28: 0.14973326 | C28: 0.17035783 | D28: =C28-B28 -> 0.020624568 | E28: =A28 -> 贵阳 | F28: =ROUND(IF(C28=J28,100,IF(AND(C28>J28),100+(C28-J28)/1%*3,IF(C28<J28,100+(C28-J28)/1%*2,100-(J28-C28)/1%*2))),1) -> 50.5 | G28: =F28*0.1 -> 5.05 | I28: 贵阳 | J28: 0.41769932 | K28: =C28-J28 -> -0.24734149 | L28: =ROUND(100-(J28-C28)/1%*2,1) -> 50.5 | M28: =F28-L28 -> 0
A29: 昆明 | B29: 0.21340913 | C29: 0.16823656 | D29: =C29-B29 -> -0.04517257 | E29: =A29 -> 昆明 | F29: =ROUND(IF(C29=J29,100,IF(AND(C29>J29),100+(C29-J29)/1%*3,IF(C29<J29,100+(C29-J29)/1%*2,100-(J29-C29)/1%*2))),1) -> 62.9 | G29: =F29*0.1 -> 6.29 | I29: 昆明 | J29: 0.35364143 | K29: =C29-J29 -> -0.18540487 | L29: =ROUND(100-(J29-C29)/1%*2,1) -> 62.9 | M29: =F29-L29 -> 0
A30: 连江 | B30: 0.26404649 | C30: 0.21955233 | D30: =C30-B30 -> -0.044494164 | E30: =A30 -> 连江 | F30: =ROUND(IF(C30=J30,100,IF(AND(C30>J30),100+(C30-J30)/1%*3,IF(C30<J30,100+(C30-J30)/1%*2,100-(J30-C30)/1%*2))),1) -> 55 | G30: =F30*0.1 -> 5.5 | I30: 连江 | J30: 0.44431278 | K30: =C30-J30 -> -0.22476045 | L30: =ROUND(100-(J30-C30)/1%*2,1) -> 55 | M30: =F30-L30 -> 0
A31: 罗源 | B31: 0.51430032 | C31: 0.47244364 | D31: =C31-B31 -> -0.041856679 | E31: =A31 -> 罗源 | F31: =ROUND(IF(C31=J31,100,IF(AND(C31>J31),100+(C31-J31)/1%*3,IF(C31<J31,100+(C31-J31)/1%*2,100-(J31-C31)/1%*2))),1) -> 63.3 | G31: =F31*0.1 -> 6.33 | I31: 罗源 | J31: 0.65588217 | K31: =C31-J31 -> -0.18343853 | L31: =ROUND(100-(J31-C31)/1%*2,1) -> 63.3 | M31: =F31-L31 -> 0
A32: 闽江 | B32: 0.4373913 | C32: 0.40021356 | D32: =C32-B32 -> -0.037177742 | E32: =A32 -> 闽江 | F32: =ROUND(IF(C32=J32,100,IF(AND(C32>J32),100+(C32-J32)/1%*3,IF(C32<J32,100+(C32-J32)/1%*2,100-(J32-C32)/1%*2))),1) -> 52.2 | G32: =F32*0.1 -> 5.22 | I32: 闽江 | J32: 0.63897592 | K32: =C32-J32 -> -0.23876236 | L32: =ROUND(100-(J32-C32)/1%*2,1) -> 52.2 | M32: =F32-L32 -> 0
A33: 宁波 | B33: 0.24037867 | C33: 0.21861167 | D33: =C33-B33 -> -0.021767002 | E33: =A33 -> 宁波 | F33: =ROUND(IF(C33=J33,100,IF(AND(C33>J33),100+(C33-J33)/1%*3,IF(C33<J33,100+(C33-J33)/1%*2,100-(J33-C33)/1%*2))),1) -> 49 | G33: =F33*0.1 -> 4.9 | I33: 宁波 | J33: 0.47367945 | K33: =C33-J33 -> -0.25506779 | L33: =ROUND(100-(J33-C33)/1%*2,1) -> 49 | M33: =F33-L33 -> 0
A34: 腾冲 | B34: 0.13449113 | C34: 0.18110736 | D34: =C34-B34 -> 0.046616239 | E34: =A34 -> 腾冲 | F34: =ROUND(IF(C34=J34,100,IF(AND(C34>J34),100+(C34-J34)/1%*3,IF(C34<J34,100+(C34-J34)/1%*2,100-(J34-C34)/1%*2))),1) -> 67.6 | G34: =F34*0.1 -> 6.76 | I34: 腾冲 | J34: 0.3429118 | K34: =C34-J34 -> -0.16180443 | L34: =ROUND(100-(J34-C34)/1%*2,1) -> 67.6 | M34: =F34-L34 -> 0
A35: 长沙 | B35: 0.11707766 | C35: 0.087764015 | D35: =C35-B35 -> -0.02931365 | E35: =A35 -> 长沙 | F35: =ROUND(IF(C35=J35,100,IF(AND(C35>J35),100+(C35-J35)/1%*3,IF(C35<J35,100+(C35-J35)/1%*2,100-(J35-C35)/1%*2))),1) -> 63.9 | G35: =F35*0.1 -> 6.39 | I35: 长沙 | J35: 0.2680702 | K35: =C35-J35 -> -0.18030619 | L35: =ROUND(100-(J35-C35)/1%*2,1) -> 63.9 | M35: =F35-L35 -> 0
A36: 合计 | B36: 0.22567986 | C36: 0.2146522 | D36: -0.030425286 | I36: 集团 | J36: 0.44195012
B39: 自-应 | C39: 自-实 | D39: 外-应 | E39: 外-实 | F39: 25.5收费率 | H39: 自-应 | I39: 自-实 | J39: 外-应 | K39: 外-实 | L39: 26.5收费率
A40: 版纳 | B40: 1223.6354 | C40: 219.78919 | D40: 723.51885 | E40: 98.392052 | F40: =(C40+E40)/(B40+D40) -> 0.16340834 | H40: 1163.6342 | I40: 196.84716 | J40: 751.74287 | K40: 92.22697 | L40: =(I40+K40)/(H40+J40) -> 0.15092283
A41: 北城 | B41: 1330.6967 | C41: 329.16664 | D41: 1803.4308 | E41: 315.39086 | F41: =(C41+E41)/(B41+D41) -> 0.20565772 | H41: 1771.2507 | I41: 447.12236 | J41: 1791.2563 | K41: 325.55252 | L41: =(I41+K41)/(H41+J41) -> 0.21689077
A42: 北京 | B42: 1890.0047 | C42: 342.00474 | D42: 1884.7235 | E42: 197.07442 | F42: =(C42+E42)/(B42+D42) -> 0.14281271 | H42: 1701.9531 | I42: 263.91508 | J42: 1925.8214 | K42: 161.23643 | L42: =(I42+K42)/(H42+J42) -> 0.11719348
A43: 滨湖 | B43: 511.12055 | C43: 177.35 | D43: 519.88 | E43: 120.94 | F43: =(C43+E43)/(B43+D43) -> 0.28932089 | H43: 514.23007 | I43: 165.55042 | J43: 676.39322 | K43: 166.66 | L43: =(I43+K43)/(H43+J43) -> 0.27902228
A44: 阜阳 | B44: 316.54031 | C44: 112.28233 | D44: 403.62987 | E44: 161.37726 | F44: =(C44+E44)/(B44+D44) -> 0.37999294 | H44: 360.33473 | I44: 123.03304 | J44: 235.83292 | K44: 141.85107 | L44: =(I44+K44)/(H44+J44) -> 0.44431144
A45: 贵阳 | B45: 1848.7316 | C45: 253.63627 | D45: 1385.5667 | E45: 230.64577 | F45: =(C45+E45)/(B45+D45) -> 0.14973326 | H45: 2093.752 | I45: 443.20921 | J45: 1559.8275 | K45: 179.20665 | L45: =(I45+K45)/(H45+J45) -> 0.17035783
A46: 昆明 | B46: 287.12379 | C46: 124.30294 | D46: 1425.5469 | E46: 241.19662 | F46: =(C46+E46)/(B46+D46) -> 0.21340913 | H46: 269.51458 | I46: 108.03407 | J46: 1462.9497 | K46: 183.42977 | L46: =(I46+K46)/(H46+J46) -> 0.16823656
...

Sheet 空间资源
A2: 公司 | B2: 空间资源指标 | C2: 已入账 | D2: 完成率 | E2: 目标完成率 | F2: 公司 | G2: 得分 | H2: 权重得分 | J2: 公司 | K2: 考核指标
A3: 版纳 | B3: 280.67058 | C3: 127.88337 | D3: =C3/B3 -> 0.45563511 | E3: 1 | F3: 版纳 | G3: =ROUND(IF(D3=$E$3,100,IF(AND(D3>$E$3),100+(D3-$E$3)/1%*3,100-($E$3-D3)/1%*2)),1) -> -8.9 | H3: =G3*0.1 -> -0.89 | J3: 版纳 | K3: 1
A4: 北城 | B4: 520.41069 | C4: 202.32602 | D4: =C4/B4 -> 0.38878145 | F4: 北城 | G4: =ROUND(IF(D4=$E$3,100,IF(AND(D4>$E$3),100+(D4-$E$3)/1%*3,100-($E$3-D4)/1%*2)),1) -> -22.2 | H4: =G4*0.1 -> -2.22 | J4: 北城 | K4: 1
A5: 北京 | B5: 1642.4747 | C5: 595.02894 | D5: =C5/B5 -> 0.36227586 | F5: 北京 | G5: =ROUND(IF(D5=$E$3,100,IF(AND(D5>$E$3),100+(D5-$E$3)/1%*3,100-($E$3-D5)/1%*2)),1) -> -27.5 | H5: =G5*0.1 -> -2.75 | J5: 北京 | K5: 1
A6: 滨湖 | B6: 505.97782 | C6: 220.90803 | D6: =C6/B6 -> 0.43659627 | F6: 滨湖 | G6: =ROUND(IF(D6=$E$3,100,IF(AND(D6>$E$3),100+(D6-$E$3)/1%*3,100-($E$3-D6)/1%*2)),1) -> -12.7 | H6: =G6*0.1 -> -1.27 | J6: 滨湖 | K6: 1
A7: 阜阳 | B7: 20.963642 | C7: 8.7150515 | D7: =C7/B7 -> 0.41572221 | F7: 阜阳 | G7: =ROUND(IF(D7=$E$3,100,IF(AND(D7>$E$3),100+(D7-$E$3)/1%*3,100-($E$3-D7)/1%*2)),1) -> -16.9 | H7: =G7*0.1 -> -1.69 | J7: 阜阳 | K7: 1
A8: 贵阳 | B8: 922.0172 | C8: 394.50547 | D8: =C8/B8 -> 0.42787213 | F8: 贵阳 | G8: =ROUND(IF(D8=$E$3,100,IF(AND(D8>$E$3),100+(D8-$E$3)/1%*3,100-($E$3-D8)/1%*2)),1) -> -14.4 | H8: =G8*0.1 -> -1.44 | J8: 贵阳 | K8: 1
A9: 昆明 | B9: 2112.0398 | C9: 795.00726 | D9: =C9/B9 -> 0.3764168 | F9: 昆明 | G9: =ROUND(IF(D9=$E$3,100,IF(AND(D9>$E$3),100+(D9-$E$3)/1%*3,100-($E$3-D9)/1%*2)),1) -> -24.7 | H9: =G9*0.1 -> -2.47 | J9: 昆明 | K9: 1
A10: 连江 | B10: 289.75328 | C10: 136.09906 | D10: =C10/B10 -> 0.4697067 | F10: 连江 | G10: =ROUND(IF(D10=$E$3,100,IF(AND(D10>$E$3),100+(D10-$E$3)/1%*3,100-($E$3-D10)/1%*2)),1) -> -6.1 | H10: =G10*0.1 -> -0.61 | J10: 连江 | K10: 1
A11: 罗源 | B11: 159.07708 | C11: 60.550383 | D11: =C11/B11 -> 0.38063549 | F11: 罗源 | G11: =ROUND(IF(D11=$E$3,100,IF(AND(D11>$E$3),100+(D11-$E$3)/1%*3,100-($E$3-D11)/1%*2)),1) -> -23.9 | H11: =G11*0.1 -> -2.39 | J11: 罗源 | K11: 1
A12: 闽江 | B12: 188.92003 | C12: 84.004721 | D12: =C12/B12 -> 0.44465756 | F12: 闽江 | G12: =ROUND(IF(D12=$E$3,100,IF(AND(D12>$E$3),100+(D12-$E$3)/1%*3,100-($E$3-D12)/1%*2)),1) -> -11.1 | H12: =G12*0.1 -> -1.11 | J12: 闽江 | K12: 1
A13: 宁波 | B13: 412.92583 | C13: 195.13466 | D13: =C13/B13 -> 0.47256589 | F13: 宁波 | G13: =ROUND(IF(D13=$E$3,100,IF(AND(D13>$E$3),100+(D13-$E$3)/1%*3,100-($E$3-D13)/1%*2)),1) -> -5.5 | H13: =G13*0.1 -> -0.55 | J13: 宁波 | K13: 1
A14: 腾冲 | B14: 121.09677 | C14: 74.556415 | D14: =C14/B14 -> 0.61567635 | F14: 腾冲 | G14: =ROUND(IF(D14=$E$3,100,IF(AND(D14>$E$3),100+(D14-$E$3)/1%*3,100-($E$3-D14)/1%*2)),1) -> 23.1 | H14: =G14*0.1 -> 2.31 | J14: 腾冲 | K14: 1
A15: 长沙 | B15: 661.0042 | C15: 222.49288 | D15: =C15/B15 -> 0.33659829 | F15: 长沙 | G15: =ROUND(IF(D15=$E$3,100,IF(AND(D15>$E$3),100+(D15-$E$3)/1%*3,100-($E$3-D15)/1%*2)),1) -> -32.7 | H15: =G15*0.1 -> -3.27 | J15: 长沙 | K15: 1
A16: 合计 | B16: 7837.3316 | C16: =SUM(C3:C15) -> 3117.2123 | D16: =C16/B16 -> 0.39773898
A20: 公司 | B20: 25年完成 | C20: 26年预算 | D20: 孰高指标 | E20: 已入账 | F20: 入账同比 | G20: 待入账 | H20: 待续签 | I20: 全年预估收入 | J20: 业绩缺口 | K20: 4月缺口 | L20: 较上月新增 | M20: 备注
A21: 阜阳 | B21: 20.963642 | C21: 20.412388 | D21: 20.963642 | E21: 8.7150515 | F21: 2.1763707 | G21: 5.38 | H21: 7 | I21: =E21+G21+H21 -> 21.095051 | J21: =E21+G21+H21-D21 -> 0.1314098 | K21: 0.21275665 | L21: =-K21+J21 -> -0.08134685
A22: 北城 | B22: 520.41069 | C22: 396.09429 | D22: 520.41069 | E22: 202.32602 | F22: 10.988084 | G22: 170.45 | H22: 99 | I22: =E22+G22+H22 -> 471.77602 | J22: =E22+G22+H22-D22 -> -48.63467 | K22: -50.49825 | L22: =-K22+J22 -> 1.8635805
A23: 宁波 | B23: 412.92583 | C23: 392.40341 | D23: 412.92583 | E23: 195.13466 | F23: 29.475473 | G23: 149.9 | H23: 50 | I23: =E23+G23+H23 -> 395.03466 | J23: =E23+G23+H23-D23 -> -17.891171 | K23: -55.292366 | L23: =-K23+J23 -> 37.401195
A24: 滨湖 | B24: 505.97782 | C24: 501.99821 | D24: =693.97782195-188 -> 505.97782 | E24: 220.90803 | F24: 17.238108 | G24: 144.01 | H24: 15 | I24: =E24+G24+H24 -> 379.91803 | J24: =E24+G24+H24-D24 -> -126.05979 | K24: -123.25837 | L24: =-K24+J24 -> -2.8014205 | M24: 1个广告合同提前退租，替换商家协商中
A25: 长沙 | B25: 614.49592 | C25: 661.0042 | D25: 661.0042 | E25: 222.49288 | F25: -22.594008 | G25: 274.78502 | H25: 31.78 | I25: =E25+G25+H25 -> 529.0579 | J25: =E25+G25+H25-D25 -> -131.94629 | K25: -137.49695 | L25: =-K25+J25 -> 5.5506528
A26: 贵阳 | B26: 922.0172 | C26: 810.02518 | D26: 922.0172 | E26: 394.50547 | F26: -25.412295 | G26: 301.77 | H26: 76.94 | I26: =E26+G26+H26 -> 773.21547 | J26: =E26+G26+H26-D26 -> -148.80174 | K26: -203.74319 | L26: =-K26+J26 -> 54.941453
A27: 北京 | B27: 1642.4747 | C27: 1562.0577 | D27: 1642.4747 | E27: 595.02894 | F27: -56.285752 | G27: 602.54487 | H27: 236.96338 | I27: =E27+G27+H27 -> 1434.5372 | J27: =E27+G27+H27-D27 -> -207.93751 | K27: -207.32784 | L27: =-K27+J27 -> -0.60967052 | M27: 电梯广告退租
A28: 小计 | B28: =SUM(B21:B27) -> 4639.2658 | C28: =SUM(C21:C27) -> 4343.9954 | D28: =SUM(D21:D27) -> 4685.7741 | E28: =SUM(E21:E27) -> 1839.1111 | F28: =SUM(F21:F27) -> -44.414019 | G28: =SUM(G21:G27) -> 1648.8399 | H28: =SUM(H21:H27) -> 516.68338 | I28: =SUM(I21:I27) -> 4004.6343 | ... K28: =SUM(K21:K27) -> -777.40421 | L28: =-K28+J28 -> 96.264444
A29: 闽江 | B29: 188.92003 | C29: 152 | D29: 188.92003 | E29: 84.004721 | F29: 1.8707083 | G29: 93.37 | H29: 6.94 | I29: =E29+G29+H29 -> 184.31472 | J29: =E29+G29+H29-D29 -> -4.6053102 | K29: -3.8464132 | L29: =-K29+J29 -> -0.75889695
A30: 腾冲 | B30: 121.09677 | C30: 100.25263 | D30: 121.09677 | E30: 74.556415 | F30: 29.055305 | G30: 15.585824 | H30: 5 | I30: =E30+G30+H30 -> 95.14224 | J30: =E30+G30+H30-D30 -> -25.954527 | K30: -34.072877 | L30: =-K30+J30 -> 8.1183496
A31: 罗源 | B31: 159.07708 | C31: 115.44343 | D31: 159.07708 | E31: 60.550383 | F31: -3.9209268 | G31: 42.325593 | H31: 9.42 | I31: =E31+G31+H31 -> 112.29598 | J31: =E31+G31+H31-D31 -> -46.781104 | K31: -56.63476 | L31: =-K31+J31 -> 9.8536556
A32: 连江 | B32: 289.75328 | C32: 193 | D32: 289.75328 | E32: 136.09906 | F32: 23.427445 | G32: 93.13 | H32: 7.08 | I32: =E32+G32+H32 -> 236.30906 | J32: =E32+G32+H32-D32 -> -53.444223 | K32: -53.44345 | L32: =-K32+J32 -> -0.00077255 | M32: 5月签约合同已计入4月
A33: 版纳 | B33: 280.67058 | C33: 239.48988 | D33: 280.67058 | E33: 127.88337 | F33: 33.48674 | G33: 94.1 | H33: 3.14 | I33: =E33+G33+H33 -> 225.12337 | J33: =E33+G33+H33-D33 -> -55.547208 | K33: -57.410315 | L33: =-K33+J33 -> 1.8631064
A34: 昆明 | B34: 2093.8022 | C34: 2112.0398 | D34: 2112.0398 | E34: 795.00726 | F34: -3.5485747 | G34: 720 | H34: 375 | I34: =E34+G34+H34 -> 1890.0073 | J34: =E34+G34+H34-D34 -> -222.0325 | K34: -218.24542 | L34: =-K34+J34 -> -3.787078 | M34: 2个合同退租，26年金额6.5万
A35: 小计 | B35: =SUM(B29:B34) -> 3133.32 | C35: =SUM(C29:C34) -> 2912.2257 | D35: =SUM(D29:D34) -> 3151.5575 | E35: =SUM(E29:E34) -> 1278.1012 | F35: =SUM(F29:F34) -> 80.370696 | G35: =SUM(G29:G34) -> 1058.5114 | H35: =SUM(H29:H34) -> 406.58 | I35: =SUM(I29:I34) -> 2743.1926 | ... K35: =SUM(K29:K34) -> -423.65324 | L35: =-K35+J35 -> 15.288364
A36: 合计 | B36: =B28+B35 -> 7772.5858 | C36: =C28+C35 -> 7256.2211 | D36: =D28+D35 -> 7837.3316 | E36: =E28+E35 -> 3117.2123 | F36: =F28+F35 -> 35.956677 | G36: =G28+G35 -> 2707.3513 | H36: =H28+H35 -> 923.26338 | I36: =I28+I35 -> 6747.8269 | ... K36: =K28+K35 -> -1201.0575 | L36: =-K36+J36 -> 111.55281
A40: 公司 | B40: 已入账 | C40: 待入账 | D40: 待续签 | E40: 业绩缺口 | F40: 全年预估收入
A41: 昆明 | B41: =VLOOKUP($A41,$A$21:$J$34,5,0) -> 795.00726 | C41: =VLOOKUP($A41,$A$21:$J$34,7,0) -> 720 | D41: =VLOOKUP($A41,$A$21:$J$34,8,0) -> 375 | E41: =IF(J21<0,VLOOKUP($A41,$A$21:$J$34,10,0)*(-1),VLOOKUP($A41,$A$21:$J$34,10,0)) -> -222.0325 | F41: =B41+C41+D41 -> 1890.0073
A42: 北京 | B42: =VLOOKUP($A42,$A$21:$J$34,5,0) -> 595.02894 | C42: =VLOOKUP($A42,$A$21:$J$34,5,0) -> 595.02894 | D42: =VLOOKUP($A42,$A$21:$J$34,5,0) -> 595.02894 | E42: =IF(J22<0,VLOOKUP($A42,$A$21:$J$34,10,0)*(-1),VLOOKUP($A42,$A$21:$J$34,10,0)) -> 207.93751 | F42: =B42+C42+D42 -> 1785.0868
A43: 贵阳 | B43: =VLOOKUP($A43,$A$21:$J$34,5,0) -> 394.50547 | C43: =VLOOKUP($A43,$A$21:$J$34,5,0) -> 394.50547 | D43: =VLOOKUP($A43,$A$21:$J$34,5,0) -> 394.50547 | E43: =IF(J23<0,VLOOKUP($A43,$A$21:$J$34,10,0)*(-1),VLOOKUP($A43,$A$21:$J$34,10,0)) -> 148.80174 | F43: =B43+C43+D43 -> 1183.5164
A44: 长沙 | B44: =VLOOKUP($A44,$A$21:$J$34,5,0) -> 222.49288 | C44: =VLOOKUP($A44,$A$21:$J$34,5,0) -> 222.49288 | D44: =VLOOKUP($A44,$A$21:$J$34,5,0) -> 222.49288 | E44: =IF(J24<0,VLOOKUP($A44,$A$21:$J$34,10,0)*(-1),VLOOKUP($A44,$A$21:$J$34,10,0)) -> 131.94629 | F44: =B44+C44+D44 -> 667.47864
A45: 滨湖 | B45: =VLOOKUP($A45,$A$21:$J$34,5,0) -> 220.90803 | C45: =VLOOKUP($A45,$A$21:$J$34,5,0) -> 220.90803 | D45: =VLOOKUP($A45,$A$21:$J$34,5,0) -> 220.90803 | E45: =IF(J25<0,VLOOKUP($A45,$A$21:$J$34,10,0)*(-1),VLOOKUP($A45,$A$21:$J$34,10,0)) -> 126.05979 | F45: =B45+C45+D45 -> 662.72409
A46: 北城 | B46: =VLOOKUP($A46,$A$21:$J$34,5,0) -> 202.32602 | C46: =VLOOKUP($A46,$A$21:$J$34,5,0) -> 202.32602 | D46: =VLOOKUP($A46,$A$21:$J$34,5,0) -> 202.32602 | E46: =IF(J26<0,VLOOKUP($A46,$A$21:$J$34,10,0)*(-1),VLOOKUP($A46,$A$21:$J$34,10,0)) -> 48.63467 | F46: =B46+C46+D46 -> 606.97806
A47: 宁波 | B47: =VLOOKUP($A47,$A$21:$J$34,5,0) -> 195.13466 | C47: =VLOOKUP($A47,$A$21:$J$34,5,0) -> 195.13466 | D47: =VLOOKUP($A47,$A$21:$J$34,5,0) -> 195.13466 | E47: =IF(J27<0,VLOOKUP($A47,$A$21:$J$34,10,0)*(-1),VLOOKUP($A47,$A$21:$J$34,10,0)) -> 17.891171 | F47: =B47+C47+D47 -> 585.40399
...

Sheet 业主满意度
A2: 2026年自建项目业主满意度
A3: 公司 | B3: 自调问卷 | C3: 400电话调查 | D3: 问卷8:电话2 | E3: 问卷7:电话3 | F3: 问卷6:电话4 | H3: 公司 | I3: 满意度 | J3: 得分 | K3: 权重得分
A4: 版纳 | H4: 版纳 | I4: =D4 -> 0 | J4: =ROUND(IF(I4=92%,100,IF(I4>92%,100+(I4-92%)/1%*5,IF(AND(I4>82%,I4<92%),100-(92%-I4)/1%*3,70))),1) -> 70 | K4: =ROUND(J4*0.25,1) -> 17.5
A5: 北城 | H5: 北城 | I5: =D5 -> 0 | J5: =ROUND(IF(I5=92%,100,IF(I5>92%,100+(I5-92%)/1%*5,IF(AND(I5>82%,I5<92%),100-(92%-I5)/1%*3,70))),1) -> 70 | K5: =ROUND(J5*0.25,1) -> 17.5
A6: 北京 | H6: 北京 | I6: =D6 -> 0 | J6: =ROUND(IF(I6=92%,100,IF(I6>92%,100+(I6-92%)/1%*5,IF(AND(I6>82%,I6<92%),100-(92%-I6)/1%*3,70))),1) -> 70 | K6: =ROUND(J6*0.25,1) -> 17.5
A7: 滨湖 | H7: 滨湖 | I7: =D7 -> 0 | J7: =ROUND(IF(I7=92%,100,IF(I7>92%,100+(I7-92%)/1%*5,IF(AND(I7>82%,I7<92%),100-(92%-I7)/1%*3,70))),1) -> 70 | K7: =ROUND(J7*0.25,1) -> 17.5
A8: 阜阳 | H8: 阜阳 | I8: =D8 -> 0 | J8: =ROUND(IF(I8=92%,100,IF(I8>92%,100+(I8-92%)/1%*5,IF(AND(I8>82%,I8<92%),100-(92%-I8)/1%*3,70))),1) -> 70 | K8: =ROUND(J8*0.25,1) -> 17.5
A9: 贵阳 | H9: 贵阳 | I9: =D9 -> 0 | J9: =ROUND(IF(I9=92%,100,IF(I9>92%,100+(I9-92%)/1%*5,IF(AND(I9>82%,I9<92%),100-(92%-I9)/1%*3,70))),1) -> 70 | K9: =ROUND(J9*0.25,1) -> 17.5
A10: 昆明 | H10: 昆明 | I10: =D10 -> 0 | J10: =ROUND(IF(I10=92%,100,IF(I10>92%,100+(I10-92%)/1%*5,IF(AND(I10>82%,I10<92%),100-(92%-I10)/1%*3,70))),1) -> 70 | K10: =ROUND(J10*0.25,1) -> 17.5
A11: 连江 | H11: 连江 | I11: =D11 -> 0 | J11: =ROUND(IF(I11=92%,100,IF(I11>92%,100+(I11-92%)/1%*5,IF(AND(I11>82%,I11<92%),100-(92%-I11)/1%*3,70))),1) -> 70 | K11: =ROUND(J11*0.25,1) -> 17.5
A12: 罗源 | H12: 罗源 | I12: =D12 -> 0 | J12: =ROUND(IF(I12=92%,100,IF(I12>92%,100+(I12-92%)/1%*5,IF(AND(I12>82%,I12<92%),100-(92%-I12)/1%*3,70))),1) -> 70 | K12: =ROUND(J12*0.25,1) -> 17.5
A13: 闽江 | H13: 闽江 | I13: =D13 -> 0 | J13: =ROUND(IF(I13=92%,100,IF(I13>92%,100+(I13-92%)/1%*5,IF(AND(I13>82%,I13<92%),100-(92%-I13)/1%*3,70))),1) -> 70 | K13: =ROUND(J13*0.25,1) -> 17.5
A14: 宁波 | H14: 宁波 | I14: =D14 -> 0 | J14: =ROUND(IF(I14=92%,100,IF(I14>92%,100+(I14-92%)/1%*5,IF(AND(I14>82%,I14<92%),100-(92%-I14)/1%*3,70))),1) -> 70 | K14: =ROUND(J14*0.25,1) -> 17.5
A15: 腾冲 | H15: 腾冲 | I15: =D15 -> 0 | J15: =ROUND(IF(I15=92%,100,IF(I15>92%,100+(I15-92%)/1%*5,IF(AND(I15>82%,I15<92%),100-(92%-I15)/1%*3,70))),1) -> 70 | K15: =ROUND(J15*0.25,1) -> 17.5
... A17: 合计 | H17: 合计 | I17: =D17 -> 0 | J17: =ROUND(IF(I17=92%,100,IF(I17>92%,100+(I17-92%)/1%*5,IF(AND(I17>82%,I17<92%),100-(92%-I17)/1%*3,70))),1) -> 70 | K17: =ROUND(J17*0.25,1) -> 17.5
A20: 公司 | B20: 异常问卷 | C20: 问卷有效率 | D20: 扣罚金额 | E20: 扣罚星级
A21: 宁波
A22: 北城
A23: 贵阳
A24: 滨湖
A25: 罗源
A26: 连江
A27: 昆明
A28: 长沙
A29: 版纳
A30: 北京
A31: 闽江
A32: 阜阳
... A34: 总计

Sheet 投诉完成率
A2: 投诉完成率=（本月办结总单量+上月未办结单量-本月不满意单量-上月转本月办结不满意单量）/（投诉总单量+上月未办结单量）
A3: 2026年投诉完成率（数据为呼叫中心提供）
A4: 公司 | B4: 1月 | C4: 2月 | D4: 3月 | E4: 4月 | F4: 5月 | G4: 6月 | H4: 7月 | I4: 8月 | J4: 9月 | K4: 10月 | L4: 11月 | M4: 12月 | O4: 公司 | P4: 得分 | Q4: 权重得分 | S4: 年度满意度 | T4: 系数
A5: 版纳 | B5: 0.56930693 | C5: 0.64761905 | D5: 0.74324324 | E5: 0.80291971 | F5: 0.6557377 | N5: =AVERAGE(B5:M5) -> 0.68376533 | O5: =A5 -> 版纳 | P5: =(100-COUNTIF(B5:M5,"<0.75")*5)*T5 -> 80 | Q5: =P5*0.1 -> 8 | S5: =N115 -> 56.104418 | T5: =IF(S5>50,1,IF(S5<40,0.9,0.95)) -> 1 | U5: =IF(S2="","",IF(S2>=50,1,IF(S2<40,0.9,0.95)))
A6: 北城 | B6: 0.81533101 | C6: 0.73577236 | D6: 0.79661017 | E6: 0.75636364 | F6: 0.73782772 | N6: =AVERAGE(B6:M6) -> 0.76838098 | O6: =A6 -> 北城 | P6: =(100-COUNTIF(B6:M6,"<0.75")*5)*T6 -> 90 | Q6: =P6*0.1 -> 9 | S6: =N116 -> 51.604938 | T6: =IF(S6>50,1,IF(S6<40,0.9,0.95)) -> 1
A7: 北京 | B7: 0.73263889 | C7: 0.79638009 | D7: 0.47906977 | E7: 0.65145228 | F7: 0.52091255 | N7: =AVERAGE(B7:M7) -> 0.63609072 | O7: =A7 -> 北京 | P7: =(100-COUNTIF(B7:M7,"<0.75")*5)*T7 -> 80 | Q7: =P7*0.1 -> 8 | S7: =N117 -> 60.640569 | T7: =IF(S7>50,1,IF(S7<40,0.9,0.95)) -> 1
A8: 滨湖 | B8: 0.68312757 | C8: 0.7189781 | D8: 0.68441065 | E8: 0.75268817 | F8: 0.79710145 | N8: =AVERAGE(B8:M8) -> 0.72726119 | O8: =A8 -> 滨湖 | P8: =(100-COUNTIF(B8:M8,"<0.75")*5)*T8 -> 85 | Q8: =P8*0.1 -> 8.5 | S8: =N118 -> 51.279318 | T8: =IF(S8>50,1,IF(S8<40,0.9,0.95)) -> 1
A9: 阜阳 | B9: 0.46835443 | C9: 0.79166667 | D9: 0.47368421 | E9: 0.67142857 | F9: 0.84782609 | N9: =AVERAGE(B9:M9) -> 0.65059199 | O9: 阜阳 | P9: =(100-COUNTIF(B9:M9,"<0.75")*5)*T9 -> 80.75 | Q9: =P9*0.1 -> 8.075 | S9: =N119 -> 46.55914 | T9: =IF(S9>50,1,IF(S9<40,0.9,0.95)) -> 0.95
A10: 贵阳 | B10: 0.824 | C10: 0.88023952 | D10: 0.91219512 | E10: 0.84210526 | F10: 0.87109375 | N10: =AVERAGE(B10:M10) -> 0.86592673 | O10: =A10 -> 贵阳 | P10: =(100-COUNTIF(B10:M10,"<0.75")*5)*T10 -> 100 | Q10: =P10*0.1 -> 10 | S10: =N120 -> 74.830508 | T10: =IF(S10>50,1,IF(S10<40,0.9,0.95)) -> 1
A11: 昆明 | B11: 0.70562771 | C11: 0.855 | D11: 0.89400922 | E11: 0.91176471 | F11: 0.836 | N11: =AVERAGE(B11:M11) -> 0.84048033 | O11: =A11 -> 昆明 | P11: =(100-COUNTIF(B11:M11,"<0.75")*5)*T11 -> 95 | Q11: =P11*0.1 -> 9.5 | S11: =N121 -> 75.048544 | T11: =IF(S11>50,1,IF(S11<40,0.9,0.95)) -> 1
A12: 连江 | B12: 0.75 | C12: 0.76727273 | D12: 0.74895397 | E12: 0.83557951 | F12: 0.7748538 | N12: =AVERAGE(B12:M12) -> 0.775332 | O12: =A12 -> 连江 | P12: =(100-COUNTIF(B12:M12,"<0.75")*5)*T12 -> 95 | Q12: =P12*0.1 -> 9.5 | S12: =N122 -> 52.545045 | T12: =IF(S12>50,1,IF(S12<40,0.9,0.95)) -> 1
A13: 罗源 | B13: 0.57768924 | C13: 0.63513514 | D13: 0.57831325 | E13: 0.56065574 | F13: 0.64575646 | N13: =AVERAGE(B13:M13) -> 0.59950997 | O13: =A13 -> 罗源 | P13: =(100-COUNTIF(B13:M13,"<0.75")*5)*T13 -> 67.5 | Q13: =P13*0.1 -> 6.75 | S13: =N123 -> 33.677249 | T13: =IF(S13>50,1,IF(S13<40,0.9,0.95)) -> 0.9
A14: 闽江 | B14: 0.77941176 | C14: 0.82608696 | D14: 0.83076923 | E14: 0.81690141 | F14: 0.82692308 | N14: =AVERAGE(B14:M14) -> 0.81601849 | O14: =A14 -> 闽江 | P14: =(100-COUNTIF(B14:M14,"<0.75")*5)*T14 -> 100 | Q14: =P14*0.1 -> 10 | S14: =N124 -> 63.723404 | T14: =IF(S14>50,1,IF(S14<40,0.9,0.95)) -> 1
A15: 宁波 | B15: 0.71641791 | C15: 0.6993007 | D15: 0.70604396 | E15: 0.718 | F15: 0.75592417 | N15: =AVERAGE(B15:M15) -> 0.71913735 | O15: =A15 -> 宁波 | P15: =(100-COUNTIF(B15:M15,"<0.75")*5)*T15 -> 80 | Q15: =P15*0.1 -> 8 | S15: =N125 -> 57.215815 | T15: =IF(S15>50,1,IF(S15<40,0.9,0.95)) -> 1
A16: 腾冲 | B16: 0.90625 | C16: 0.75862069 | D16: 0.7 | E16: 0.36956522 | F16: 0.75757576 | N16: =AVERAGE(B16:M16) -> 0.69840233 | O16: =A16 -> 腾冲 | P16: =(100-COUNTIF(B16:M16,"<0.75")*5)*T16 -> 81 | Q16: =P16*0.1 -> 8.1 | S16: =N126 -> 34.770642 | T16: =IF(S16>50,1,IF(S16<40,0.9,0.95)) -> 0.9
A17: 长沙 | B17: 0.61983471 | C17: 0.8 | D17: 0.81621622 | E17: 0.74208145 | F17: 0.77731092 | N17: =AVERAGE(B17:M17) -> 0.75108866 | O17: =A17 -> 长沙 | P17: =(100-COUNTIF(B17:M17,"<0.75")*5)*T17 -> 90 | Q17: =P17*0.1 -> 9 | S17: =N127 -> 56.412698 | T17: =IF(S17>50,1,IF(S17<40,0.9,0.95)) -> 1
A18: 合计 | B18: 0.70362694 | C18: 0.74979184 | D18: 0.72790507 | E18: 0.73548171 | F18: 0.7460815 | N18: =AVERAGE(B18:M18) -> 0.73257741
A21: 2026投诉汇总
A22: 公司 | B22: 1月 | C22: 2月 | D22: 3月 | E22: 4月 | F22: 5月 | G22: 6月 | H22: 7月 | I22: 8月 | J22: 9月 | K22: 10月 | L22: 11月 | M22: 12月 | N22: 总计
A23: 版纳 | B23: 202 | C23: 210 | D23: 147 | E23: 136 | F23: 121 | N23: =SUM(B23:M23) -> 816
A24: 北城 | B24: 286 | C24: 245 | D24: 236 | E24: 275 | F24: 267 | N24: =SUM(B24:M24) -> 1309
A25: 北京 | B25: 287 | C25: 221 | D25: 214 | E25: 215 | F25: 213 | N25: =SUM(B25:M25) -> 1150
A26: 滨湖 | B26: 243 | C26: 274 | D26: 263 | E26: 279 | F26: 274 | N26: =SUM(B26:M26) -> 1333
A27: 阜阳 | B27: 79 | C27: 48 | D27: 38 | E27: 70 | F27: 46 | N27: =SUM(B27:M27) -> 281
A28: 贵阳 | B28: 250 | C28: 167 | D28: 205 | E28: 247 | F28: 256 | N28: =SUM(B28:M28) -> 1125
A29: 昆明 | B29: 229 | C29: 200 | D29: 217 | E29: 170 | F29: 250 | N29: =SUM(B29:M29) -> 1066
A30: 连江 | B30: 320 | C30: 275 | D30: 239 | E30: 371 | F30: 342 | N30: =SUM(B30:M30) -> 1547
A31: 罗源 | B31: 234 | C31: 205 | D31: 246 | E31: 294 | F31: 247 | N31: =SUM(B31:M31) -> 1226
A32: 闽江 | B32: 68 | C32: 69 | D32: 65 | E32: 71 | F32: 50 | N32: =SUM(B32:M32) -> 323
A33: 宁波 | B33: 396 | C33: 281 | D33: 353 | E33: 489 | F33: 412 | N33: =SUM(B33:M33) -> 1931
A34: 腾冲 | B34: 32 | C34: 29 | D34: 20 | E34: 92 | F34: 66 | N34: =SUM(B34:M34) -> 239
A35: 长沙 | B35: 242 | C35: 155 | D35: 185 | E35: 221 | F35: 238 | N35: =SUM(B35:M35) -> 1041
A36: 总计 | B36: =SUM(B23:B35) -> 2868 | C36: =SUM(C23:C35) -> 2379 | D36: =SUM(D23:D35) -> 2428 | E36: =SUM(E23:E35) -> 2930 | F36: =SUM(F23:F35) -> 2782 | G36: =SUM(G23:G35) -> 0 | H36: =SUM(H23:H35) -> 0 | I36: =SUM(I23:I35) -> 0 | ... M36: =SUM(M23:M35) -> 0 | N36: =SUM(B36:M36) -> 13387
A39: 2026投诉回访不满意工单
A40: 公司 | B40: 1月 | C40: 2月 | D40: 3月 | E40: 4月 | F40: 5月 | G40: 6月 | H40: 7月 | I40: 8月 | J40: 9月 | K40: 10月 | L40: 11月 | M40: 12月 | N40: 总计
A41: 版纳 | B41: 57 | C41: 55 | D41: 32 | E41: 22 | F41: 24 | N41: =SUM(B41:M41) -> 190
A42: 北城 | B42: 49 | C42: 64 | D42: 48 | E42: 65 | F42: 70 | N42: =SUM(B42:M42) -> 296
A43: 北京 | B43: 51 | C43: 33 | D43: 41 | E43: 28 | F43: 28 | N43: =SUM(B43:M43) -> 181
A44: 滨湖 | B44: 77 | C44: 76 | D44: 83 | E44: 67 | F44: 54 | N44: =SUM(B44:M44) -> 357
A45: 阜阳 | B45: 42 | C45: 10 | D45: 20 | E45: 23 | F45: 7 | N45: =SUM(B45:M45) -> 102
...

Sheet 设备设施管理
B2: 公司 | C2: 巡检完成率 | D2: 维保完成率 | E2: 现场巡查系数 | G2: 公司 | H2: 得分 | I2: 权重得分
B3: 版纳 | G3: 版纳 | H3: =(100*C3*50%+100*D3*50%)*E3 -> 0 | I3: =H3*0.1 -> 0
B4: 北城 | G4: 北城 | H4: =(100*C4*50%+100*D4*50%)*E4 -> 0 | I4: =H4*0.1 -> 0
B5: 北京 | G5: 北京 | H5: =(100*C5*50%+100*D5*50%)*E5 -> 0 | I5: =H5*0.1 -> 0
B6: 滨湖 | G6: 滨湖 | H6: =(100*C6*50%+100*D6*50%)*E6 -> 0 | I6: =H6*0.1 -> 0
B7: 阜阳 | G7: 阜阳 | H7: =(100*C7*50%+100*D7*50%)*E7 -> 0 | I7: =H7*0.1 -> 0
B8: 贵阳 | G8: 贵阳 | H8: =(100*C8*50%+100*D8*50%)*E8 -> 0 | I8: =H8*0.1 -> 0
B9: 昆明 | G9: 昆明 | H9: =(100*C9*50%+100*D9*50%)*E9 -> 0 | I9: =H9*0.1 -> 0
B10: 连江 | G10: 连江 | H10: =(100*C10*50%+100*D10*50%)*E10 -> 0 | I10: =H10*0.1 -> 0
B11: 罗源 | G11: 罗源 | H11: =(100*C11*50%+100*D11*50%)*E11 -> 0 | I11: =H11*0.1 -> 0
B12: 闽江 | G12: 闽江 | H12: =(100*C12*50%+100*D12*50%)*E12 -> 0 | I12: =H12*0.1 -> 0
B13: 宁波 | G13: 宁波 | H13: =(100*C13*50%+100*D13*50%)*E13 -> 0 | I13: =H13*0.1 -> 0
B14: 腾冲 | G14: 腾冲 | H14: =(100*C14*50%+100*D14*50%)*E14 -> 0 | I14: =H14*0.1 -> 0
... B16: 集团 | G16: 集团 | H16: =(100*C16*50%+100*D16*50%)*E16 -> 0 | I16: =H16*0.1 -> 0

Sheet 自用能耗成本
B2: 公司 | C2: 合计收入 | D2: 合计成本 | E2: 盈亏率 | F2: 24盈亏率 | G2: 同比差异 | H2: 修正情况 | J2: 公司 | K2: 得分 | L2: 权重得分
B3: 版纳 | J3: 版纳 | K3: 120 | L3: =K3*0.05 -> 6
B4: 北城 | J4: 北城 | K4: 113.49797 | L4: =K4*0.05 -> 5.6748985
B5: 北京 | J5: 北京 | K5: 119.04002 | L5: =K5*0.05 -> 5.9520011
B6: 滨湖 | J6: 滨湖 | K6: 120 | L6: =K6*0.05 -> 6
B7: 阜阳 | J7: 阜阳 | K7: 120 | L7: =K7*0.05 -> 6
B8: 贵阳 | J8: 贵阳 | K8: 111.35705 | L8: =K8*0.05 -> 5.5678524
B9: 昆明 | J9: 昆明 | K9: 79.413851 | L9: =K9*0.05 -> 3.9706925
B10: 连江 | J10: 连江 | K10: 120 | L10: =K10*0.05 -> 6
B11: 罗源 | J11: 罗源 | K11: 99.557215 | L11: =K11*0.05 -> 4.9778608
B12: 闽江 | J12: 闽江 | K12: 120 | L12: =K12*0.05 -> 6
B13: 宁波 | J13: 宁波 | K13: 115.43206 | L13: =K13*0.05 -> 5.7716028
B14: 腾冲 | J14: 腾冲 | K14: 75.824727 | L14: =K14*0.05 -> 3.7912363
... B16: 集团 | J16: 集团 | K16: 112.55535 | L16: =K16*0.05 -> 5.6277676

Sheet 基础信息抽查
A1: 2026年基础信息准确率
A2: 公司 | B2: 1月 | C2: 2月 | D2: 3月 | E2: 4月 | F2: 5月 | G2: 6月 | H2: 7月 | I2: 8月 | J2: 9月 | K2: 10月 | L2: 11月 | M2: 12月 | N2: 年度均值 | O2: 公司 | P2: 均值 | Q2: 得分 | R2: 权重得分
A3: 版纳 | B3: 0.90334572 | D3: 0.90688259 | E3: 0.88888889 | F3: 0.91290323 | N3: =AVERAGE(B3:M3) -> 0.90300511 | O3: 版纳 | P3: =AVERAGE(B3:M3) -> 0.90300511 | Q3: =ROUND(IF(P3>=95%,100,IF(P3>=75%,100-(95%-P3)/1%*3,40)),1) -> 85.9 | R3: =Q3*0.05 -> 4.295 | S3: 0.90334572 | T3: 0.44032922
A4: 北城 | B4: 0.9 | D4: 0.94112061 | E4: 0.99698492 | F4: 0.89963168 | N4: =AVERAGE(B4:M4) -> 0.9344343 | O4: 北城 | P4: =AVERAGE(B4:M4) -> 0.9344343 | Q4: =ROUND(IF(P4>=95%,100,IF(P4>=75%,100-(95%-P4)/1%*3,40)),1) -> 95.3 | R4: =Q4*0.05 -> 4.765 | S4: 0.9 | T4: 0.4620462
A5: 北京 | B5: 0.92519685 | D5: 0.92635659 | E5: 0.92241379 | F5: 0.9628866 | N5: =AVERAGE(B5:M5) -> 0.93421346 | O5: 北京 | P5: =AVERAGE(B5:M5) -> 0.93421346 | Q5: =ROUND(IF(P5>=95%,100,IF(P5>=75%,100-(95%-P5)/1%*3,40)),1) -> 95.3 | R5: =Q5*0.05 -> 4.765 | S5: 0.92519685 | T5: 0.61702128
A6: 滨湖 | B6: 0.82679739 | D6: 0.84090909 | E6: 0.85667216 | F6: 0.86911765 | N6: =AVERAGE(B6:M6) -> 0.84837407 | O6: 滨湖 | P6: =AVERAGE(B6:M6) -> 0.84837407 | Q6: =ROUND(IF(P6>=95%,100,IF(P6>=75%,100-(95%-P6)/1%*3,40)),1) -> 69.5 | R6: =Q6*0.05 -> 3.475 | S6: 0.82679739 | T6: 0.46640316
A7: 阜阳 | B7: 0.92546584 | D7: 0.93567251 | E7: 0.95302013 | F7: 0.93220339 | N7: =AVERAGE(B7:M7) -> 0.93659047 | O7: 阜阳 | P7: =AVERAGE(B7:M7) -> 0.93659047 | Q7: =ROUND(IF(P7>=95%,100,IF(P7>=75%,100-(95%-P7)/1%*3,40)),1) -> 96 | R7: =Q7*0.05 -> 4.8 | S7: 0.92546584 | T7: 0.55033557
A8: 贵阳 | B8: 0.9441402 | D8: 0.94376278 | E8: 0.94234801 | F8: 0.96737213 | N8: =AVERAGE(B8:M8) -> 0.94940578 | O8: 贵阳 | P8: 0.996 | Q8: =ROUND(IF(P8>=95%,100,IF(P8>=75%,100-(95%-P8)/1%*3,40)),1) -> 100 | R8: =Q8*0.05 -> 5 | S8: 0.9441402 | T8: 0.47911833
A9: 昆明 | B9: 0.98295455 | D9: 0.96056338 | E9: 0.93489583 | F9: 0.97132616 | N9: =AVERAGE(B9:M9) -> 0.96243498 | O9: 昆明 | P9: =AVERAGE(B9:M9) -> 0.96243498 | Q9: =ROUND(IF(P9>=95%,100,IF(P9>=75%,100-(95%-P9)/1%*3,40)),1) -> 100 | R9: =Q9*0.05 -> 5 | S9: 0.98295455 | T9: 0.56647399
A10: 连江 | B10: 0.92597765 | D10: 0.90769231 | E10: 0.94730392 | F10: 0.95733611 | N10: =AVERAGE(B10:M10) -> 0.9345775 | O10: 连江 | P10: =AVERAGE(B10:M10) -> 0.9345775 | Q10: =ROUND(IF(P10>=95%,100,IF(P10>=75%,100-(95%-P10)/1%*3,40)),1) -> 95.4 | R10: =Q10*0.05 -> 4.77 | S10: 0.92597765 | T10: 0.5158371
A11: 罗源 | B11: 0.95839753 | D11: 0.94714882 | E11: 0.95492958 | F11: 0.95454545 | N11: =AVERAGE(B11:M11) -> 0.95375535 | O11: 罗源 | P11: =AVERAGE(B11:M11) -> 0.95375535 | Q11: =ROUND(IF(P11>=95%,100,IF(P11>=75%,100-(95%-P11)/1%*3,40)),1) -> 100 | R11: =Q11*0.05 -> 5 | S11: 0.95839753 | T11: 0.52572347
A12: 闽江 | B12: 0.9375 | D12: 0.93886463 | E12: 0.89166667 | F12: 0.94921875 | N12: =AVERAGE(B12:M12) -> 0.92931251 | O12: 闽江 | P12: =AVERAGE(B12:M12) -> 0.92931251 | Q12: =ROUND(IF(P12>=95%,100,IF(P12>=75%,100-(95%-P12)/1%*3,40)),1) -> 93.8 | R12: =Q12*0.05 -> 4.69 | S12: 0.9375 | T12: 0.53333333
A13: 宁波 | B13: 0.89051095 | D13: 0.88846154 | E13: 0.88619403 | F13: 0.91917973 | N13: =AVERAGE(B13:M13) -> 0.89608656 | O13: 宁波 | P13: 0.936 | Q13: =ROUND(IF(P13>=95%,100,IF(P13>=75%,100-(95%-P13)/1%*3,40)),1) -> 95.8 | R13: =Q13*0.05 -> 4.79 | S13: 0.89051095 | T13: 0.46106557
A14: 腾冲 | B14: 0.88275862 | D14: 0.91056911 | E14: 0.85714286 | F14: 0.91017964 | N14: =AVERAGE(B14:M14) -> 0.89016256 | O14: 腾冲 | P14: =AVERAGE(B14:M14) -> 0.89016256 | Q14: =ROUND(IF(P14>=95%,100,IF(P14>=75%,100-(95%-P14)/1%*3,40)),1) -> 82 | R14: =Q14*0.05 -> 4.1 | S14: 0.88275862 | T14: 0.625
A15: 长沙 | B15: 0.92273731 | D15: 0.90361446 | E15: 0.91275168 | F15: 0.92110092 | N15: =AVERAGE(B15:M15) -> 0.91505109 | O15: 长沙 | P15: =AVERAGE(B15:M15) -> 0.91505109 | Q15: =ROUND(IF(P15>=95%,100,IF(P15>=75%,100-(95%-P15)/1%*3,40)),1) -> 89.5 | R15: =Q15*0.05 -> 4.475 | S15: 0.92273731 | T15: 0.50717703
A16: 总计 | B16: 0.9164288 | D16: 0.92045632 | E16: 0.93143034 | F16: 0.93440563 | N16: =AVERAGE(B16:M16) -> 0.92568027 | P16: =AVERAGE(B16:M16) -> 0.92568027 | S16: 0.9164288 | T16: 0.5012978
A20: 2025年基础信息准确率
A21: 公司 | B21: 1月 | C21: 2月 | D21: 3月 | E21: 4月 | F21: 5月 | G21: 6月 | H21: 7月 | I21: 8月 | J21: 9月 | K21: 10月 | L21: 11月 | M21: 12月 | N21: 年度均值
A22: 版纳 | B22: 0.88104089 | C22: 0.89361702 | D22: 0.90545455 | E22: 0.89315068 | F22: 0.90748031 | G22: 0.89618644 | H22: 0.93287037 | I22: 0.92814371 | J22: 0.94230769 | L22: 0.96747967 | M22: 0 | N22: =AVERAGE(B22:M22) -> 0.83161194
A23: 北城 | B23: 0.96035242 | C23: 0.95909423 | D23: 0.93871665 | E23: 0.95 | F23: 0.9486458 | G23: 0.94676442 | H23: 0.96996047 | I23: 0.94805803 | J23: 0.95989613 | L23: 0.95813205 | M23: 0.81925926 | N23: =AVERAGE(B23:M23) -> 0.94171632
A24: 北京 | B24: 0.97597598 | C24: 0.95211268 | D24: 0.94647887 | E24: 0.94959677 | F24: 0.94751381 | G24: 0.94928479 | H24: 0.96194503 | I24: 0.96049046 | J24: 0.95229983 | L24: 0.97887324 | M24: 0.93396226 | N24: =AVERAGE(B24:M24) -> 0.95532125
A25: 滨湖 | B25: 0.942324 | C25: 0.94463087 | D25: 0.93333333 | E25: 0.93100276 | F25: 0.93813776 | G25: 0.93084371 | H25: 0.93044129 | I25: 0.92495637 | J25: 0.92639734 | L25: 0.96327684 | M25: 1 | N25: =AVERAGE(B25:M25) -> 0.94230402
A26: 阜阳 | B26: 0.95789474 | C26: 0.97008547 | D26: 0.96787149 | E26: 0.95081967 | F26: 0.91743119 | G26: 0.9742268 | H26: 0.96439169 | I26: 0.96497373 | J26: 0.95913978 | L26: 0.9921875 | M26: 1 | N26: =AVERAGE(B26:M26) -> 0.96536564
A27: 贵阳 | B27: 0.9592721 | C27: 0.97024346 | D27: 0.95604396 | E27: 0.96643878 | F27: 0.97345133 | G27: 0.94391678 | H27: 0.97776655 | I27: 0.97580398 | J27: 0.96951702 | L27: 0.9305073 | M27: 1 | N27: =AVERAGE(B27:M27) -> 0.96572375
A28: 昆明 | B28: 0.97727273 | C28: 0.9751693 | D28: 0.95842956 | E28: 0.92628205 | F28: 0.9516129 | G28: 0.96246973 | H28: 0.96944444 | I28: 0.96655518 | J28: 0.96283391 | L28: 0.95625 | M28: 0.91666667 | N28: =AVERAGE(B28:M28) -> 0.95663514
A29: 连江 | B29: 0.96491228 | C29: 0.9608802 | D29: 0.95298602 | E29: 0.95837024 | F29: 0.96213658 | G29: 0.93873762 | H29: 0.95676047 | I29: 0.93124006 | J29: 0.93753123 | L29: 0.97876106 | M29: 1 | N29: =AVERAGE(B29:M29) -> 0.95839234
A30: 罗源 | B30: 0.97081413 | C30: 0.96396396 | D30: 0.95820433 | E30: 0.95762712 | F30: 0.95231214 | G30: 0.95010115 | H30: 0.97229219 | I30: 0.95508391 | J30: 0.95087065 | L30: 0.93908629 | M30: 1 | N30: =AVERAGE(B30:M30) -> 0.96094144
A31: 闽江 | B31: 0.95112782 | C31: 0.97026022 | D31: 0.95564516 | E31: 0.92196532 | F31: 0.93139293 | G31: 0.93904762 | H31: 0.96856582 | I31: 0.94146341 | J31: 0.95290424 | L31: 0.86842105 | M31: 1 | N31: =AVERAGE(B31:M31) -> 0.94552669
A32: 宁波 | B32: 0.93222222 | C32: 0.93691589 | D32: 0.93502538 | E32: 0.92548435 | F32: 0.925 | G32: 0.94618145 | H32: 0.93883792 | I32: 0.9310183 | J32: 0.93381906 | L32: 0.9487909 | M32: 0.85495119 | N32: =AVERAGE(B32:M32) -> 0.92802242
A33: 腾冲 | B33: 0.97765363 | C33: 0.94193548 | D33: 0.9378882 | E33: 0.94418605 | F33: 0.9269103 | G33: 0.9252669 | H33: 0.94186047 | I33: 0.91706161 | J33: 0.92774566 | L33: 0.975 | M33: 0.75 | N33: =AVERAGE(B33:M33) -> 0.92413712
... A35: 总计 | B35: 0.9552257 | C35: 0.95463868 | D35: 0.94557736 | E35: 0.94379289 | F35: 0.94615385 | G35: 0.94451629 | H35: 0.96062875 | I35: 0.94780074 | J35: 0.94969615 | L35: 0.95210424 | M35: 0.8474359 | N35: =AVERAGE(B35:M35) -> 0.94068823

Sheet 400知晓率
A1: 2025年知晓400电话比例
A2: 公司 | B2: 1月 | C2: 2月 | D2: 3月 | E2: 4月 | F2: 5月 | G2: 6月 | H2: 7月 | I2: 8月 | J2: 9月 | K2: 10月 | L2: 11月 | M2: 12月 | N2: 年度均值 | P2: 公司 | Q2: 均值 | R2: 得分 | S2: 权重得分
A3: 版纳 | B3: 0.44032922 | D3: 0.45982143 | E3: 0.50925926 | F3: 0.61130742 | N3: =AVERAGE(B3:M3) -> 0.50517933 | P3: 版纳 | Q3: =AVERAGE(B3:M3) -> 0.50517933 | R3: =ROUND(IF(Q3=50%,100,IF(Q3>50%,100+(Q3-50%)/1%*2,100-(50%-Q3)/1%*2)),1) -> 101 | S3: =R3*0.05 -> 5.05
A4: 北城 | B4: 0.4620462 | D4: 0.46014127 | E4: 0.46673387 | F4: 0.4370522 | N4: =AVERAGE(B4:M4) -> 0.45649339 | P4: 北城 | Q4: 0.5054 | R4: =ROUND(IF(Q4=50%,100,IF(Q4>50%,100+(Q4-50%)/1%*2,100-(50%-Q4)/1%*2)),1) -> 101.1 | S4: =R4*0.05 -> 5.055
A5: 北京 | B5: 0.61702128 | D5: 0.65271967 | E5: 0.69626168 | F5: 0.86723769 | N5: =AVERAGE(B5:M5) -> 0.70831008 | P5: 北京 | Q5: =AVERAGE(B5:M5) -> 0.70831008 | R5: =ROUND(IF(Q5=50%,100,IF(Q5>50%,100+(Q5-50%)/1%*2,100-(50%-Q5)/1%*2)),1) -> 141.7 | S5: =R5*0.05 -> 7.085
A6: 滨湖 | B6: 0.46640316 | D6: 0.41119691 | E6: 0.45961538 | F6: 0.51945854 | N6: =AVERAGE(B6:M6) -> 0.4641685 | P6: 滨湖 | Q6: =AVERAGE(B6:M6) -> 0.4641685 | R6: =ROUND(IF(Q6=50%,100,IF(Q6>50%,100+(Q6-50%)/1%*2,100-(50%-Q6)/1%*2)),1) -> 92.8 | S6: =R6*0.05 -> 4.64
A7: 阜阳 | B7: 0.55033557 | D7: 0.49375 | E7: 0.58450704 | F7: 0.61818182 | N7: =AVERAGE(B7:M7) -> 0.56169361 | P7: 阜阳 | Q7: =AVERAGE(B7:M7) -> 0.56169361 | R7: =ROUND(IF(Q7=50%,100,IF(Q7>50%,100+(Q7-50%)/1%*2,100-(50%-Q7)/1%*2)),1) -> 112.3 | S7: =R7*0.05 -> 5.615
A8: 贵阳 | B8: 0.47911833 | D8: 0.49512459 | E8: 0.58731924 | F8: 0.57976299 | N8: =AVERAGE(B8:M8) -> 0.53533129 | P8: 贵阳 | Q8: 0.523 | R8: =ROUND(IF(Q8=50%,100,IF(Q8>50%,100+(Q8-50%)/1%*2,100-(50%-Q8)/1%*2)),1) -> 104.6 | S8: =R8*0.05 -> 5.23
A9: 昆明 | B9: 0.56647399 | D9: 0.50439883 | E9: 0.51532033 | F9: 0.68819188 | N9: =AVERAGE(B9:M9) -> 0.56859626 | P9: 昆明 | Q9: =AVERAGE(B9:M9) -> 0.56859626 | R9: =ROUND(IF(Q9=50%,100,IF(Q9>50%,100+(Q9-50%)/1%*2,100-(50%-Q9)/1%*2)),1) -> 113.7 | S9: =R9*0.05 -> 5.685
A10: 连江 | B10: 0.5158371 | D10: 0.52080123 | E10: 0.65847348 | F10: 0.69673913 | N10: =AVERAGE(B10:M10) -> 0.59796274 | P10: 连江 | Q10: =AVERAGE(B10:M10) -> 0.59796274 | R10: =ROUND(IF(Q10=50%,100,IF(Q10>50%,100+(Q10-50%)/1%*2,100-(50%-Q10)/1%*2)),1) -> 119.6 | S10: =R10*0.05 -> 5.98
A11: 罗源 | B11: 0.52572347 | D11: 0.55359765 | E11: 0.58849558 | F11: 0.56190476 | N11: =AVERAGE(B11:M11) -> 0.55743037 | P11: 罗源 | Q11: =AVERAGE(B11:M11) -> 0.55743037 | R11: =ROUND(IF(Q11=50%,100,IF(Q11>50%,100+(Q11-50%)/1%*2,100-(50%-Q11)/1%*2)),1) -> 111.5 | S11: =R11*0.05 -> 5.575
A12: 闽江 | B12: 0.53333333 | D12: 0.56744186 | E12: 0.52336449 | F12: 0.5473251 | N12: =AVERAGE(B12:M12) -> 0.5428662 | P12: 闽江 | Q12: =AVERAGE(B12:M12) -> 0.5428662 | R12: =ROUND(IF(Q12=50%,100,IF(Q12>50%,100+(Q12-50%)/1%*2,100-(50%-Q12)/1%*2)),1) -> 108.6 | S12: =R12*0.05 -> 5.43
A13: 宁波 | B13: 0.46106557 | D13: 0.46536797 | E13: 0.48842105 | F13: 0.69422572 | N13: =AVERAGE(B13:M13) -> 0.52727008 | P13: 宁波 | Q13: 0.459 | R13: =ROUND(IF(Q13=50%,100,IF(Q13>50%,100+(Q13-50%)/1%*2,100-(50%-Q13)/1%*2)),1) -> 91.8 | S13: =R13*0.05 -> 4.59
A14: 腾冲 | B14: 0.625 | D14: 0.45535714 | E14: 0.50877193 | F14: 0.66447368 | N14: =AVERAGE(B14:M14) -> 0.56340069 | P14: 腾冲 | Q14: =AVERAGE(B14:M14) -> 0.56340069 | R14: =ROUND(IF(Q14=50%,100,IF(Q14>50%,100+(Q14-50%)/1%*2,100-(50%-Q14)/1%*2)),1) -> 112.7 | S14: =R14*0.05 -> 5.635
A15: 长沙 | B15: 0.50717703 | D15: 0.41066667 | E15: 0.50980392 | F15: 0.57569721 | N15: =AVERAGE(B15:M15) -> 0.50083621 | P15: 长沙 | Q15: =AVERAGE(B15:M15) -> 0.50083621 | R15: =ROUND(IF(Q15=50%,100,IF(Q15>50%,100+(Q15-50%)/1%*2,100-(50%-Q15)/1%*2)),1) -> 100.2 | S15: =R15*0.05 -> 5.01
A16: 总计 | B16: 0.5012978 | D16: 0.49117148 | E16: 0.54546969 | F16: 0.60906401 | N16: =AVERAGE(B16:M16) -> 0.53675074 | P16: 总计 | Q16: =AVERAGE(Q3:Q15) -> 0.54291107 | R16: =ROUND(IF(Q16=50%,100,IF(Q16>50%,100+(Q16-50%)/1%*2,100-(50%-Q16)/1%*2)),1) -> 108.6 | S16: =R16*0.05 -> 5.43
A21: 2025年知晓400电话比例
A22: 公司 | B22: 1月 | C22: 2月 | D22: 3月 | E22: 4月 | F22: 5月 | G22: 6月 | H22: 7月 | I22: 8月 | J22: 9月 | K22: 10月 | L22: 11月 | M22: 12月 | N22: 年度均值
A23: 版纳 | B23: 0.52320675 | C23: 0.47222222 | D23: 0.55421687 | E23: 0.49079755 | F23: 0.51409978 | G23: 0.52955083 | H23: 0.39205955 | I23: 0.35870968 | J23: 0.42687075 | L23: 0.7394958 | M23: 0 | N23: =AVERAGE(B23:M23) -> 0.45465725
A24: 北城 | B24: 0.47247706 | C24: 0.42269612 | D24: 0.40168971 | E24: 0.45077973 | F24: 0.45346681 | G24: 0.52558923 | H24: 0.41198044 | I24: 0.43213228 | J24: 0.4667869 | L24: 0.53613445 | M24: 0.1482821 | N24: =AVERAGE(B24:M24) -> 0.42927407
A25: 北京 | B25: 0.68615385 | C25: 0.64201183 | D25: 0.68452381 | E25: 0.67303609 | F25: 0.67055394 | G25: 0.63424658 | H25: 0.54505495 | I25: 0.53758865 | J25: 0.59033989 | L25: 0.73201439 | M25: 0.14141414 | N25: =AVERAGE(B25:M25) -> 0.5942671
A26: 滨湖 | B26: 0.47434743 | C26: 0.45559503 | D26: 0.55428571 | E26: 0.5 | F26: 0.52277362 | G26: 0.46805349 | H26: 0.43569132 | I26: 0.44292453 | J26: 0.45878136 | L26: 0.6568915 | M26: 0.66666667 | N26: =AVERAGE(B26:M26) -> 0.51236461
A27: 阜阳 | B27: 0.62087912 | C27: 0.57268722 | D27: 0.50622407 | E27: 0.49137931 | F27: 0.534 | G27: 0.58730159 | H27: 0.56923077 | I27: 0.53720508 | J27: 0.53811659 | L27: 0.4488189 | M27: 0 | N27: =AVERAGE(B27:M27) -> 0.49144024
A28: 贵阳 | B28: 0.46522132 | C28: 0.48884758 | D28: 0.4683908 | E28: 0.50803859 | F28: 0.485 | G28: 0.46190704 | H28: 0.46666667 | I28: 0.45543001 | J28: 0.498 | L28: 0.54742345 | M28: 0.53 | N28: =AVERAGE(B28:M28) -> 0.48862959
A29: 昆明 | B29: 0.52790698 | C29: 0.55555556 | D29: 0.56626506 | E29: 0.5432526 | F29: 0.57105606 | G29: 0.52830189 | H29: 0.52578797 | I29: 0.47318339 | J29: 0.52352232 | L29: 0.66013072 | M29: 0.3030303 | N29: =AVERAGE(B29:M29) -> 0.52527208
A30: 连江 | B30: 0.54805195 | C30: 0.54961832 | D30: 0.59066667 | E30: 0.55637708 | F30: 0.59522136 | G30: 0.5629532 | H30: 0.50789096 | I30: 0.48997012 | J30: 0.48187633 | L30: 0.74141049 | M30: 0.25 | N30: =AVERAGE(B30:M30) -> 0.53400332
A31: 罗源 | B31: 0.56329114 | C31: 0.59034268 | D31: 0.57996769 | E31: 0.51327434 | F31: 0.55007587 | G31: 0.51312988 | H31: 0.54835924 | I31: 0.5374677 | J31: 0.4911707 | L31: 0.75675676 | M31: 0.66666667 | N31: =AVERAGE(B31:M31) -> 0.57368206
A32: 闽江 | B32: 0.57312253 | C32: 0.58237548 | D32: 0.57383966 | E32: 0.49216301 | F32: 0.55133929 | G32: 0.49492901 | H32: 0.53752535 | I32: 0.51554404 | J32: 0.52059308 | L32: 0.74747475 | M32: 0.33333333 | N32: =AVERAGE(B32:M32) -> 0.53838541
